Workbook

Sheet Reporte
A2: ProjectName | B2: UT - ENTERRITORIO 2027 | E2: ProjectName | F2: UT - ENTERRITORIO 2027
J3: CPI (Cost Performance Index) | K3: SPI (Schedule Performance Index)
A4: Etiquetas de fila | B4: Promedio de SPI (Schedule Performance Index) | C4: Suma de Meta SPI | E4: Etiquetas de fila | F4: Promedio de CPI (Cost Performance Index) | G4: Suma de Meta CPI | J4: CPI = EV / AC | K4: SPI = EV / PV
A5: 2024 | B5: 1.2421744 | C5: 8 | E5: 2025 | F5: 15.886921 | G5: 12 | J5: CPI = 1,00 → gasto exacto según lo presupuestado | K5: SPI = 1,00 → a tiempo
A6: Mayo | B6: 2.5 | C6: 1 | E6: Enero | F6: 9.662221 | G6: 1 | J6: CPI > 1,00 → eficiente (gastas menos de lo esperado) | K6: SPI > 1,00 → adelantado
A7: Proyecto adelantado respecto al cronograma | B7: 2.5 | C7: 1 | E7: Costo eficiente: se está gastando menos de lo presupuestado | F7: 9.662221 | G7: 1 | J7: CPI < 1,00 → ineficiente (gastas más de lo esperado) | K7: SPI < 1,00 → atrasado
A8: Junio | B8: 1.4 | C8: 1 | E8: Febrero | F8: 10.777093 | G8: 1
A9: Proyecto adelantado respecto al cronograma | B9: 1.4 | C9: 1 | E9: Costo eficiente: se está gastando menos de lo presupuestado | F9: 10.777093 | G9: 1
A10: Julio | B10: 1 | C10: 1 | E10: Marzo | F10: 11.891964 | G10: 1
A11: Proyecto a tiempo según lo planificado | B11: 1 | C11: 1 | E11: Costo eficiente: se está gastando menos de lo presupuestado | F11: 11.891964 | G11: 1
A12: Agosto | B12: 1 | C12: 1 | E12: Abril | F12: 13.006836 | G12: 1
A13: Proyecto a tiempo según lo planificado | B13: 1 | C13: 1 | E13: Costo eficiente: se está gastando menos de lo presupuestado | F13: 13.006836 | G13: 1
A14: Septiembre | B14: 0.92857143 | C14: 1 | E14: Mayo | F14: 14.121708 | G14: 1
A15: Proyecto atrasado con respecto al cronograma | B15: 0.92857143 | C15: 1 | E15: Costo eficiente: se está gastando menos de lo presupuestado | F15: 14.121708 | G15: 1
A16: Octubre | B16: 1.0588235 | C16: 1 | E16: Junio | F16: 15.608203 | G16: 1
A17: Proyecto adelantado respecto al cronograma | B17: 1.0588235 | C17: 1 | E17: Costo eficiente: se está gastando menos de lo presupuestado | F17: 15.608203 | G17: 1
A18: Noviembre | B18: 1.05 | C18: 1 | E18: Julio | F18: 16.723075 | G18: 1
A19: Proyecto adelantado respecto al cronograma | B19: 1.05 | C19: 1 | E19: Costo eficiente: se está gastando menos de lo presupuestado | F19: 16.723075 | G19: 1
... A21: Proyecto a tiempo según lo planificado | B21: 1 | C21: 1 | E21: Costo eficiente: se está gastando menos de lo presupuestado | F21: 17.837946 | G21: 1
A22: 2025 | B22: 1.0056995 | C22: 12 | E22: Septiembre | F22: 18.581194 | G22: 1
A23: Enero | B23: 1 | C23: 1 | E23: Costo eficiente: se está gastando menos de lo presupuestado | F23: 18.581194 | G23: 1
A24: Proyecto a tiempo según lo planificado | B24: 1 | C24: 1 | E24: Octubre | F24: 19.696066 | G24: 1
A25: Febrero | B25: 1 | C25: 1 | E25: Costo eficiente: se está gastando menos de lo presupuestado | F25: 19.696066 | G25: 1
A26: Proyecto a tiempo según lo planificado | B26: 1 | C26: 1 | E26: Noviembre | F26: 20.810938 | G26: 1
A27: Marzo | B27: 1 | C27: 1 | E27: Costo eficiente: se está gastando menos de lo presupuestado | F27: 20.810938 | G27: 1
A28: Proyecto a tiempo según lo planificado | B28: 1 | C28: 1 | E28: Diciembre | F28: 21.925809 | G28: 1
A29: Abril | B29: 1 | C29: 1 | E29: Costo eficiente: se está gastando menos de lo presupuestado | F29: 21.925809 | G29: 1
A30: Proyecto a tiempo según lo planificado | B30: 1 | C30: 1 | E30: Total general | F30: 15.886921 | G30: 12
A31: Mayo | B31: 1 | C31: 1
A32: Proyecto a tiempo según lo planificado | B32: 1 | C32: 1
A33: Junio | B33: 1.0243902 | C33: 1
A34: Proyecto adelantado respecto al cronograma | B34: 1.0243902 | C34: 1
A35: Julio | B35: 1.0227273 | C35: 1
A36: Proyecto adelantado respecto al cronograma | B36: 1.0227273 | C36: 1
A37: Agosto | B37: 1.0212766 | C37: 1
A38: Proyecto adelantado respecto al cronograma | B38: 1.0212766 | C38: 1
A39: Septiembre | B39: 1 | C39: 1
A40: Proyecto a tiempo según lo planificado | B40: 1 | C40: 1
A41: Octubre | B41: 1 | C41: 1
A42: Proyecto a tiempo según lo planificado | B42: 1 | C42: 1
...

Sheet Resumen
A3: Etiquetas de fila | B3: Promedio de SPI (Schedule Performance Index) | C3: Cuenta de CPI (Cost Performance Index)
A4: FONDO ACCION - MEJORAS APLICATIVO ASEC | B4: 1.1333333 | C4: 3
A5: UT CIBERSEGURIDAD MT | B5: 1.0951082 | C5: 15
A6: EMTEL - ICFES - FABRICA | B6: 1.0623689 | C6: 8
A7: ERT- MT– DISPOSITIVOS IOT Y ANALÍTICA | B7: 1.0359642 | C7: 8
A8: SNR- MIGRACION FOLIO A SIR | B8: 1.0357843 | C8: 7
A9: EXPERTIX - DEFENSORIA – RENOVACIÓN MEGA | B9: 1 | C9: 2
A10: TELEFONICA - RNEC-ELECCIONES 2026 | B10: 1 | C10: 11
A11: CCD-INM-AE-2025 | B11: 1 | C11: 4
A12: FNA -DATAFABRIC | B12: 1 | C12: 12
A13: COMREDES - URT - SOLUCIÓN HCI FASE II | B13: 1 | C13: 1
A14: SNR-MIGRACION FOLIO A SIR-BID | B14: 1 | C14: 2
A15: DIAN-BORRADO SEGURO BLANCCO | B15: 1 | C15: 2
... A85: Total general | B85: 0.41543848 | C85: 914

Sheet Indicador
A1: Año | B1: Mes | C1: ProjectId | D1: ProjectCreatedDate | E1: ProjectName | F1: ProjectOwnerName | G1: ProjectWorkspaceInternalUrl | H1: Objetocontractual | I1: Portafolio | J1: CentrodeCostosProyecto | K1: Estado | L1: Presupuesto | M1: Inicio | N1: Fin | O1: Meses | P1: Tiempo Diferencia | Q1: Tiempo Ejecución | R1: Tiempo Proyectado | S1: % Planeado | T1: Completado Real | U1: AC (Actual Cost) | V1: Costo Mensual | W1: EV (Earned Value) | X1: PV (Planned Value) | Y1: CV (Cost Variance) | Z1: SV (Schedule Variance) | AA1: CPI (Cost Performance Index) | AB1: Detalle de CPI | AC1: SPI (Schedule Performance Index) | AD1: Detalle SPI | AE1: EAC (Estimación al finalizar) | AF1: VAC (Exceso de presupuesto proyectado) | AG1: Ruta | AH1: Meta SPI | AI1: Meta CPI
A2: 2024 | B2: Enero | C2: 72cbf93a-8da6-ef11-bd95-00155d10dc02 | D2: 45615.656 | E2: ERT-URT-HIPERCORVENGENCIA | F2: Carlos Alberto Osorio Ortiz | G2: https://growdatasas.sharepoint.com/sites/pwa/ERT-URT-HIPERCORVENGENCIA | H2: ​Suministro de una solución de Hiperconvergencia para la unidad de restitución de tierras | I2: TI | J2: 0349 | K2: Activo.En Cierre | L2: =VLOOKUP(E2,Diccionario!C$2:AC$150,22,0) -> 314881564 | M2: =VLOOKUP(E2,Diccionario!C$2:AC$150,24,0) -> 45292 | N2: =VLOOKUP(E2,Diccionario!C$2:AC$150,25,0) -> 45321 | O2: =VLOOKUP(E2,Diccionario!C$2:AC$150,26,0) -> 0.97 | P2: =O2-Q2 -> -0.03 | Q2: 1 | R2: 1 | S2: 1 | T2: 1 | U2: 314881564 | V2: 314881564 | W2: =IFERROR(T2*L2,0) -> 314881564 | X2: =S2*L2 -> 314881564 | Y2: =IFERROR(W2-U2,0) -> 0 | Z2: =W2-X2 -> 0 | AA2: =IFERROR(W2/U2,"No se realizó gasto en este corte") -> 1 | AB2: =IFERROR( IF(OR(AA2="",AA2=0), "No calculado", IF(AA2>1,"Costo eficiente: se está gastando menos de lo presupuestado", IF(AA2=1,"Costo según lo presupuestado", "Costo ineficiente: se está gastando más de lo presupuestado"))), "No calculado") -> Costo según lo presupuestado | AC2: =IFERROR(W2/X2,0) -> 1 | AD2: =IF(OR(AC2="",AC2=0),"Sin Línea Base", IF(AC2>1,"Proyecto adelantado respecto al cronograma", IF(AC2=1,"Proyecto a tiempo según lo planificado", IF(AC2<1,"Proyecto atrasado con respecto al cronograma", "No calculado")))) -> Proyecto a tiempo según lo planificado | AE2: =IFERROR(L2/AA2,0) -> 314881564 | AF2: =IFERROR(AE2-L2,0) -> 0 | AG2: =VLOOKUP(Indicador!E2,Diccionario!C$1:AC$150,27,0) -> https://growdatasas.sharepoint.com/:x:/r/sites/Gestiondocumental/Administrativa/GD/Financiera/_layouts/15/Doc.aspx?sourcedoc=%7BEA2AC996-D46C-4123-8126-7F0BE9537AF4%7D&file=20241108%20MODELO%20FINANCIERO%20REFERENCIA%20V7.2%20APROBADO.xlsm&action=default&mobileredirect=true | AH2: 1 | AI2: 1
A3: 2024 | B3: Enero | C3: a514ea09-ced4-ee11-bd00-00155d682338 | D3: 45348.736 | E3: TELEFONICA - SENA MDA | F3: Carlos Fernando Gomez Rodriguez | G3: https://growdatasas.sharepoint.com/sites/pwa/TELEFONICA - SENA MDA | H3: ​Mesa de servicio para el SENA | I3: TI | J3: 0319 | K3: Cerrado | L3: =VLOOKUP(E3,Diccionario!C$2:AC$150,22,0) -> 13344287960 | M3: =VLOOKUP(E3,Diccionario!C$2:AC$150,24,0) -> 45292 | N3: =VLOOKUP(E3,Diccionario!C$2:AC$150,25,0) -> 45381 | O3: =VLOOKUP(E3,Diccionario!C$2:AC$150,26,0) -> 2.97 | P3: =Q3-O3 -> -1.97 | Q3: 1 | R3: 3 | S3: 0.3 | T3: 0.25 | U3: 1589891803 | V3: 1589891803 | W3: =IFERROR(T3*L3,0) -> 3336071990 | X3: =S3*L3 -> 4003286388 | Y3: =IFERROR(W3-U3,0) -> 1746180187 | Z3: =W3-X3 -> -667214398 | AA3: =IFERROR(W3/U3,"No se realizó gasto en este corte") -> 2.0983013 | AB3: =IFERROR( IF(OR(AA3="",AA3=0), "No calculado", IF(AA3>1,"Costo eficiente: se está gastando menos de lo presupuestado", IF(AA3=1,"Costo según lo presupuestado", "Costo ineficiente: se está gastando más de lo presupuestado"))), "No calculado") -> Costo eficiente: se está gastando menos de lo presupuestado | AC3: =IFERROR(W3/X3,0) -> 0.83333333 | AD3: =IF(OR(AC3="",AC3=0),"Sin Línea Base", IF(AC3>1,"Proyecto adelantado respecto al cronograma", IF(AC3=1,"Proyecto a tiempo según lo planificado", IF(AC3<1,"Proyecto atrasado con respecto al cronograma", "No calculado")))) -> Proyecto atrasado con respecto al cronograma | AE3: =IFERROR(L3/AA3,0) -> 6359567212 | AF3: =IFERROR(AE3-L3,0) -> -6984720748 | AG3: =VLOOKUP(Indicador!E3,Diccionario!C$1:AC$150,27,0) -> https://growdatasas.sharepoint.com/:x:/r/sites/Gestiondocumental/Administrativa/GD/Financiera/_layouts/15/Doc.aspx?sourcedoc=%7B06FB1484-E2DE-40DA-83E0-D97F6AF0AE9B%7D&file=MODELO%20FINANCIERO%20REFERENCIA%20V7%20MS%2020240130.xlsx&action=default&mobileredirect=true | AH3: 1 | AI3: 1
A4: 2024 | B4: Febrero | C4: a514ea09-ced4-ee11-bd00-00155d682338 | D4: 45348.736 | E4: TELEFONICA - SENA MDA | F4: Carlos Fernando Gomez Rodriguez | G4: https://growdatasas.sharepoint.com/sites/pwa/TELEFONICA - SENA MDA | H4: ​Mesa de servicio para el SENA | I4: TI | J4: 0319 | K4: Cerrado | L4: =VLOOKUP(E4,Diccionario!C$2:AC$150,22,0) -> 13344287960 | M4: =VLOOKUP(E4,Diccionario!C$2:AC$150,24,0) -> 45292 | N4: =VLOOKUP(E4,Diccionario!C$2:AC$150,25,0) -> 45381 | O4: =VLOOKUP(E4,Diccionario!C$2:AC$150,26,0) -> 2.97 | P4: =Q4-O4 -> -0.97 | Q4: 2 | R4: 3 | S4: 0.7 | T4: 0.65 | U4: =U3+TablaIndicador[[#This Row],[Costo Mensual]] -> 3913702428 | V4: 2323810625 | W4: =IFERROR(T4*L4,0) -> 8673787174 | X4: =S4*L4 -> 9341001572 | Y4: =IFERROR(W4-U4,0) -> 4760084746 | Z4: =W4-X4 -> -667214398 | AA4: =IFERROR(W4/U4,"No se realizó gasto en este corte") -> 2.2162613 | AB4: =IFERROR( IF(OR(AA4="",AA4=0), "No calculado", IF(AA4>1,"Costo eficiente: se está gastando menos de lo presupuestado", IF(AA4=1,"Costo según lo presupuestado", "Costo ineficiente: se está gastando más de lo presupuestado"))), "No calculado") -> Costo eficiente: se está gastando menos de lo presupuestado | AC4: =IFERROR(W4/X4,0) -> 0.92857143 | AD4: =IF(OR(AC4="",AC4=0),"Sin Línea Base", IF(AC4>1,"Proyecto adelantado respecto al cronograma", IF(AC4=1,"Proyecto a tiempo según lo planificado", IF(AC4<1,"Proyecto atrasado con respecto al cronograma", "No calculado")))) -> Proyecto atrasado con respecto al cronograma | AE4: =IFERROR(L4/AA4,0) -> 6.0210807e+09 | AF4: =IFERROR(AE4-L4,0) -> -7.3232073e+09 | AG4: =VLOOKUP(Indicador!E4,Diccionario!C$1:AC$150,27,0) -> https://growdatasas.sharepoint.com/:x:/r/sites/Gestiondocumental/Administrativa/GD/Financiera/_layouts/15/Doc.aspx?sourcedoc=%7B06FB1484-E2DE-40DA-83E0-D97F6AF0AE9B%7D&file=MODELO%20FINANCIERO%20REFERENCIA%20V7%20MS%2020240130.xlsx&action=default&mobileredirect=true | AH4: 1 | AI4: 1
A5: 2024 | B5: Marzo | C5: a514ea09-ced4-ee11-bd00-00155d682338 | D5: 45348.736 | E5: TELEFONICA - SENA MDA | F5: Carlos Fernando Gomez Rodriguez | G5: https://growdatasas.sharepoint.com/sites/pwa/TELEFONICA - SENA MDA | H5: ​Mesa de servicio para el SENA | I5: TI | J5: 0319 | K5: Cerrado | L5: =VLOOKUP(E5,Diccionario!C$2:AC$150,22,0) -> 13344287960 | M5: =VLOOKUP(E5,Diccionario!C$2:AC$150,24,0) -> 45292 | N5: =VLOOKUP(E5,Diccionario!C$2:AC$150,25,0) -> 45381 | O5: =VLOOKUP(E5,Diccionario!C$2:AC$150,26,0) -> 2.97 | P5: =Q5-O5 -> 0.03 | Q5: 3 | R5: 3 | S5: 1 | T5: 1 | U5: =U4+TablaIndicador[[#This Row],[Costo Mensual]] -> 6237513053 | V5: 2323810625 | W5: =IFERROR(T5*L5,0) -> 13344287960 | X5: =S5*L5 -> 13344287960 | Y5: =IFERROR(W5-U5,0) -> 7106774907 | Z5: =W5-X5 -> 0 | AA5: =IFERROR(W5/U5,"No se realizó gasto en este corte") -> 2.1393603 | AB5: =IFERROR( IF(OR(AA5="",AA5=0), "No calculado", IF(AA5>1,"Costo eficiente: se está gastando menos de lo presupuestado", IF(AA5=1,"Costo según lo presupuestado", "Costo ineficiente: se está gastando más de lo presupuestado"))), "No calculado") -> Costo eficiente: se está gastando menos de lo presupuestado | AC5: =IFERROR(W5/X5,0) -> 1 | AD5: =IF(OR(AC5="",AC5=0),"Sin Línea Base", IF(AC5>1,"Proyecto adelantado respecto al cronograma", IF(AC5=1,"Proyecto a tiempo según lo planificado", IF(AC5<1,"Proyecto atrasado con respecto al cronograma", "No calculado")))) -> Proyecto a tiempo según lo planificado | AE5: =IFERROR(L5/AA5,0) -> 6237513053 | AF5: =IFERROR(AE5-L5,0) -> -7106774907 | AG5: =VLOOKUP(Indicador!E5,Diccionario!C$1:AC$150,27,0) -> https://growdatasas.sharepoint.com/:x:/r/sites/Gestiondocumental/Administrativa/GD/Financiera/_layouts/15/Doc.aspx?sourcedoc=%7B06FB1484-E2DE-40DA-83E0-D97F6AF0AE9B%7D&file=MODELO%20FINANCIERO%20REFERENCIA%20V7%20MS%2020240130.xlsx&action=default&mobileredirect=true | AH5: 1 | AI5: 1
A6: 2024 | B6: Enero | C6: b3dee2f4-49c1-ee11-add8-00155d10211a | D6: 45323.9 | E6: CORP COLOMBIA DIGITAL-FNA-AE | F6: Johan Sebastian Rodriguez Niño | G6: https://growdatasas.sharepoint.com/sites/pwa/CORP COLOMBIA DIGITAL-FNA-AE | H6: Consultoría para el diseño de la Transformación Digital de la entidad que designe la Corporación Colombia Digital, basado en desarrollar la arquitectura empresarial - AR, la definición e implementación del Gobierno y la gestión de datos, la definición de la hoja de ruta de la AR para el plan estratégico de TI PETI, la formación de personal y la planeación del proyecto de la entidad designada. | I6: CONSULTORÍA | J6: 0315 | K6: Activo.En Cierre | L6: =VLOOKUP(E6,Diccionario!C$2:AC$150,22,0) -> 1422409157 | M6: =VLOOKUP(E6,Diccionario!C$2:AC$150,24,0) -> 45292 | N6: =VLOOKUP(E6,Diccionario!C$2:AC$150,25,0) -> 45534 | O6: =VLOOKUP(E6,Diccionario!C$2:AC$150,26,0) -> 7.97 | P6: =Q6-O6 -> -6.97 | Q6: 1 | R6: 8 | S6: 0.1 | T6: 0.08 | U6: =TablaIndicador[[#This Row],[Costo Mensual]] -> 1.531156e+08 | V6: 1.531156e+08 | W6: =IFERROR(T6*L6,0) -> 1.1379273e+08 | X6: =S6*L6 -> 1.4224092e+08 | Y6: =IFERROR(W6-U6,0) -> -39322867 | Z6: =W6-X6 -> -28448183 | AA6: =IFERROR(W6/U6,"No se realizó gasto en este corte") -> 0.74318184 | AB6: =IFERROR( IF(OR(AA6="",AA6=0), "No calculado", IF(AA6>1,"Costo eficiente: se está gastando menos de lo presupuestado", IF(AA6=1,"Costo según lo presupuestado", "Costo ineficiente: se está gastando más de lo presupuestado"))), "No calculado") -> Costo ineficiente: se está gastando más de lo presupuestado | AC6: =IFERROR(W6/X6,0) -> 0.8 | AD6: =IF(OR(AC6="",AC6=0),"Sin Línea Base", IF(AC6>1,"Proyecto adelantado respecto al cronograma", IF(AC6=1,"Proyecto a tiempo según lo planificado", IF(AC6<1,"Proyecto atrasado con respecto al cronograma", "No calculado")))) -> Proyecto atrasado con respecto al cronograma | AE6: =IFERROR(L6/AA6,0) -> 1.913945e+09 | AF6: =IFERROR(AE6-L6,0) -> 4.9153584e+08 | AG6: =VLOOKUP(Indicador!E6,Diccionario!C$1:AC$150,27,0) -> https://growdatasas.sharepoint.com/:x:/r/sites/Gestiondocumental/Administrativa/GD/Financiera/_layouts/15/Doc.aspx?sourcedoc=%7B453B6AA8-B631-4722-B916-8323F8C43E87%7D&file=315%20CORP%20COLOMBIA%20DIGITAL%20FNA%20AE.xlsm&action=default&mobileredirect=true | AH6: 1 | AI6: 1
A7: 2024 | B7: Febrero | C7: b3dee2f4-49c1-ee11-add8-00155d10211a | D7: 45323.9 | E7: CORP COLOMBIA DIGITAL-FNA-AE | F7: Johan Sebastian Rodriguez Niño | G7: https://growdatasas.sharepoint.com/sites/pwa/CORP COLOMBIA DIGITAL-FNA-AE | H7: Consultoría para el diseño de la Transformación Digital de la entidad que designe la Corporación Colombia Digital, basado en desarrollar la arquitectura empresarial - AR, la definición e implementación del Gobierno y la gestión de datos, la definición de la hoja de ruta de la AR para el plan estratégico de TI PETI, la formación de personal y la planeación del proyecto de la entidad designada. | I7: CONSULTORÍA | J7: 0315 | K7: Activo.En Cierre | L7: =VLOOKUP(E7,Diccionario!C$2:AC$150,22,0) -> 1422409157 | M7: =VLOOKUP(E7,Diccionario!C$2:AC$150,24,0) -> 45292 | N7: =VLOOKUP(E7,Diccionario!C$2:AC$150,25,0) -> 45534 | O7: =VLOOKUP(E7,Diccionario!C$2:AC$150,26,0) -> 7.97 | P7: =Q7-O7 -> -5.97 | Q7: 2 | R7: 8 | S7: 0.2 | T7: 0.18 | U7: =U6+TablaIndicador[[#This Row],[Costo Mensual]] -> 4.0497338e+08 | V7: 2.5185778e+08 | W7: =IFERROR(T7*L7,0) -> 2.5603365e+08 | X7: =S7*L7 -> 2.8448183e+08 | Y7: =IFERROR(W7-U7,0) -> -1.4893973e+08 | Z7: =W7-X7 -> -28448183 | AA7: =IFERROR(W7/U7,"No se realizó gasto en este corte") -> 0.6322234 | AB7: =IFERROR( IF(OR(AA7="",AA7=0), "No calculado", IF(AA7>1,"Costo eficiente: se está gastando menos de lo presupuestado", IF(AA7=1,"Costo según lo presupuestado", "Costo ineficiente: se está gastando más de lo presupuestado"))), "No calculado") -> Costo ineficiente: se está gastando más de lo presupuestado | AC7: =IFERROR(W7/X7,0) -> 0.9 | AD7: =IF(OR(AC7="",AC7=0),"Sin Línea Base", IF(AC7>1,"Proyecto adelantado respecto al cronograma", IF(AC7=1,"Proyecto a tiempo según lo planificado", IF(AC7<1,"Proyecto atrasado con respecto al cronograma", "No calculado")))) -> Proyecto atrasado con respecto al cronograma | AE7: =IFERROR(L7/AA7,0) -> 2.2498521e+09 | AF7: =IFERROR(AE7-L7,0) -> 8.2744295e+08 | AG7: =VLOOKUP(Indicador!E7,Diccionario!C$1:AC$150,27,0) -> https://growdatasas.sharepoint.com/:x:/r/sites/Gestiondocumental/Administrativa/GD/Financiera/_layouts/15/Doc.aspx?sourcedoc=%7B453B6AA8-B631-4722-B916-8323F8C43E87%7D&file=315%20CORP%20COLOMBIA%20DIGITAL%20FNA%20AE.xlsm&action=default&mobileredirect=true | AH7: 1 | AI7: 1
A8: 2024 | B8: Marzo | C8: b3dee2f4-49c1-ee11-add8-00155d10211a | D8: 45323.9 | E8: CORP COLOMBIA DIGITAL-FNA-AE | F8: Johan Sebastian Rodriguez Niño | G8: https://growdatasas.sharepoint.com/sites/pwa/CORP COLOMBIA DIGITAL-FNA-AE | H8: Consultoría para el diseño de la Transformación Digital de la entidad que designe la Corporación Colombia Digital, basado en desarrollar la arquitectura empresarial - AR, la definición e implementación del Gobierno y la gestión de datos, la definición de la hoja de ruta de la AR para el plan estratégico de TI PETI, la formación de personal y la planeación del proyecto de la entidad designada. | I8: CONSULTORÍA | J8: 0315 | K8: Activo.En Cierre | L8: =VLOOKUP(E8,Diccionario!C$2:AC$150,22,0) -> 1422409157 | M8: =VLOOKUP(E8,Diccionario!C$2:AC$150,24,0) -> 45292 | N8: =VLOOKUP(E8,Diccionario!C$2:AC$150,25,0) -> 45534 | O8: =VLOOKUP(E8,Diccionario!C$2:AC$150,26,0) -> 7.97 | P8: =Q8-O8 -> -4.97 | Q8: 3 | R8: 8 | S8: 0.3 | T8: 0.32 | U8: =U7+TablaIndicador[[#This Row],[Costo Mensual]] -> 5.5808898e+08 | V8: 1.531156e+08 | W8: =IFERROR(T8*L8,0) -> 4.5517093e+08 | X8: =S8*L8 -> 4.2672275e+08 | Y8: =IFERROR(W8-U8,0) -> -1.0291805e+08 | Z8: =W8-X8 -> 28448183 | AA8: =IFERROR(W8/U8,"No se realizó gasto en este corte") -> 0.81558846 | AB8: =IFERROR( IF(OR(AA8="",AA8=0), "No calculado", IF(AA8>1,"Costo eficiente: se está gastando menos de lo presupuestado", IF(AA8=1,"Costo según lo presupuestado", "Costo ineficiente: se está gastando más de lo presupuestado"))), "No calculado") -> Costo ineficiente: se está gastando más de lo presupuestado | AC8: =IFERROR(W8/X8,0) -> 1.0666667 | AD8: =IF(OR(AC8="",AC8=0),"Sin Línea Base", IF(AC8>1,"Proyecto adelantado respecto al cronograma", IF(AC8=1,"Proyecto a tiempo según lo planificado", IF(AC8<1,"Proyecto atrasado con respecto al cronograma", "No calculado")))) -> Proyecto adelantado respecto al cronograma | AE8: =IFERROR(L8/AA8,0) -> 1.7440281e+09 | AF8: =IFERROR(AE8-L8,0) -> 3.216189e+08 | AG8: =VLOOKUP(Indicador!E8,Diccionario!C$1:AC$150,27,0) -> https://growdatasas.sharepoint.com/:x:/r/sites/Gestiondocumental/Administrativa/GD/Financiera/_layouts/15/Doc.aspx?sourcedoc=%7B453B6AA8-B631-4722-B916-8323F8C43E87%7D&file=315%20CORP%20COLOMBIA%20DIGITAL%20FNA%20AE.xlsm&action=default&mobileredirect=true | AH8: 1 | AI8: 1
A9: 2024 | B9: Abril | C9: b3dee2f4-49c1-ee11-add8-00155d10211a | D9: 45323.9 | E9: CORP COLOMBIA DIGITAL-FNA-AE | F9: Johan Sebastian Rodriguez Niño | G9: https://growdatasas.sharepoint.com/sites/pwa/CORP COLOMBIA DIGITAL-FNA-AE | H9: Consultoría para el diseño de la Transformación Digital de la entidad que designe la Corporación Colombia Digital, basado en desarrollar la arquitectura empresarial - AR, la definición e implementación del Gobierno y la gestión de datos, la definición de la hoja de ruta de la AR para el plan estratégico de TI PETI, la formación de personal y la planeación del proyecto de la entidad designada. | I9: CONSULTORÍA | J9: 0315 | K9: Activo.En Cierre | L9: =VLOOKUP(E9,Diccionario!C$2:AC$150,22,0) -> 1422409157 | M9: =VLOOKUP(E9,Diccionario!C$2:AC$150,24,0) -> 45292 | N9: =VLOOKUP(E9,Diccionario!C$2:AC$150,25,0) -> 45534 | O9: =VLOOKUP(E9,Diccionario!C$2:AC$150,26,0) -> 7.97 | P9: =Q9-O9 -> -3.97 | Q9: 4 | R9: 8 | S9: 0.5 | T9: 0.51 | U9: =U8+TablaIndicador[[#This Row],[Costo Mensual]] -> 7.1120458e+08 | V9: 1.531156e+08 | W9: =IFERROR(T9*L9,0) -> 7.2542867e+08 | X9: =S9*L9 -> 7.1120458e+08 | Y9: =IFERROR(W9-U9,0) -> 14224092 | Z9: =W9-X9 -> 14224092 | AA9: =IFERROR(W9/U9,"No se realizó gasto en este corte") -> 1.02 | AB9: =IFERROR( IF(OR(AA9="",AA9=0), "No calculado", IF(AA9>1,"Costo eficiente: se está gastando menos de lo presupuestado", IF(AA9=1,"Costo según lo presupuestado", "Costo ineficiente: se está gastando más de lo presupuestado"))), "No calculado") -> Costo eficiente: se está gastando menos de lo presupuestado | AC9: =IFERROR(W9/X9,0) -> 1.02 | AD9: =IF(OR(AC9="",AC9=0),"Sin Línea Base", IF(AC9>1,"Proyecto adelantado respecto al cronograma", IF(AC9=1,"Proyecto a tiempo según lo planificado", IF(AC9<1,"Proyecto atrasado con respecto al cronograma", "No calculado")))) -> Proyecto adelantado respecto al cronograma | AE9: =IFERROR(L9/AA9,0) -> 1.3945188e+09 | AF9: =IFERROR(AE9-L9,0) -> -27890376 | AG9: =VLOOKUP(Indicador!E9,Diccionario!C$1:AC$150,27,0) -> https://growdatasas.sharepoint.com/:x:/r/sites/Gestiondocumental/Administrativa/GD/Financiera/_layouts/15/Doc.aspx?sourcedoc=%7B453B6AA8-B631-4722-B916-8323F8C43E87%7D&file=315%20CORP%20COLOMBIA%20DIGITAL%20FNA%20AE.xlsm&action=default&mobileredirect=true | AH9: 1 | AI9: 1
A10: 2024 | B10: Mayo | C10: b3dee2f4-49c1-ee11-add8-00155d10211a | D10: 45323.9 | E10: CORP COLOMBIA DIGITAL-FNA-AE | F10: Johan Sebastian Rodriguez Niño | G10: https://growdatasas.sharepoint.com/sites/pwa/CORP COLOMBIA DIGITAL-FNA-AE | H10: Consultoría para el diseño de la Transformación Digital de la entidad que designe la Corporación Colombia Digital, basado en desarrollar la arquitectura empresarial - AR, la definición e implementación del Gobierno y la gestión de datos, la definición de la hoja de ruta de la AR para el plan estratégico de TI PETI, la formación de personal y la planeación del proyecto de la entidad designada. | I10: CONSULTORÍA | J10: 0315 | K10: Activo.En Cierre | L10: =VLOOKUP(E10,Diccionario!C$2:AC$150,22,0) -> 1422409157 | M10: =VLOOKUP(E10,Diccionario!C$2:AC$150,24,0) -> 45292 | N10: =VLOOKUP(E10,Diccionario!C$2:AC$150,25,0) -> 45534 | O10: =VLOOKUP(E10,Diccionario!C$2:AC$150,26,0) -> 7.97 | P10: =Q10-O10 -> -2.97 | Q10: 5 | R10: 8 | S10: 0.6 | T10: 0.6 | U10: =U9+TablaIndicador[[#This Row],[Costo Mensual]] -> 8.6432018e+08 | V10: 1.531156e+08 | W10: =IFERROR(T10*L10,0) -> 8.5344549e+08 | X10: =S10*L10 -> 8.5344549e+08 | Y10: =IFERROR(W10-U10,0) -> -10874684 | Z10: =W10-X10 -> 0 | AA10: =IFERROR(W10/U10,"No se realizó gasto en este corte") -> 0.98741822 | AB10: =IFERROR( IF(OR(AA10="",AA10=0), "No calculado", IF(AA10>1,"Costo eficiente: se está gastando menos de lo presupuestado", IF(AA10=1,"Costo según lo presupuestado", "Costo ineficiente: se está gastando más de lo presupuestado"))), "No calculado") -> Costo ineficiente: se está gastando más de lo presupuestado | AC10: =IFERROR(W10/X10,0) -> 1 | AD10: =IF(OR(AC10="",AC10=0),"Sin Línea Base", IF(AC10>1,"Proyecto adelantado respecto al cronograma", IF(AC10=1,"Proyecto a tiempo según lo planificado", IF(AC10<1,"Proyecto atrasado con respecto al cronograma", "No calculado")))) -> Proyecto a tiempo según lo planificado | AE10: =IFERROR(L10/AA10,0) -> 1.4405336e+09 | AF10: =IFERROR(AE10-L10,0) -> 18124473 | AG10: =VLOOKUP(Indicador!E10,Diccionario!C$1:AC$150,27,0) -> https://growdatasas.sharepoint.com/:x:/r/sites/Gestiondocumental/Administrativa/GD/Financiera/_layouts/15/Doc.aspx?sourcedoc=%7B453B6AA8-B631-4722-B916-8323F8C43E87%7D&file=315%20CORP%20COLOMBIA%20DIGITAL%20FNA%20AE.xlsm&action=default&mobileredirect=true | AH10: 1 | AI10: 1
A11: 2024 | B11: Junio | C11: b3dee2f4-49c1-ee11-add8-00155d10211a | D11: 45323.9 | E11: CORP COLOMBIA DIGITAL-FNA-AE | F11: Johan Sebastian Rodriguez Niño | G11: https://growdatasas.sharepoint.com/sites/pwa/CORP COLOMBIA DIGITAL-FNA-AE | H11: Consultoría para el diseño de la Transformación Digital de la entidad que designe la Corporación Colombia Digital, basado en desarrollar la arquitectura empresarial - AR, la definición e implementación del Gobierno y la gestión de datos, la definición de la hoja de ruta de la AR para el plan estratégico de TI PETI, la formación de personal y la planeación del proyecto de la entidad designada. | I11: CONSULTORÍA | J11: 0315 | K11: Activo.En Cierre | L11: =VLOOKUP(E11,Diccionario!C$2:AC$150,22,0) -> 1422409157 | M11: =VLOOKUP(E11,Diccionario!C$2:AC$150,24,0) -> 45292 | N11: =VLOOKUP(E11,Diccionario!C$2:AC$150,25,0) -> 45534 | O11: =VLOOKUP(E11,Diccionario!C$2:AC$150,26,0) -> 7.97 | P11: =Q11-O11 -> -1.97 | Q11: 6 | R11: 8 | S11: 0.75 | T11: 0.73 | U11: =U10+TablaIndicador[[#This Row],[Costo Mensual]] -> 1.116178e+09 | V11: 2.5185778e+08 | W11: =IFERROR(T11*L11,0) -> 1.0383587e+09 | X11: =S11*L11 -> 1.0668069e+09 | Y11: =IFERROR(W11-U11,0) -> -77819273 | Z11: =W11-X11 -> -28448183 | AA11: =IFERROR(W11/U11,"No se realizó gasto en este corte") -> 0.93028059 | AB11: =IFERROR( IF(OR(AA11="",AA11=0), "No calculado", IF(AA11>1,"Costo eficiente: se está gastando menos de lo presupuestado", IF(AA11=1,"Costo según lo presupuestado", "Costo ineficiente: se está gastando más de lo presupuestado"))), "No calculado") -> Costo ineficiente: se está gastando más de lo presupuestado | AC11: =IFERROR(W11/X11,0) -> 0.97333333 | AD11: =IF(OR(AC11="",AC11=0),"Sin Línea Base", IF(AC11>1,"Proyecto adelantado respecto al cronograma", IF(AC11=1,"Proyecto a tiempo según lo planificado", IF(AC11<1,"Proyecto atrasado con respecto al cronograma", "No calculado")))) -> Proyecto atrasado con respecto al cronograma | AE11: =IFERROR(L11/AA11,0) -> 1.5290109e+09 | AF11: =IFERROR(AE11-L11,0) -> 1.0660174e+08 | AG11: =VLOOKUP(Indicador!E11,Diccionario!C$1:AC$150,27,0) -> https://growdatasas.sharepoint.com/:x:/r/sites/Gestiondocumental/Administrativa/GD/Financiera/_layouts/15/Doc.aspx?sourcedoc=%7B453B6AA8-B631-4722-B916-8323F8C43E87%7D&file=315%20CORP%20COLOMBIA%20DIGITAL%20FNA%20AE.xlsm&action=default&mobileredirect=true | AH11: 1 | AI11: 1
A12: 2024 | B12: Julio | C12: b3dee2f4-49c1-ee11-add8-00155d10211a | D12: 45323.9 | E12: CORP COLOMBIA DIGITAL-FNA-AE | F12: Johan Sebastian Rodriguez Niño | G12: https://growdatasas.sharepoint.com/sites/pwa/CORP COLOMBIA DIGITAL-FNA-AE | H12: Consultoría para el diseño de la Transformación Digital de la entidad que designe la Corporación Colombia Digital, basado en desarrollar la arquitectura empresarial - AR, la definición e implementación del Gobierno y la gestión de datos, la definición de la hoja de ruta de la AR para el plan estratégico de TI PETI, la formación de personal y la planeación del proyecto de la entidad designada. | I12: CONSULTORÍA | J12: 0315 | K12: Activo.En Cierre | L12: =VLOOKUP(E12,Diccionario!C$2:AC$150,22,0) -> 1422409157 | M12: =VLOOKUP(E12,Diccionario!C$2:AC$150,24,0) -> 45292 | N12: =VLOOKUP(E12,Diccionario!C$2:AC$150,25,0) -> 45534 | O12: =VLOOKUP(E12,Diccionario!C$2:AC$150,26,0) -> 7.97 | P12: =Q12-O12 -> -0.97 | Q12: 7 | R12: 8 | S12: 0.8 | T12: 0.82 | U12: =U11+TablaIndicador[[#This Row],[Costo Mensual]] -> 1.2692936e+09 | V12: 1.531156e+08 | W12: =IFERROR(T12*L12,0) -> 1.1663755e+09 | X12: =S12*L12 -> 1.1379273e+09 | Y12: =IFERROR(W12-U12,0) -> -1.0291805e+08 | Z12: =W12-X12 -> 28448183 | AA12: =IFERROR(W12/U12,"No se realizó gasto en este corte") -> 0.91891706 | AB12: =IFERROR( IF(OR(AA12="",AA12=0), "No calculado", IF(AA12>1,"Costo eficiente: se está gastando menos de lo presupuestado", IF(AA12=1,"Costo según lo presupuestado", "Costo ineficiente: se está gastando más de lo presupuestado"))), "No calculado") -> Costo ineficiente: se está gastando más de lo presupuestado | AC12: =IFERROR(W12/X12,0) -> 1.025 | AD12: =IF(OR(AC12="",AC12=0),"Sin Línea Base", IF(AC12>1,"Proyecto adelantado respecto al cronograma", IF(AC12=1,"Proyecto a tiempo según lo planificado", IF(AC12<1,"Proyecto atrasado con respecto al cronograma", "No calculado")))) -> Proyecto adelantado respecto al cronograma | AE12: =IFERROR(L12/AA12,0) -> 1.547919e+09 | AF12: =IFERROR(AE12-L12,0) -> 1.2550982e+08 | AG12: =VLOOKUP(Indicador!E12,Diccionario!C$1:AC$150,27,0) -> https://growdatasas.sharepoint.com/:x:/r/sites/Gestiondocumental/Administrativa/GD/Financiera/_layouts/15/Doc.aspx?sourcedoc=%7B453B6AA8-B631-4722-B916-8323F8C43E87%7D&file=315%20CORP%20COLOMBIA%20DIGITAL%20FNA%20AE.xlsm&action=default&mobileredirect=true | AH12: 1 | AI12: 1
A13: 2024 | B13: Agosto | C13: b3dee2f4-49c1-ee11-add8-00155d10211a | D13: 45323.9 | E13: CORP COLOMBIA DIGITAL-FNA-AE | F13: Johan Sebastian Rodriguez Niño | G13: https://growdatasas.sharepoint.com/sites/pwa/CORP COLOMBIA DIGITAL-FNA-AE | H13: Consultoría para el diseño de la Transformación Digital de la entidad que designe la Corporación Colombia Digital, basado en desarrollar la arquitectura empresarial - AR, la definición e implementación del Gobierno y la gestión de datos, la definición de la hoja de ruta de la AR para el plan estratégico de TI PETI, la formación de personal y la planeación del proyecto de la entidad designada. | I13: CONSULTORÍA | J13: 0315 | K13: Activo.En Cierre | L13: =VLOOKUP(E13,Diccionario!C$2:AC$150,22,0) -> 1422409157 | M13: =VLOOKUP(E13,Diccionario!C$2:AC$150,24,0) -> 45292 | N13: =VLOOKUP(E13,Diccionario!C$2:AC$150,25,0) -> 45534 | O13: =VLOOKUP(E13,Diccionario!C$2:AC$150,26,0) -> 7.97 | P13: =Q13-O13 -> 0.03 | Q13: 8 | R13: 8 | S13: 1 | T13: 1 | U13: =U12+TablaIndicador[[#This Row],[Costo Mensual]] -> 1.4224092e+09 | V13: 1.531156e+08 | W13: =IFERROR(T13*L13,0) -> 1422409157 | X13: =S13*L13 -> 1422409157 | Y13: =IFERROR(W13-U13,0) -> -0.042016029 | Z13: =W13-X13 -> 0 | AA13: =IFERROR(W13/U13,"No se realizó gasto en este corte") -> 1 | AB13: =IFERROR( IF(OR(AA13="",AA13=0), "No calculado", IF(AA13>1,"Costo eficiente: se está gastando menos de lo presupuestado", IF(AA13=1,"Costo según lo presupuestado", "Costo ineficiente: se está gastando más de lo presupuestado"))), "No calculado") -> Costo ineficiente: se está gastando más de lo presupuestado | AC13: =IFERROR(W13/X13,0) -> 1 | AD13: =IF(OR(AC13="",AC13=0),"Sin Línea Base", IF(AC13>1,"Proyecto adelantado respecto al cronograma", IF(AC13=1,"Proyecto a tiempo según lo planificado", IF(AC13<1,"Proyecto atrasado con respecto al cronograma", "No calculado")))) -> Proyecto a tiempo según lo planificado | AE13: =IFERROR(L13/AA13,0) -> 1.4224092e+09 | AF13: =IFERROR(AE13-L13,0) -> 0.042016029 | AG13: =VLOOKUP(Indicador!E13,Diccionario!C$1:AC$150,27,0) -> https://growdatasas.sharepoint.com/:x:/r/sites/Gestiondocumental/Administrativa/GD/Financiera/_layouts/15/Doc.aspx?sourcedoc=%7B453B6AA8-B631-4722-B916-8323F8C43E87%7D&file=315%20CORP%20COLOMBIA%20DIGITAL%20FNA%20AE.xlsm&action=default&mobileredirect=true | AH13: 1 | AI13: 1
A14: 2024 | B14: Enero | C14: 93afa0f2-87b4-ee11-b12b-00155d10d37b | D14: 45307.665 | E14: INFOTIC-DPC-SOC | F14: Janeth Annelise Araujo Ramos | G14: https://growdatasas.sharepoint.com/sites/pwa/INFOTIC-DPC-SOC | H14: ​Implementación y puesta en operación del Centro de Operaciones de Seguridad (SOC). | I14: TI | J14: 0320 | K14: Cerrado | L14: =VLOOKUP(E14,Diccionario!C$2:AC$150,22,0) -> 5280083724 | M14: =VLOOKUP(E14,Diccionario!C$2:AC$150,24,0) -> 45300 | N14: =VLOOKUP(E14,Diccionario!C$2:AC$150,25,0) -> 45473 | O14: =VLOOKUP(E14,Diccionario!C$2:AC$150,26,0) -> 5.7 | P14: =Q14-O14 -> -4.7 | Q14: 1 | R14: 6 | S14: 0.2 | T14: 0.25 | U14: 35266820 | V14: 35266820 | W14: =IFERROR(T14*L14,0) -> 1320020931 | X14: =S14*L14 -> 1.0560167e+09 | Y14: =IFERROR(W14-U14,0) -> 1284754111 | Z14: =W14-X14 -> 2.6400419e+08 | AA14: =IFERROR(W14/U14,"No se realizó gasto en este corte") -> 37.429542 | AB14: =IFERROR( IF(OR(AA14="",AA14=0), "No calculado", IF(AA14>1,"Costo eficiente: se está gastando menos de lo presupuestado", IF(AA14=1,"Costo según lo presupuestado", "Costo ineficiente: se está gastando más de lo presupuestado"))), "No calculado") -> Costo eficiente: se está gastando menos de lo presupuestado | AC14: =IFERROR(W14/X14,0) -> 1.25 | AD14: =IF(OR(AC14="",AC14=0),"Sin Línea Base", IF(AC14>1,"Proyecto adelantado respecto al cronograma", IF(AC14=1,"Proyecto a tiempo según lo planificado", IF(AC14<1,"Proyecto atrasado con respecto al cronograma", "No calculado")))) -> Proyecto adelantado respecto al cronograma | AE14: =IFERROR(L14/AA14,0) -> 141067280 | AF14: =IFERROR(AE14-L14,0) -> -5139016444 | AG14: =VLOOKUP(Indicador!E14,Diccionario!C$1:AC$150,27,0) -> https://growdatasas.sharepoint.com/:x:/r/sites/Gestiondocumental/Administrativa/GD/Financiera/_layouts/15/Doc.aspx?sourcedoc=%7BB4DE39AF-1EC1-466C-A807-3FE95776A982%7D&file=17012024%20INFOTIC%20DPC%20SOC%20V2.xlsm&action=default&mobileredirect=true | AH14: 1 | AI14: 1
A15: 2024 | B15: Febrero | C15: 93afa0f2-87b4-ee11-b12b-00155d10d37b | D15: 45307.665 | E15: INFOTIC-DPC-SOC | F15: Janeth Annelise Araujo Ramos | G15: https://growdatasas.sharepoint.com/sites/pwa/INFOTIC-DPC-SOC | H15: ​Implementación y puesta en operación del Centro de Operaciones de Seguridad (SOC). | I15: TI | J15: 0320 | K15: Cerrado | L15: =VLOOKUP(E15,Diccionario!C$2:AC$150,22,0) -> 5280083724 | M15: =VLOOKUP(E15,Diccionario!C$2:AC$150,24,0) -> 45300 | N15: =VLOOKUP(E15,Diccionario!C$2:AC$150,25,0) -> 45473 | O15: =VLOOKUP(E15,Diccionario!C$2:AC$150,26,0) -> 5.7 | P15: =Q15-O15 -> -3.7 | Q15: 2 | R15: 6 | S15: 0.45 | T15: 0.35 | U15: 4039374977 | V15: 4039374977 | W15: =IFERROR(T15*L15,0) -> 1.8480293e+09 | X15: =S15*L15 -> 2.3760377e+09 | Y15: =IFERROR(W15-U15,0) -> -2.1913457e+09 | Z15: =W15-X15 -> -5.2800837e+08 | AA15: =IFERROR(W15/U15,"No se realizó gasto en este corte") -> 0.45750378 | AB15: =IFERROR( IF(OR(AA15="",AA15=0), "No calculado", IF(AA15>1,"Costo eficiente: se está gastando menos de lo presupuestado", IF(AA15=1,"Costo según lo presupuestado", "Costo ineficiente: se está gastando más de lo presupuestado"))), "No calculado") -> Costo ineficiente: se está gastando más de lo presupuestado | AC15: =IFERROR(W15/X15,0) -> 0.77777778 | AD15: =IF(OR(AC15="",AC15=0),"Sin Línea Base", IF(AC15>1,"Proyecto adelantado respecto al cronograma", IF(AC15=1,"Proyecto a tiempo según lo planificado", IF(AC15<1,"Proyecto atrasado con respecto al cronograma", "No calculado")))) -> Proyecto atrasado con respecto al cronograma | AE15: =IFERROR(L15/AA15,0) -> 1.1541071e+10 | AF15: =IFERROR(AE15-L15,0) -> 6.2609876e+09 | AG15: =VLOOKUP(Indicador!E15,Diccionario!C$1:AC$150,27,0) -> https://growdatasas.sharepoint.com/:x:/r/sites/Gestiondocumental/Administrativa/GD/Financiera/_layouts/15/Doc.aspx?sourcedoc=%7BB4DE39AF-1EC1-466C-A807-3FE95776A982%7D&file=17012024%20INFOTIC%20DPC%20SOC%20V2.xlsm&action=default&mobileredirect=true | AH15: 1 | AI15: 1
A16: 2024 | B16: Marzo | C16: 93afa0f2-87b4-ee11-b12b-00155d10d37b | D16: 45307.665 | E16: INFOTIC-DPC-SOC | F16: Janeth Annelise Araujo Ramos | G16: https://growdatasas.sharepoint.com/sites/pwa/INFOTIC-DPC-SOC | H16: ​Implementación y puesta en operación del Centro de Operaciones de Seguridad (SOC). | I16: TI | J16: 0320 | K16: Cerrado | L16: =VLOOKUP(E16,Diccionario!C$2:AC$150,22,0) -> 5280083724 | M16: =VLOOKUP(E16,Diccionario!C$2:AC$150,24,0) -> 45300 | N16: =VLOOKUP(E16,Diccionario!C$2:AC$150,25,0) -> 45473 | O16: =VLOOKUP(E16,Diccionario!C$2:AC$150,26,0) -> 5.7 | P16: =Q16-O16 -> -2.7 | Q16: 3 | R16: 6 | S16: 0.6 | T16: 0.38 | U16: 1072838872 | V16: 1072838872 | W16: =IFERROR(T16*L16,0) -> 2.0064318e+09 | X16: =S16*L16 -> 3.1680502e+09 | Y16: =IFERROR(W16-U16,0) -> 9.3359294e+08 | Z16: =W16-X16 -> -1.1616184e+09 | AA16: =IFERROR(W16/U16,"No se realizó gasto en este corte") -> 1.870208 | AB16: =IFERROR( IF(OR(AA16="",AA16=0), "No calculado", IF(AA16>1,"Costo eficiente: se está gastando menos de lo presupuestado", IF(AA16=1,"Costo según lo presupuestado", "Costo ineficiente: se está gastando más de lo presupuestado"))), "No calculado") -> Costo eficiente: se está gastando menos de lo presupuestado | AC16: =IFERROR(W16/X16,0) -> 0.63333333 | AD16: =IF(OR(AC16="",AC16=0),"Sin Línea Base", IF(AC16>1,"Proyecto adelantado respecto al cronograma", IF(AC16=1,"Proyecto a tiempo según lo planificado", IF(AC16<1,"Proyecto atrasado con respecto al cronograma", "No calculado")))) -> Proyecto atrasado con respecto al cronograma | AE16: =IFERROR(L16/AA16,0) -> 2.8232602e+09 | AF16: =IFERROR(AE16-L16,0) -> -2.4568235e+09 | AG16: =VLOOKUP(Indicador!E16,Diccionario!C$1:AC$150,27,0) -> https://growdatasas.sharepoint.com/:x:/r/sites/Gestiondocumental/Administrativa/GD/Financiera/_layouts/15/Doc.aspx?sourcedoc=%7BB4DE39AF-1EC1-466C-A807-3FE95776A982%7D&file=17012024%20INFOTIC%20DPC%20SOC%20V2.xlsm&action=default&mobileredirect=true | AH16: 1 | AI16: 1
A17: 2024 | B17: Abril | C17: 93afa0f2-87b4-ee11-b12b-00155d10d37b | D17: 45307.665 | E17: INFOTIC-DPC-SOC | F17: Janeth Annelise Araujo Ramos | G17: https://growdatasas.sharepoint.com/sites/pwa/INFOTIC-DPC-SOC | H17: ​Implementación y puesta en operación del Centro de Operaciones de Seguridad (SOC). | I17: TI | J17: 0320 | K17: Cerrado | L17: =VLOOKUP(E17,Diccionario!C$2:AC$150,22,0) -> 5280083724 | M17: =VLOOKUP(E17,Diccionario!C$2:AC$150,24,0) -> 45300 | N17: =VLOOKUP(E17,Diccionario!C$2:AC$150,25,0) -> 45473 | O17: =VLOOKUP(E17,Diccionario!C$2:AC$150,26,0) -> 5.7 | P17: =Q17-O17 -> -1.7 | Q17: 4 | R17: 6 | S17: 0.75 | T17: 0.49 | U17: 35266820 | V17: 35266820 | W17: =IFERROR(T17*L17,0) -> 2.587241e+09 | X17: =S17*L17 -> 3960062793 | Y17: =IFERROR(W17-U17,0) -> 2.5519742e+09 | Z17: =W17-X17 -> -1.3728218e+09 | AA17: =IFERROR(W17/U17,"No se realizó gasto en este corte") -> 73.361903 | AB17: =IFERROR( IF(OR(AA17="",AA17=0), "No calculado", IF(AA17>1,"Costo eficiente: se está gastando menos de lo presupuestado", IF(AA17=1,"Costo según lo presupuestado", "Costo ineficiente: se está gastando más de lo presupuestado"))), "No calculado") -> Costo eficiente: se está gastando menos de lo presupuestado | AC17: =IFERROR(W17/X17,0) -> 0.65333333 | AD17: =IF(OR(AC17="",AC17=0),"Sin Línea Base", IF(AC17>1,"Proyecto adelantado respecto al cronograma", IF(AC17=1,"Proyecto a tiempo según lo planificado", IF(AC17<1,"Proyecto atrasado con respecto al cronograma", "No calculado")))) -> Proyecto atrasado con respecto al cronograma | AE17: =IFERROR(L17/AA17,0) -> 71973102 | AF17: =IFERROR(AE17-L17,0) -> -5.2081106e+09 | AG17: =VLOOKUP(Indicador!E17,Diccionario!C$1:AC$150,27,0) -> https://growdatasas.sharepoint.com/:x:/r/sites/Gestiondocumental/Administrativa/GD/Financiera/_layouts/15/Doc.aspx?sourcedoc=%7BB4DE39AF-1EC1-466C-A807-3FE95776A982%7D&file=17012024%20INFOTIC%20DPC%20SOC%20V2.xlsm&action=default&mobileredirect=true | AH17: 1 | AI17: 1
A18: 2024 | B18: Mayo | C18: 93afa0f2-87b4-ee11-b12b-00155d10d37b | D18: 45307.665 | E18: INFOTIC-DPC-SOC | F18: Janeth Annelise Araujo Ramos | G18: https://growdatasas.sharepoint.com/sites/pwa/INFOTIC-DPC-SOC | H18: ​Implementación y puesta en operación del Centro de Operaciones de Seguridad (SOC). | I18: TI | J18: 0320 | K18: Cerrado | L18: =VLOOKUP(E18,Diccionario!C$2:AC$150,22,0) -> 5280083724 | M18: =VLOOKUP(E18,Diccionario!C$2:AC$150,24,0) -> 45300 | N18: =VLOOKUP(E18,Diccionario!C$2:AC$150,25,0) -> 45473 | O18: =VLOOKUP(E18,Diccionario!C$2:AC$150,26,0) -> 5.7 | P18: =Q18-O18 -> -0.7 | Q18: 5 | R18: 6 | S18: 0.8 | T18: 0.6 | U18: 35266820 | V18: 35266820 | W18: =IFERROR(T18*L18,0) -> 3.1680502e+09 | X18: =S18*L18 -> 4.224067e+09 | Y18: =IFERROR(W18-U18,0) -> 3.1327834e+09 | Z18: =W18-X18 -> -1.0560167e+09 | AA18: =IFERROR(W18/U18,"No se realizó gasto en este corte") -> 89.830902 | AB18: =IFERROR( IF(OR(AA18="",AA18=0), "No calculado", IF(AA18>1,"Costo eficiente: se está gastando menos de lo presupuestado", IF(AA18=1,"Costo según lo presupuestado", "Costo ineficiente: se está gastando más de lo presupuestado"))), "No calculado") -> Costo eficiente: se está gastando menos de lo presupuestado | AC18: =IFERROR(W18/X18,0) -> 0.75 | AD18: =IF(OR(AC18="",AC18=0),"Sin Línea Base", IF(AC18>1,"Proyecto adelantado respecto al cronograma", IF(AC18=1,"Proyecto a tiempo según lo planificado", IF(AC18<1,"Proyecto atrasado con respecto al cronograma", "No calculado")))) -> Proyecto atrasado con respecto al cronograma | AE18: =IFERROR(L18/AA18,0) -> 58778033 | AF18: =IFERROR(AE18-L18,0) -> -5.2213057e+09 | AG18: =VLOOKUP(Indicador!E18,Diccionario!C$1:AC$150,27,0) -> https://growdatasas.sharepoint.com/:x:/r/sites/Gestiondocumental/Administrativa/GD/Financiera/_layouts/15/Doc.aspx?sourcedoc=%7BB4DE39AF-1EC1-466C-A807-3FE95776A982%7D&file=17012024%20INFOTIC%20DPC%20SOC%20V2.xlsm&action=default&mobileredirect=true | AH18: 1 | AI18: 1
A19: 2024 | B19: Junio | C19: 93afa0f2-87b4-ee11-b12b-00155d10d37b | D19: 45307.665 | E19: INFOTIC-DPC-SOC | F19: Janeth Annelise Araujo Ramos | G19: https://growdatasas.sharepoint.com/sites/pwa/INFOTIC-DPC-SOC | H19: ​Implementación y puesta en operación del Centro de Operaciones de Seguridad (SOC). | I19: TI | J19: 0320 | K19: Cerrado | L19: =VLOOKUP(E19,Diccionario!C$2:AC$150,22,0) -> 5280083724 | M19: =VLOOKUP(E19,Diccionario!C$2:AC$150,24,0) -> 45300 | N19: =VLOOKUP(E19,Diccionario!C$2:AC$150,25,0) -> 45473 | O19: =VLOOKUP(E19,Diccionario!C$2:AC$150,26,0) -> 5.7 | P19: =Q19-O19 -> 0.3 | Q19: 6 | R19: 6 | S19: 1 | T19: 0.78 | U19: 35266820 | V19: 35266820 | W19: =IFERROR(T19*L19,0) -> 4.1184653e+09 | X19: =S19*L19 -> 5280083724 | Y19: =IFERROR(W19-U19,0) -> 4.0831985e+09 | Z19: =W19-X19 -> -1.1616184e+09 | AA19: =IFERROR(W19/U19,"No se realizó gasto en este corte") -> 116.78017 | AB19: =IFERROR( IF(OR(AA19="",AA19=0), "No calculado", IF(AA19>1,"Costo eficiente: se está gastando menos de lo presupuestado", IF(AA19=1,"Costo según lo presupuestado", "Costo ineficiente: se está gastando más de lo presupuestado"))), "No calculado") -> Costo eficiente: se está gastando menos de lo presupuestado | AC19: =IFERROR(W19/X19,0) -> 0.78 | AD19: =IF(OR(AC19="",AC19=0),"Sin Línea Base", IF(AC19>1,"Proyecto adelantado respecto al cronograma", IF(AC19=1,"Proyecto a tiempo según lo planificado", IF(AC19<1,"Proyecto atrasado con respecto al cronograma", "No calculado")))) -> Proyecto atrasado con respecto al cronograma | AE19: =IFERROR(L19/AA19,0) -> 45213872 | AF19: =IFERROR(AE19-L19,0) -> -5.2348699e+09 | AG19: =VLOOKUP(Indicador!E19,Diccionario!C$1:AC$150,27,0) -> https://growdatasas.sharepoint.com/:x:/r/sites/Gestiondocumental/Administrativa/GD/Financiera/_layouts/15/Doc.aspx?sourcedoc=%7BB4DE39AF-1EC1-466C-A807-3FE95776A982%7D&file=17012024%20INFOTIC%20DPC%20SOC%20V2.xlsm&action=default&mobileredirect=true | AH19: 1 | AI19: 1
A20: 2024 | B20: Julio | C20: 93afa0f2-87b4-ee11-b12b-00155d10d37b | D20: 45307.665 | E20: INFOTIC-DPC-SOC | F20: Janeth Annelise Araujo Ramos | G20: https://growdatasas.sharepoint.com/sites/pwa/INFOTIC-DPC-SOC | H20: ​Implementación y puesta en operación del Centro de Operaciones de Seguridad (SOC). | I20: TI | J20: 0320 | K20: Cerrado | L20: =VLOOKUP(E20,Diccionario!C$2:AC$150,22,0) -> 5280083724 | M20: =VLOOKUP(E20,Diccionario!C$2:AC$150,24,0) -> 45300 | N20: =VLOOKUP(E20,Diccionario!C$2:AC$150,25,0) -> 45473 | O20: =VLOOKUP(E20,Diccionario!C$2:AC$150,26,0) -> 5.7 | P20: =Q20-O20 -> 1.3 | Q20: 7 | R20: 6 | S20: 1 | T20: 0.9 | U20: 13401297 | V20: 13401297 | W20: =IFERROR(T20*L20,0) -> 4.7520754e+09 | X20: =S20*L20 -> 5280083724 | Y20: =IFERROR(W20-U20,0) -> 4.7386741e+09 | Z20: =W20-X20 -> -5.2800837e+08 | AA20: =IFERROR(W20/U20,"No se realizó gasto en este corte") -> 354.59817 | AB20: =IFERROR( IF(OR(AA20="",AA20=0), "No calculado", IF(AA20>1,"Costo eficiente: se está gastando menos de lo presupuestado", IF(AA20=1,"Costo según lo presupuestado", "Costo ineficiente: se está gastando más de lo presupuestado"))), "No calculado") -> Costo eficiente: se está gastando menos de lo presupuestado | AC20: =IFERROR(W20/X20,0) -> 0.9 | AD20: =IF(OR(AC20="",AC20=0),"Sin Línea Base", IF(AC20>1,"Proyecto adelantado respecto al cronograma", IF(AC20=1,"Proyecto a tiempo según lo planificado", IF(AC20<1,"Proyecto atrasado con respecto al cronograma", "No calculado")))) -> Proyecto atrasado con respecto al cronograma | AE20: =IFERROR(L20/AA20,0) -> 14890330 | AF20: =IFERROR(AE20-L20,0) -> -5265193394 | AG20: =VLOOKUP(Indicador!E20,Diccionario!C$1:AC$150,27,0) -> https://growdatasas.sharepoint.com/:x:/r/sites/Gestiondocumental/Administrativa/GD/Financiera/_layouts/15/Doc.aspx?sourcedoc=%7BB4DE39AF-1EC1-466C-A807-3FE95776A982%7D&file=17012024%20INFOTIC%20DPC%20SOC%20V2.xlsm&action=default&mobileredirect=true | AH20: 1 | AI20: 1
A21: 2024 | B21: Agosto | C21: 93afa0f2-87b4-ee11-b12b-00155d10d37b | D21: 45307.665 | E21: INFOTIC-DPC-SOC | F21: Janeth Annelise Araujo Ramos | G21: https://growdatasas.sharepoint.com/sites/pwa/INFOTIC-DPC-SOC | H21: ​Implementación y puesta en operación del Centro de Operaciones de Seguridad (SOC). | I21: TI | J21: 0320 | K21: Cerrado | L21: =VLOOKUP(E21,Diccionario!C$2:AC$150,22,0) -> 5280083724 | M21: =VLOOKUP(E21,Diccionario!C$2:AC$150,24,0) -> 45300 | N21: =VLOOKUP(E21,Diccionario!C$2:AC$150,25,0) -> 45473 | O21: =VLOOKUP(E21,Diccionario!C$2:AC$150,26,0) -> 5.7 | P21: =Q21-O21 -> 2.3 | Q21: 8 | R21: 6 | S21: 1 | T21: 1 | U21: 13401297 | V21: 13401297 | W21: =IFERROR(T21*L21,0) -> 5280083724 | X21: =S21*L21 -> 5280083724 | Y21: =IFERROR(W21-U21,0) -> 5266682427 | Z21: =W21-X21 -> 0 | AA21: =IFERROR(W21/U21,"No se realizó gasto en este corte") -> 393.99796 | AB21: =IFERROR( IF(OR(AA21="",AA21=0), "No calculado", IF(AA21>1,"Costo eficiente: se está gastando menos de lo presupuestado", IF(AA21=1,"Costo según lo presupuestado", "Costo ineficiente: se está gastando más de lo presupuestado"))), "No calculado") -> Costo eficiente: se está gastando menos de lo presupuestado | AC21: =IFERROR(W21/X21,0) -> 1 | AD21: =IF(OR(AC21="",AC21=0),"Sin Línea Base", IF(AC21>1,"Proyecto adelantado respecto al cronograma", IF(AC21=1,"Proyecto a tiempo según lo planificado", IF(AC21<1,"Proyecto atrasado con respecto al cronograma", "No calculado")))) -> Proyecto a tiempo según lo planificado | AE21: =IFERROR(L21/AA21,0) -> 13401297 | AF21: =IFERROR(AE21-L21,0) -> -5266682427 | AG21: =VLOOKUP(Indicador!E21,Diccionario!C$1:AC$150,27,0) -> https://growdatasas.sharepoint.com/:x:/r/sites/Gestiondocumental/Administrativa/GD/Financiera/_layouts/15/Doc.aspx?sourcedoc=%7BB4DE39AF-1EC1-466C-A807-3FE95776A982%7D&file=17012024%20INFOTIC%20DPC%20SOC%20V2.xlsm&action=default&mobileredirect=true | AH21: 1 | AI21: 1
A22: 2024 | B22: Enero | C22: 227b8bc1-c7ab-ee11-ba7f-00155d104f2c | D22: 45296.529 | E22: CCD - DPC - IMPLEMENTACIÓN ERP | F22: Johan Sebastian Rodriguez Niño | G22: https://growdatasas.sharepoint.com/sites/pwa/CCD - DPC - IMPLEMENTACIÓN ERP | H22: Suministro e implementación del sistema de información ADMINISTRATIVO ERP NOVASOFT – versión ENTERPRISE WEB y el GESTOR DE RIESGOS para la entidad Defensoría del Pueblo.Incluye: 14 módulos específicos + 5 módulos financieros con licencia para 5000 usuarios finales, Licenciamiento de la Base de Datos SQL Server (Estándar para 8 Cores), Consultoría estándar de implementación de cada uno de los sistemas ofrecidos, soporte y actualización por 2 años y una bolsa de horas (según acuerdo por 2 años) | I22: DATOS Y SISTEMAS DE INFORMACIÓN | J22: 0318 | K22: Activo.En Ejecución | L22: =VLOOKUP(E22,Diccionario!C$2:AC$150,22,0) -> 3323223361 | M22: =VLOOKUP(E22,Diccionario!C$2:AC$150,24,0) -> 45300 | N22: =VLOOKUP(E22,Diccionario!C$2:AC$150,25,0) -> 45473 | O22: =VLOOKUP(E22,Diccionario!C$2:AC$150,26,0) -> 5.7 | P22: =Q22-O22 -> -4.7 | Q22: 1 | R22: 6 | S22: 0.2 | T22: 0.2 | W22: =IFERROR(T22*L22,0) -> 6.6464467e+08 | X22: =S22*L22 -> 6.6464467e+08 | Y22: =IFERROR(W22-U22,0) -> 6.6464467e+08 | Z22: =W22-X22 -> 0 | AA22: =IFERROR(W22/U22,"No se realizó gasto en este corte") -> No se realizó gasto en este corte | AB22: =IFERROR( IF(OR(AA22="",AA22=0), "No calculado", IF(AA22>1,"Costo eficiente: se está gastando menos de lo presupuestado", IF(AA22=1,"Costo según lo presupuestado", "Costo ineficiente: se está gastando más de lo presupuestado"))), "No calculado") -> Costo eficiente: se está gastando menos de lo presupuestado | AC22: =IFERROR(W22/X22,0) -> 1 | AD22: =IF(OR(AC22="",AC22=0),"Sin Línea Base", IF(AC22>1,"Proyecto adelantado respecto al cronograma", IF(AC22=1,"Proyecto a tiempo según lo planificado", IF(AC22<1,"Proyecto atrasado con respecto al cronograma", "No calculado")))) -> Proyecto a tiempo según lo planificado | AE22: =IFERROR(L22/AA22,0) -> 0 | AF22: =IFERROR(AE22-L22,0) -> -3323223361 | AG22: =VLOOKUP(Indicador!E22,Diccionario!C$1:AC$150,27,0) -> https://growdatasas.sharepoint.com/:x:/r/sites/Gestiondocumental/Administrativa/GD/Financiera/_layouts/15/Doc.aspx?sourcedoc=%7BC3EFE0E2-C211-45B0-905D-ECEF11221767%7D&file=299.%20DEFENSORIA_ERP.xlsm&action=default&mobileredirect=true | AH22: 1 | AI22: 1
A23: 2024 | B23: Febrero | C23: 227b8bc1-c7ab-ee11-ba7f-00155d104f2c | D23: 45296.529 | E23: CCD - DPC - IMPLEMENTACIÓN ERP | F23: Johan Sebastian Rodriguez Niño | G23: https://growdatasas.sharepoint.com/sites/pwa/CCD - DPC - IMPLEMENTACIÓN ERP | H23: Suministro e implementación del sistema de información ADMINISTRATIVO ERP NOVASOFT – versión ENTERPRISE WEB y el GESTOR DE RIESGOS para la entidad Defensoría del Pueblo.Incluye: 14 módulos específicos + 5 módulos financieros con licencia para 5000 usuarios finales, Licenciamiento de la Base de Datos SQL Server (Estándar para 8 Cores), Consultoría estándar de implementación de cada uno de los sistemas ofrecidos, soporte y actualización por 2 años y una bolsa de horas (según acuerdo por 2 años) | I23: DATOS Y SISTEMAS DE INFORMACIÓN | J23: 0318 | K23: Activo.En Ejecución | L23: =VLOOKUP(E23,Diccionario!C$2:AC$150,22,0) -> 3323223361 | M23: =VLOOKUP(E23,Diccionario!C$2:AC$150,24,0) -> 45300 | N23: =VLOOKUP(E23,Diccionario!C$2:AC$150,25,0) -> 45473 | O23: =VLOOKUP(E23,Diccionario!C$2:AC$150,26,0) -> 5.7 | P23: =Q23-O23 -> -3.7 | Q23: 2 | R23: 6 | S23: 0.3 | T23: 0.3 | W23: =IFERROR(T23*L23,0) -> 9.9696701e+08 | X23: =S23*L23 -> 9.9696701e+08 | Y23: =IFERROR(W23-U23,0) -> 9.9696701e+08 | Z23: =W23-X23 -> 0 | AA23: =IFERROR(W23/U23,"No se realizó gasto en este corte") -> No se realizó gasto en este corte | AB23: =IFERROR( IF(OR(AA23="",AA23=0), "No calculado", IF(AA23>1,"Costo eficiente: se está gastando menos de lo presupuestado", IF(AA23=1,"Costo según lo presupuestado", "Costo ineficiente: se está gastando más de lo presupuestado"))), "No calculado") -> Costo eficiente: se está gastando menos de lo presupuestado | AC23: =IFERROR(W23/X23,0) -> 1 | AD23: =IF(OR(AC23="",AC23=0),"Sin Línea Base", IF(AC23>1,"Proyecto adelantado respecto al cronograma", IF(AC23=1,"Proyecto a tiempo según lo planificado", IF(AC23<1,"Proyecto atrasado con respecto al cronograma", "No calculado")))) -> Proyecto a tiempo según lo planificado | AE23: =IFERROR(L23/AA23,0) -> 0 | AF23: =IFERROR(AE23-L23,0) -> -3323223361 | AG23: =VLOOKUP(Indicador!E23,Diccionario!C$1:AC$150,27,0) -> https://growdatasas.sharepoint.com/:x:/r/sites/Gestiondocumental/Administrativa/GD/Financiera/_layouts/15/Doc.aspx?sourcedoc=%7BC3EFE0E2-C211-45B0-905D-ECEF11221767%7D&file=299.%20DEFENSORIA_ERP.xlsm&action=default&mobileredirect=true | AH23: 1 | AI23: 1
A24: 2024 | B24: Marzo | C24: 227b8bc1-c7ab-ee11-ba7f-00155d104f2c | D24: 45296.529 | E24: CCD - DPC - IMPLEMENTACIÓN ERP | F24: Johan Sebastian Rodriguez Niño | G24: https://growdatasas.sharepoint.com/sites/pwa/CCD - DPC - IMPLEMENTACIÓN ERP | H24: Suministro e implementación del sistema de información ADMINISTRATIVO ERP NOVASOFT – versión ENTERPRISE WEB y el GESTOR DE RIESGOS para la entidad Defensoría del Pueblo.Incluye: 14 módulos específicos + 5 módulos financieros con licencia para 5000 usuarios finales, Licenciamiento de la Base de Datos SQL Server (Estándar para 8 Cores), Consultoría estándar de implementación de cada uno de los sistemas ofrecidos, soporte y actualización por 2 años y una bolsa de horas (según acuerdo por 2 años) | I24: DATOS Y SISTEMAS DE INFORMACIÓN | J24: 0318 | K24: Activo.En Ejecución | L24: =VLOOKUP(E24,Diccionario!C$2:AC$150,22,0) -> 3323223361 | M24: =VLOOKUP(E24,Diccionario!C$2:AC$150,24,0) -> 45300 | N24: =VLOOKUP(E24,Diccionario!C$2:AC$150,25,0) -> 45473 | O24: =VLOOKUP(E24,Diccionario!C$2:AC$150,26,0) -> 5.7 | P24: =Q24-O24 -> 24.3 | Q24: =DATEDIF(M24,TODAY(),"m") -> 30 | R24: 6 | S24: 0.5 | T24: 0.4 | W24: =IFERROR(T24*L24,0) -> 1.3292893e+09 | X24: =S24*L24 -> 1.6616117e+09 | Y24: =IFERROR(W24-U24,0) -> 1.3292893e+09 | Z24: =W24-X24 -> -3.3232234e+08 | AA24: =IFERROR(W24/U24,"No se realizó gasto en este corte") -> No se realizó gasto en este corte | AB24: =IFERROR( IF(OR(AA24="",AA24=0), "No calculado", IF(AA24>1,"Costo eficiente: se está gastando menos de lo presupuestado", IF(AA24=1,"Costo según lo presupuestado", "Costo ineficiente: se está gastando más de lo presupuestado"))), "No calculado") -> Costo eficiente: se está gastando menos de lo presupuestado | AC24: =IFERROR(W24/X24,0) -> 0.8 | AD24: =IF(OR(AC24="",AC24=0),"Sin Línea Base", IF(AC24>1,"Proyecto adelantado respecto al cronograma", IF(AC24=1,"Proyecto a tiempo según lo planificado", IF(AC24<1,"Proyecto atrasado con respecto al cronograma", "No calculado")))) -> Proyecto atrasado con respecto al cronograma | AE24: =IFERROR(L24/AA24,0) -> 0 | AF24: =IFERROR(AE24-L24,0) -> -3323223361 | AG24: =VLOOKUP(Indicador!E24,Diccionario!C$1:AC$150,27,0) -> https://growdatasas.sharepoint.com/:x:/r/sites/Gestiondocumental/Administrativa/GD/Financiera/_layouts/15/Doc.aspx?sourcedoc=%7BC3EFE0E2-C211-45B0-905D-ECEF11221767%7D&file=299.%20DEFENSORIA_ERP.xlsm&action=default&mobileredirect=true | AH24: 1 | AI24: 1
A25: 2024 | B25: Abril | C25: 227b8bc1-c7ab-ee11-ba7f-00155d104f2c | D25: 45296.529 | E25: CCD - DPC - IMPLEMENTACIÓN ERP | F25: Johan Sebastian Rodriguez Niño | G25: https://growdatasas.sharepoint.com/sites/pwa/CCD - DPC - IMPLEMENTACIÓN ERP | H25: Suministro e implementación del sistema de información ADMINISTRATIVO ERP NOVASOFT – versión ENTERPRISE WEB y el GESTOR DE RIESGOS para la entidad Defensoría del Pueblo.Incluye: 14 módulos específicos + 5 módulos financieros con licencia para 5000 usuarios finales, Licenciamiento de la Base de Datos SQL Server (Estándar para 8 Cores), Consultoría estándar de implementación de cada uno de los sistemas ofrecidos, soporte y actualización por 2 años y una bolsa de horas (según acuerdo por 2 años) | I25: DATOS Y SISTEMAS DE INFORMACIÓN | J25: 0318 | K25: Activo.En Ejecución | L25: =VLOOKUP(E25,Diccionario!C$2:AC$150,22,0) -> 3323223361 | M25: =VLOOKUP(E25,Diccionario!C$2:AC$150,24,0) -> 45300 | N25: =VLOOKUP(E25,Diccionario!C$2:AC$150,25,0) -> 45473 | O25: =VLOOKUP(E25,Diccionario!C$2:AC$150,26,0) -> 5.7 | P25: =Q25-O25 -> 24.3 | Q25: =DATEDIF(M25,TODAY(),"m") -> 30 | R25: 6 | S25: 0.75 | T25: =T24+0.02 -> 0.42 | W25: =IFERROR(T25*L25,0) -> 1.3957538e+09 | X25: =S25*L25 -> 2.4924175e+09 | Y25: =IFERROR(W25-U25,0) -> 1.3957538e+09 | Z25: =W25-X25 -> -1.0966637e+09 | AA25: =IFERROR(W25/U25,"No se realizó gasto en este corte") -> No se realizó gasto en este corte | AB25: =IFERROR( IF(OR(AA25="",AA25=0), "No calculado", IF(AA25>1,"Costo eficiente: se está gastando menos de lo presupuestado", IF(AA25=1,"Costo según lo presupuestado", "Costo ineficiente: se está gastando más de lo presupuestado"))), "No calculado") -> Costo eficiente: se está gastando menos de lo presupuestado | AC25: =IFERROR(W25/X25,0) -> 0.56 | AD25: =IF(OR(AC25="",AC25=0),"Sin Línea Base", IF(AC25>1,"Proyecto adelantado respecto al cronograma", IF(AC25=1,"Proyecto a tiempo según lo planificado", IF(AC25<1,"Proyecto atrasado con respecto al cronograma", "No calculado")))) -> Proyecto atrasado con respecto al cronograma | AE25: =IFERROR(L25/AA25,0) -> 0 | AF25: =IFERROR(AE25-L25,0) -> -3323223361 | AG25: =VLOOKUP(Indicador!E25,Diccionario!C$1:AC$150,27,0) -> https://growdatasas.sharepoint.com/:x:/r/sites/Gestiondocumental/Administrativa/GD/Financiera/_layouts/15/Doc.aspx?sourcedoc=%7BC3EFE0E2-C211-45B0-905D-ECEF11221767%7D&file=299.%20DEFENSORIA_ERP.xlsm&action=default&mobileredirect=true | AH25: 1 | AI25: 1
A26: 2024 | B26: Mayo | C26: 227b8bc1-c7ab-ee11-ba7f-00155d104f2c | D26: 45296.529 | E26: CCD - DPC - IMPLEMENTACIÓN ERP | F26: Johan Sebastian Rodriguez Niño | G26: https://growdatasas.sharepoint.com/sites/pwa/CCD - DPC - IMPLEMENTACIÓN ERP | H26: Suministro e implementación del sistema de información ADMINISTRATIVO ERP NOVASOFT – versión ENTERPRISE WEB y el GESTOR DE RIESGOS para la entidad Defensoría del Pueblo.Incluye: 14 módulos específicos + 5 módulos financieros con licencia para 5000 usuarios finales, Licenciamiento de la Base de Datos SQL Server (Estándar para 8 Cores), Consultoría estándar de implementación de cada uno de los sistemas ofrecidos, soporte y actualización por 2 años y una bolsa de horas (según acuerdo por 2 años) | I26: DATOS Y SISTEMAS DE INFORMACIÓN | J26: 0318 | K26: Activo.En Ejecución | L26: =VLOOKUP(E26,Diccionario!C$2:AC$150,22,0) -> 3323223361 | M26: =VLOOKUP(E26,Diccionario!C$2:AC$150,24,0) -> 45300 | N26: =VLOOKUP(E26,Diccionario!C$2:AC$150,25,0) -> 45473 | O26: =VLOOKUP(E26,Diccionario!C$2:AC$150,26,0) -> 5.7 | P26: =Q26-O26 -> 24.3 | Q26: =DATEDIF(M26,TODAY(),"m") -> 30 | R26: 6 | S26: 0.8 | T26: =T25+0.02 -> 0.44 | W26: =IFERROR(T26*L26,0) -> 1.4622183e+09 | X26: =S26*L26 -> 2.6585787e+09 | Y26: =IFERROR(W26-U26,0) -> 1.4622183e+09 | Z26: =W26-X26 -> -1.1963604e+09 | AA26: =IFERROR(W26/U26,"No se realizó gasto en este corte") -> No se realizó gasto en este corte | AB26: =IFERROR( IF(OR(AA26="",AA26=0), "No calculado", IF(AA26>1,"Costo eficiente: se está gastando menos de lo presupuestado", IF(AA26=1,"Costo según lo presupuestado", "Costo ineficiente: se está gastando más de lo presupuestado"))), "No calculado") -> Costo eficiente: se está gastando menos de lo presupuestado | AC26: =IFERROR(W26/X26,0) -> 0.55 | AD26: =IF(OR(AC26="",AC26=0),"Sin Línea Base", IF(AC26>1,"Proyecto adelantado respecto al cronograma", IF(AC26=1,"Proyecto a tiempo según lo planificado", IF(AC26<1,"Proyecto atrasado con respecto al cronograma", "No calculado")))) -> Proyecto atrasado con respecto al cronograma | AE26: =IFERROR(L26/AA26,0) -> 0 | AF26: =IFERROR(AE26-L26,0) -> -3323223361 | AG26: =VLOOKUP(Indicador!E26,Diccionario!C$1:AC$150,27,0) -> https://growdatasas.sharepoint.com/:x:/r/sites/Gestiondocumental/Administrativa/GD/Financiera/_layouts/15/Doc.aspx?sourcedoc=%7BC3EFE0E2-C211-45B0-905D-ECEF11221767%7D&file=299.%20DEFENSORIA_ERP.xlsm&action=default&mobileredirect=true | AH26: 1 | AI26: 1
