Workbook

Sheet Indicador
A1: Año | B1: Mes | C1: ProjectId | D1: ProjectCreatedDate | E1: ProjectName | F1: ProjectOwnerName | G1: ProjectWorkspaceInternalUrl | H1: Objetocontractual | I1: Portafolio | J1: CentrodeCostosProyecto | K1: Estado | L1: Presupuesto | M1: Inicio | N1: Fin | O1: Meses | P1: Tiempo Diferencia | Q1: Tiempo Ejecución | R1: Tiempo Proyectado | S1: % Planeado | T1: Completado Real | U1: AC (Actual Cost) | V1: Costo Mensual | W1: EV (Earned Value) | X1: PV (Planned Value) | Y1: CV (Cost Variance) | Z1: SV (Schedule Variance) | AA1: CPI (Cost Performance Index) | AB1: Detalle de CPI | AC1: SPI (Schedule Performance Index) | AD1: Detalle SPI | AE1: EAC (Estimación al finalizar) | AF1: VAC (Exceso de presupuesto proyectado) | AG1: Ruta | AH1: Meta SPI | AI1: Meta CPI | AJ1: Estado CMMI | AK1: Columna1
A2: 2024 | B2: Enero | C2: 227b8bc1-c7ab-ee11-ba7f-00155d104f2c | D2: 45296.529 | E2: CCD - DPC - IMPLEMENTACIÓN ERP | F2: Johan Sebastian Rodriguez Niño | G2: https://growdatasas.sharepoint.com/sites/pwa/CCD - DPC - IMPLEMENTACIÓN ERP | H2: Suministro e implementación del sistema de información ADMINISTRATIVO ERP NOVASOFT – versión ENTERPRISE WEB y el GESTOR DE RIESGOS para la entidad Defensoría del Pueblo.Incluye: 14 módulos específicos + 5 módulos financieros con licencia para 5000 usuarios finales, Licenciamiento de la Base de Datos SQL Server (Estándar para 8 Cores), Consultoría estándar de implementación de cada uno de los sistemas ofrecidos, soporte y actualización por 2 años y una bolsa de horas (según acuerdo por 2 años) | I2: DATOS Y SISTEMAS DE INFORMACIÓN | J2: 0318 | K2: Activo.En Ejecución | L2: =VLOOKUP(E2,[1]Diccionario!C$2:AC$150,22,0) -> 3323223361 | M2: =VLOOKUP(E2,[1]Diccionario!C$2:AC$150,24,0) -> 45300 | N2: =VLOOKUP(E2,[1]Diccionario!C$2:AC$150,25,0) -> 45473 | O2: =VLOOKUP(E2,[1]Diccionario!C$2:AC$150,26,0) -> 5.7 | P2: =Q2-O2 -> -4.7 | Q2: 1 | R2: 6 | S2: 0.2 | T2: 0.2 | U2: =TablaIndicador[[#This Row],[Costo Mensual]] -> 0 | W2: =IFERROR(T2*L2,0) -> 6.6464467e+08 | X2: =S2*L2 -> 6.6464467e+08 | Y2: =IFERROR(W2-U2,0) -> 6.6464467e+08 | Z2: =W2-X2 -> 0 | AA2: =IFERROR(W2/U2,"No se realizó gasto en este corte") -> No se realizó gasto en este corte | AB2: =IFERROR( IF(OR(AA2="",AA2=0), "No calculado", IF(AA2>1,"Costo eficiente: se está gastando menos de lo presupuestado", IF(AA2=1,"Costo según lo presupuestado", "Costo ineficiente: se está gastando más de lo presupuestado"))), "No calculado") -> Costo eficiente: se está gastando menos de lo presupuestado | AC2: =IFERROR(W2/X2,0) -> 1 | AD2: =IF(OR(AC2="",AC2=0),"Sin Línea Base", IF(AC2>1,"Proyecto adelantado respecto al cronograma", IF(AC2=1,"Proyecto a tiempo según lo planificado", IF(AC2<1,"Proyecto atrasado con respecto al cronograma", "No calculado")))) -> Proyecto a tiempo según lo planificado | AE2: =IFERROR(L2/AA2,0) -> 0 | AF2: =IFERROR(AE2-L2,0) -> -3323223361 | AG2: =VLOOKUP(Indicador!E25,[1]Diccionario!C$1:AC$150,27,0) -> https://growdatasas.sharepoint.com/:x:/r/sites/Gestiondocumental/Administrativa/GD/Financiera/_layouts/15/Doc.aspx?sourcedoc=%7BC3EFE0E2-C211-45B0-905D-ECEF11221767%7D&file=299.%20DEFENSORIA_ERP.xlsm&action=default&mobileredirect=true | AH2: 1 | AI2: 1 | AJ2: ok
A3: 2024 | B3: Febrero | C3: 227b8bc1-c7ab-ee11-ba7f-00155d104f2c | D3: 45296.529 | E3: CCD - DPC - IMPLEMENTACIÓN ERP | F3: Johan Sebastian Rodriguez Niño | G3: https://growdatasas.sharepoint.com/sites/pwa/CCD - DPC - IMPLEMENTACIÓN ERP | H3: Suministro e implementación del sistema de información ADMINISTRATIVO ERP NOVASOFT – versión ENTERPRISE WEB y el GESTOR DE RIESGOS para la entidad Defensoría del Pueblo.Incluye: 14 módulos específicos + 5 módulos financieros con licencia para 5000 usuarios finales, Licenciamiento de la Base de Datos SQL Server (Estándar para 8 Cores), Consultoría estándar de implementación de cada uno de los sistemas ofrecidos, soporte y actualización por 2 años y una bolsa de horas (según acuerdo por 2 años) | I3: DATOS Y SISTEMAS DE INFORMACIÓN | J3: 0318 | K3: Activo.En Ejecución | L3: =VLOOKUP(E3,[1]Diccionario!C$2:AC$150,22,0) -> 3323223361 | M3: =VLOOKUP(E3,[1]Diccionario!C$2:AC$150,24,0) -> 45300 | N3: =VLOOKUP(E3,[1]Diccionario!C$2:AC$150,25,0) -> 45473 | O3: =VLOOKUP(E3,[1]Diccionario!C$2:AC$150,26,0) -> 5.7 | P3: =Q3-O3 -> -3.7 | Q3: 2 | R3: 6 | S3: 0.3 | T3: 0.3 | U3: =U2+TablaIndicador[[#This Row],[Costo Mensual]] -> 0 | W3: =IFERROR(T3*L3,0) -> 9.9696701e+08 | X3: =S3*L3 -> 9.9696701e+08 | Y3: =IFERROR(W3-U3,0) -> 9.9696701e+08 | Z3: =W3-X3 -> 0 | AA3: =IFERROR(W3/U3,"No se realizó gasto en este corte") -> No se realizó gasto en este corte | AB3: =IFERROR( IF(OR(AA3="",AA3=0), "No calculado", IF(AA3>1,"Costo eficiente: se está gastando menos de lo presupuestado", IF(AA3=1,"Costo según lo presupuestado", "Costo ineficiente: se está gastando más de lo presupuestado"))), "No calculado") -> Costo eficiente: se está gastando menos de lo presupuestado | AC3: =IFERROR(W3/X3,0) -> 1 | AD3: =IF(OR(AC3="",AC3=0),"Sin Línea Base", IF(AC3>1,"Proyecto adelantado respecto al cronograma", IF(AC3=1,"Proyecto a tiempo según lo planificado", IF(AC3<1,"Proyecto atrasado con respecto al cronograma", "No calculado")))) -> Proyecto a tiempo según lo planificado | AE3: =IFERROR(L3/AA3,0) -> 0 | AF3: =IFERROR(AE3-L3,0) -> -3323223361 | AG3: =VLOOKUP(Indicador!E26,[1]Diccionario!C$1:AC$150,27,0) -> https://growdatasas.sharepoint.com/:x:/r/sites/Gestiondocumental/Administrativa/GD/Financiera/_layouts/15/Doc.aspx?sourcedoc=%7BC3EFE0E2-C211-45B0-905D-ECEF11221767%7D&file=299.%20DEFENSORIA_ERP.xlsm&action=default&mobileredirect=true | AH3: 1 | AI3: 1 | AJ3: ok
A4: 2024 | B4: Marzo | C4: 227b8bc1-c7ab-ee11-ba7f-00155d104f2c | D4: 45296.529 | E4: CCD - DPC - IMPLEMENTACIÓN ERP | F4: Johan Sebastian Rodriguez Niño | G4: https://growdatasas.sharepoint.com/sites/pwa/CCD - DPC - IMPLEMENTACIÓN ERP | H4: Suministro e implementación del sistema de información ADMINISTRATIVO ERP NOVASOFT – versión ENTERPRISE WEB y el GESTOR DE RIESGOS para la entidad Defensoría del Pueblo.Incluye: 14 módulos específicos + 5 módulos financieros con licencia para 5000 usuarios finales, Licenciamiento de la Base de Datos SQL Server (Estándar para 8 Cores), Consultoría estándar de implementación de cada uno de los sistemas ofrecidos, soporte y actualización por 2 años y una bolsa de horas (según acuerdo por 2 años) | I4: DATOS Y SISTEMAS DE INFORMACIÓN | J4: 0318 | K4: Activo.En Ejecución | L4: =VLOOKUP(E4,[1]Diccionario!C$2:AC$150,22,0) -> 3323223361 | M4: =VLOOKUP(E4,[1]Diccionario!C$2:AC$150,24,0) -> 45300 | N4: =VLOOKUP(E4,[1]Diccionario!C$2:AC$150,25,0) -> 45473 | O4: =VLOOKUP(E4,[1]Diccionario!C$2:AC$150,26,0) -> 5.7 | P4: =Q4-O4 -> 20.3 | Q4: =DATEDIF(M4,TODAY(),"m") -> 26 | R4: 6 | S4: 0.5 | T4: 0.4 | U4: =U3+TablaIndicador[[#This Row],[Costo Mensual]] -> 0 | W4: =IFERROR(T4*L4,0) -> 1.3292893e+09 | X4: =S4*L4 -> 1.6616117e+09 | Y4: =IFERROR(W4-U4,0) -> 1.3292893e+09 | Z4: =W4-X4 -> -3.3232234e+08 | AA4: =IFERROR(W4/U4,"No se realizó gasto en este corte") -> No se realizó gasto en este corte | AB4: =IFERROR( IF(OR(AA4="",AA4=0), "No calculado", IF(AA4>1,"Costo eficiente: se está gastando menos de lo presupuestado", IF(AA4=1,"Costo según lo presupuestado", "Costo ineficiente: se está gastando más de lo presupuestado"))), "No calculado") -> Costo eficiente: se está gastando menos de lo presupuestado | AC4: =IFERROR(W4/X4,0) -> 0.8 | AD4: =IF(OR(AC4="",AC4=0),"Sin Línea Base", IF(AC4>1,"Proyecto adelantado respecto al cronograma", IF(AC4=1,"Proyecto a tiempo según lo planificado", IF(AC4<1,"Proyecto atrasado con respecto al cronograma", "No calculado")))) -> Proyecto atrasado con respecto al cronograma | AE4: =IFERROR(L4/AA4,0) -> 0 | AF4: =IFERROR(AE4-L4,0) -> -3323223361 | AG4: =VLOOKUP(Indicador!E27,[1]Diccionario!C$1:AC$150,27,0) -> https://growdatasas.sharepoint.com/:x:/r/sites/Gestiondocumental/Administrativa/GD/Financiera/_layouts/15/Doc.aspx?sourcedoc=%7BC3EFE0E2-C211-45B0-905D-ECEF11221767%7D&file=299.%20DEFENSORIA_ERP.xlsm&action=default&mobileredirect=true | AH4: 1 | AI4: 1 | AJ4: ok
A5: 2024 | B5: Abril | C5: 227b8bc1-c7ab-ee11-ba7f-00155d104f2c | D5: 45296.529 | E5: CCD - DPC - IMPLEMENTACIÓN ERP | F5: Johan Sebastian Rodriguez Niño | G5: https://growdatasas.sharepoint.com/sites/pwa/CCD - DPC - IMPLEMENTACIÓN ERP | H5: Suministro e implementación del sistema de información ADMINISTRATIVO ERP NOVASOFT – versión ENTERPRISE WEB y el GESTOR DE RIESGOS para la entidad Defensoría del Pueblo.Incluye: 14 módulos específicos + 5 módulos financieros con licencia para 5000 usuarios finales, Licenciamiento de la Base de Datos SQL Server (Estándar para 8 Cores), Consultoría estándar de implementación de cada uno de los sistemas ofrecidos, soporte y actualización por 2 años y una bolsa de horas (según acuerdo por 2 años) | I5: DATOS Y SISTEMAS DE INFORMACIÓN | J5: 0318 | K5: Activo.En Ejecución | L5: =VLOOKUP(E5,[1]Diccionario!C$2:AC$150,22,0) -> 3323223361 | M5: =VLOOKUP(E5,[1]Diccionario!C$2:AC$150,24,0) -> 45300 | N5: =VLOOKUP(E5,[1]Diccionario!C$2:AC$150,25,0) -> 45473 | O5: =VLOOKUP(E5,[1]Diccionario!C$2:AC$150,26,0) -> 5.7 | P5: =Q5-O5 -> 20.3 | Q5: =DATEDIF(M5,TODAY(),"m") -> 26 | R5: 6 | S5: 0.75 | T5: =T4+0.02 -> 0.42 | U5: =U4+TablaIndicador[[#This Row],[Costo Mensual]] -> 0 | W5: =IFERROR(T5*L5,0) -> 1.3957538e+09 | X5: =S5*L5 -> 2.4924175e+09 | Y5: =IFERROR(W5-U5,0) -> 1.3957538e+09 | Z5: =W5-X5 -> -1.0966637e+09 | AA5: =IFERROR(W5/U5,"No se realizó gasto en este corte") -> No se realizó gasto en este corte | AB5: =IFERROR( IF(OR(AA5="",AA5=0), "No calculado", IF(AA5>1,"Costo eficiente: se está gastando menos de lo presupuestado", IF(AA5=1,"Costo según lo presupuestado", "Costo ineficiente: se está gastando más de lo presupuestado"))), "No calculado") -> Costo eficiente: se está gastando menos de lo presupuestado | AC5: =IFERROR(W5/X5,0) -> 0.56 | AD5: =IF(OR(AC5="",AC5=0),"Sin Línea Base", IF(AC5>1,"Proyecto adelantado respecto al cronograma", IF(AC5=1,"Proyecto a tiempo según lo planificado", IF(AC5<1,"Proyecto atrasado con respecto al cronograma", "No calculado")))) -> Proyecto atrasado con respecto al cronograma | AE5: =IFERROR(L5/AA5,0) -> 0 | AF5: =IFERROR(AE5-L5,0) -> -3323223361 | AG5: =VLOOKUP(Indicador!E28,[1]Diccionario!C$1:AC$150,27,0) -> https://growdatasas.sharepoint.com/:x:/r/sites/Gestiondocumental/Administrativa/GD/Financiera/_layouts/15/Doc.aspx?sourcedoc=%7B4F9BD6BF-F6F0-4033-84A5-4B5D6077FC32%7D&file=314.%20TELEFONICA%20%E2%80%93%20DPC%20%20SALA%20DE%20ANALITICA.xlsx&action=default&mobileredirect=true | AH5: 1 | AI5: 1 | AJ5: ok
A6: 2024 | B6: Mayo | C6: 227b8bc1-c7ab-ee11-ba7f-00155d104f2c | D6: 45296.529 | E6: CCD - DPC - IMPLEMENTACIÓN ERP | F6: Johan Sebastian Rodriguez Niño | G6: https://growdatasas.sharepoint.com/sites/pwa/CCD - DPC - IMPLEMENTACIÓN ERP | H6: Suministro e implementación del sistema de información ADMINISTRATIVO ERP NOVASOFT – versión ENTERPRISE WEB y el GESTOR DE RIESGOS para la entidad Defensoría del Pueblo.Incluye: 14 módulos específicos + 5 módulos financieros con licencia para 5000 usuarios finales, Licenciamiento de la Base de Datos SQL Server (Estándar para 8 Cores), Consultoría estándar de implementación de cada uno de los sistemas ofrecidos, soporte y actualización por 2 años y una bolsa de horas (según acuerdo por 2 años) | I6: DATOS Y SISTEMAS DE INFORMACIÓN | J6: 0318 | K6: Activo.En Ejecución | L6: =VLOOKUP(E6,[1]Diccionario!C$2:AC$150,22,0) -> 3323223361 | M6: =VLOOKUP(E6,[1]Diccionario!C$2:AC$150,24,0) -> 45300 | N6: =VLOOKUP(E6,[1]Diccionario!C$2:AC$150,25,0) -> 45473 | O6: =VLOOKUP(E6,[1]Diccionario!C$2:AC$150,26,0) -> 5.7 | P6: =Q6-O6 -> 20.3 | Q6: =DATEDIF(M6,TODAY(),"m") -> 26 | R6: 6 | S6: 0.8 | T6: =T5+0.02 -> 0.44 | U6: =U5+TablaIndicador[[#This Row],[Costo Mensual]] -> 0 | W6: =IFERROR(T6*L6,0) -> 1.4622183e+09 | X6: =S6*L6 -> 2.6585787e+09 | Y6: =IFERROR(W6-U6,0) -> 1.4622183e+09 | Z6: =W6-X6 -> -1.1963604e+09 | AA6: =IFERROR(W6/U6,"No se realizó gasto en este corte") -> No se realizó gasto en este corte | AB6: =IFERROR( IF(OR(AA6="",AA6=0), "No calculado", IF(AA6>1,"Costo eficiente: se está gastando menos de lo presupuestado", IF(AA6=1,"Costo según lo presupuestado", "Costo ineficiente: se está gastando más de lo presupuestado"))), "No calculado") -> Costo eficiente: se está gastando menos de lo presupuestado | AC6: =IFERROR(W6/X6,0) -> 0.55 | AD6: =IF(OR(AC6="",AC6=0),"Sin Línea Base", IF(AC6>1,"Proyecto adelantado respecto al cronograma", IF(AC6=1,"Proyecto a tiempo según lo planificado", IF(AC6<1,"Proyecto atrasado con respecto al cronograma", "No calculado")))) -> Proyecto atrasado con respecto al cronograma | AE6: =IFERROR(L6/AA6,0) -> 0 | AF6: =IFERROR(AE6-L6,0) -> -3323223361 | AG6: =VLOOKUP(Indicador!E29,[1]Diccionario!C$1:AC$150,27,0) -> https://growdatasas.sharepoint.com/:x:/r/sites/Gestiondocumental/Administrativa/GD/Financiera/_layouts/15/Doc.aspx?sourcedoc=%7B4F9BD6BF-F6F0-4033-84A5-4B5D6077FC32%7D&file=314.%20TELEFONICA%20%E2%80%93%20DPC%20%20SALA%20DE%20ANALITICA.xlsx&action=default&mobileredirect=true | AH6: 1 | AI6: 1 | AJ6: ok
A7: 2024 | B7: Junio | C7: 227b8bc1-c7ab-ee11-ba7f-00155d104f2c | D7: 45296.529 | E7: CCD - DPC - IMPLEMENTACIÓN ERP | F7: Johan Sebastian Rodriguez Niño | G7: https://growdatasas.sharepoint.com/sites/pwa/CCD - DPC - IMPLEMENTACIÓN ERP | H7: Suministro e implementación del sistema de información ADMINISTRATIVO ERP NOVASOFT – versión ENTERPRISE WEB y el GESTOR DE RIESGOS para la entidad Defensoría del Pueblo.Incluye: 14 módulos específicos + 5 módulos financieros con licencia para 5000 usuarios finales, Licenciamiento de la Base de Datos SQL Server (Estándar para 8 Cores), Consultoría estándar de implementación de cada uno de los sistemas ofrecidos, soporte y actualización por 2 años y una bolsa de horas (según acuerdo por 2 años) | I7: DATOS Y SISTEMAS DE INFORMACIÓN | J7: 0318 | K7: Activo.En Ejecución | L7: =VLOOKUP(E7,[1]Diccionario!C$2:AC$150,22,0) -> 3323223361 | M7: =VLOOKUP(E7,[1]Diccionario!C$2:AC$150,24,0) -> 45300 | N7: =VLOOKUP(E7,[1]Diccionario!C$2:AC$150,25,0) -> 45473 | O7: =VLOOKUP(E7,[1]Diccionario!C$2:AC$150,26,0) -> 5.7 | P7: =Q7-O7 -> 20.3 | Q7: =DATEDIF(M7,TODAY(),"m") -> 26 | R7: 6 | S7: 1 | T7: =T6+0.02 -> 0.46 | U7: =U6+TablaIndicador[[#This Row],[Costo Mensual]] -> 0 | W7: =IFERROR(T7*L7,0) -> 1.5286827e+09 | X7: =S7*L7 -> 3323223361 | Y7: =IFERROR(W7-U7,0) -> 1.5286827e+09 | Z7: =W7-X7 -> -1.7945406e+09 | AA7: =IFERROR(W7/U7,"No se realizó gasto en este corte") -> No se realizó gasto en este corte | AB7: =IFERROR( IF(OR(AA7="",AA7=0), "No calculado", IF(AA7>1,"Costo eficiente: se está gastando menos de lo presupuestado", IF(AA7=1,"Costo según lo presupuestado", "Costo ineficiente: se está gastando más de lo presupuestado"))), "No calculado") -> Costo eficiente: se está gastando menos de lo presupuestado | AC7: =IFERROR(W7/X7,0) -> 0.46 | AD7: =IF(OR(AC7="",AC7=0),"Sin Línea Base", IF(AC7>1,"Proyecto adelantado respecto al cronograma", IF(AC7=1,"Proyecto a tiempo según lo planificado", IF(AC7<1,"Proyecto atrasado con respecto al cronograma", "No calculado")))) -> Proyecto atrasado con respecto al cronograma | AE7: =IFERROR(L7/AA7,0) -> 0 | AF7: =IFERROR(AE7-L7,0) -> -3323223361 | AG7: =VLOOKUP(Indicador!E30,[1]Diccionario!C$1:AC$150,27,0) -> https://growdatasas.sharepoint.com/:x:/r/sites/Gestiondocumental/Administrativa/GD/Financiera/_layouts/15/Doc.aspx?sourcedoc=%7B4F9BD6BF-F6F0-4033-84A5-4B5D6077FC32%7D&file=314.%20TELEFONICA%20%E2%80%93%20DPC%20%20SALA%20DE%20ANALITICA.xlsx&action=default&mobileredirect=true | AH7: 1 | AI7: 1 | AJ7: ok
A8: 2024 | B8: Julio | C8: 227b8bc1-c7ab-ee11-ba7f-00155d104f2c | D8: 45296.529 | E8: CCD - DPC - IMPLEMENTACIÓN ERP | F8: Johan Sebastian Rodriguez Niño | G8: https://growdatasas.sharepoint.com/sites/pwa/CCD - DPC - IMPLEMENTACIÓN ERP | H8: Suministro e implementación del sistema de información ADMINISTRATIVO ERP NOVASOFT – versión ENTERPRISE WEB y el GESTOR DE RIESGOS para la entidad Defensoría del Pueblo.Incluye: 14 módulos específicos + 5 módulos financieros con licencia para 5000 usuarios finales, Licenciamiento de la Base de Datos SQL Server (Estándar para 8 Cores), Consultoría estándar de implementación de cada uno de los sistemas ofrecidos, soporte y actualización por 2 años y una bolsa de horas (según acuerdo por 2 años) | I8: DATOS Y SISTEMAS DE INFORMACIÓN | J8: 0318 | K8: Activo.En Ejecución | L8: =VLOOKUP(E8,[1]Diccionario!C$2:AC$150,22,0) -> 3323223361 | M8: =VLOOKUP(E8,[1]Diccionario!C$2:AC$150,24,0) -> 45300 | N8: =VLOOKUP(E8,[1]Diccionario!C$2:AC$150,25,0) -> 45473 | O8: =VLOOKUP(E8,[1]Diccionario!C$2:AC$150,26,0) -> 5.7 | P8: =Q8-O8 -> 20.3 | Q8: =DATEDIF(M8,TODAY(),"m") -> 26 | R8: 6 | S8: 1 | T8: =T7+0.02 -> 0.48 | U8: =U7+TablaIndicador[[#This Row],[Costo Mensual]] -> 0 | W8: =IFERROR(T8*L8,0) -> 1.5951472e+09 | X8: =S8*L8 -> 3323223361 | Y8: =IFERROR(W8-U8,0) -> 1.5951472e+09 | Z8: =W8-X8 -> -1.7280761e+09 | AA8: =IFERROR(W8/U8,"No se realizó gasto en este corte") -> No se realizó gasto en este corte | AB8: =IFERROR( IF(OR(AA8="",AA8=0), "No calculado", IF(AA8>1,"Costo eficiente: se está gastando menos de lo presupuestado", IF(AA8=1,"Costo según lo presupuestado", "Costo ineficiente: se está gastando más de lo presupuestado"))), "No calculado") -> Costo eficiente: se está gastando menos de lo presupuestado | AC8: =IFERROR(W8/X8,0) -> 0.48 | AD8: =IF(OR(AC8="",AC8=0),"Sin Línea Base", IF(AC8>1,"Proyecto adelantado respecto al cronograma", IF(AC8=1,"Proyecto a tiempo según lo planificado", IF(AC8<1,"Proyecto atrasado con respecto al cronograma", "No calculado")))) -> Proyecto atrasado con respecto al cronograma | AE8: =IFERROR(L8/AA8,0) -> 0 | AF8: =IFERROR(AE8-L8,0) -> -3323223361 | AG8: =VLOOKUP(Indicador!E31,[1]Diccionario!C$1:AC$150,27,0) -> https://growdatasas.sharepoint.com/:x:/r/sites/Gestiondocumental/Administrativa/GD/Financiera/_layouts/15/Doc.aspx?sourcedoc=%7B4F9BD6BF-F6F0-4033-84A5-4B5D6077FC32%7D&file=314.%20TELEFONICA%20%E2%80%93%20DPC%20%20SALA%20DE%20ANALITICA.xlsx&action=default&mobileredirect=true | AH8: 1 | AI8: 1 | AJ8: ok
A9: 2024 | B9: Agosto | C9: 227b8bc1-c7ab-ee11-ba7f-00155d104f2c | D9: 45296.529 | E9: CCD - DPC - IMPLEMENTACIÓN ERP | F9: Johan Sebastian Rodriguez Niño | G9: https://growdatasas.sharepoint.com/sites/pwa/CCD - DPC - IMPLEMENTACIÓN ERP | H9: Suministro e implementación del sistema de información ADMINISTRATIVO ERP NOVASOFT – versión ENTERPRISE WEB y el GESTOR DE RIESGOS para la entidad Defensoría del Pueblo.Incluye: 14 módulos específicos + 5 módulos financieros con licencia para 5000 usuarios finales, Licenciamiento de la Base de Datos SQL Server (Estándar para 8 Cores), Consultoría estándar de implementación de cada uno de los sistemas ofrecidos, soporte y actualización por 2 años y una bolsa de horas (según acuerdo por 2 años) | I9: DATOS Y SISTEMAS DE INFORMACIÓN | J9: 0318 | K9: Activo.En Ejecución | L9: =VLOOKUP(E9,[1]Diccionario!C$2:AC$150,22,0) -> 3323223361 | M9: =VLOOKUP(E9,[1]Diccionario!C$2:AC$150,24,0) -> 45300 | N9: =VLOOKUP(E9,[1]Diccionario!C$2:AC$150,25,0) -> 45473 | O9: =VLOOKUP(E9,[1]Diccionario!C$2:AC$150,26,0) -> 5.7 | P9: =Q9-O9 -> 20.3 | Q9: =DATEDIF(M9,TODAY(),"m") -> 26 | R9: 6 | S9: 1 | T9: =T8+0.02 -> 0.5 | U9: =U8+TablaIndicador[[#This Row],[Costo Mensual]] -> 0 | W9: =IFERROR(T9*L9,0) -> 1.6616117e+09 | X9: =S9*L9 -> 3323223361 | Y9: =IFERROR(W9-U9,0) -> 1.6616117e+09 | Z9: =W9-X9 -> -1.6616117e+09 | AA9: =IFERROR(W9/U9,"No se realizó gasto en este corte") -> No se realizó gasto en este corte | AB9: =IFERROR( IF(OR(AA9="",AA9=0), "No calculado", IF(AA9>1,"Costo eficiente: se está gastando menos de lo presupuestado", IF(AA9=1,"Costo según lo presupuestado", "Costo ineficiente: se está gastando más de lo presupuestado"))), "No calculado") -> Costo eficiente: se está gastando menos de lo presupuestado | AC9: =IFERROR(W9/X9,0) -> 0.5 | AD9: =IF(OR(AC9="",AC9=0),"Sin Línea Base", IF(AC9>1,"Proyecto adelantado respecto al cronograma", IF(AC9=1,"Proyecto a tiempo según lo planificado", IF(AC9<1,"Proyecto atrasado con respecto al cronograma", "No calculado")))) -> Proyecto atrasado con respecto al cronograma | AE9: =IFERROR(L9/AA9,0) -> 0 | AF9: =IFERROR(AE9-L9,0) -> -3323223361 | AG9: =VLOOKUP(Indicador!E32,[1]Diccionario!C$1:AC$150,27,0) -> https://growdatasas.sharepoint.com/:x:/r/sites/Gestiondocumental/Administrativa/GD/Financiera/_layouts/15/Doc.aspx?sourcedoc=%7B4F9BD6BF-F6F0-4033-84A5-4B5D6077FC32%7D&file=314.%20TELEFONICA%20%E2%80%93%20DPC%20%20SALA%20DE%20ANALITICA.xlsx&action=default&mobileredirect=true | AH9: 1 | AI9: 1 | AJ9: ok
A10: 2024 | B10: Septiembre | C10: 227b8bc1-c7ab-ee11-ba7f-00155d104f2c | D10: 45296.529 | E10: CCD - DPC - IMPLEMENTACIÓN ERP | F10: Johan Sebastian Rodriguez Niño | G10: https://growdatasas.sharepoint.com/sites/pwa/CCD - DPC - IMPLEMENTACIÓN ERP | H10: Suministro e implementación del sistema de información ADMINISTRATIVO ERP NOVASOFT – versión ENTERPRISE WEB y el GESTOR DE RIESGOS para la entidad Defensoría del Pueblo.Incluye: 14 módulos específicos + 5 módulos financieros con licencia para 5000 usuarios finales, Licenciamiento de la Base de Datos SQL Server (Estándar para 8 Cores), Consultoría estándar de implementación de cada uno de los sistemas ofrecidos, soporte y actualización por 2 años y una bolsa de horas (según acuerdo por 2 años) | I10: DATOS Y SISTEMAS DE INFORMACIÓN | J10: 0318 | K10: Activo.En Ejecución | L10: =VLOOKUP(E10,[1]Diccionario!C$2:AC$150,22,0) -> 3323223361 | M10: =VLOOKUP(E10,[1]Diccionario!C$2:AC$150,24,0) -> 45300 | N10: =VLOOKUP(E10,[1]Diccionario!C$2:AC$150,25,0) -> 45473 | O10: =VLOOKUP(E10,[1]Diccionario!C$2:AC$150,26,0) -> 5.7 | P10: =Q10-O10 -> 20.3 | Q10: =DATEDIF(M10,TODAY(),"m") -> 26 | R10: 6 | S10: 1 | T10: =T9+0.02 -> 0.52 | U10: =U9+TablaIndicador[[#This Row],[Costo Mensual]] -> 0 | W10: =IFERROR(T10*L10,0) -> 1.7280761e+09 | X10: =S10*L10 -> 3323223361 | Y10: =IFERROR(W10-U10,0) -> 1.7280761e+09 | Z10: =W10-X10 -> -1.5951472e+09 | AA10: =IFERROR(W10/U10,"No se realizó gasto en este corte") -> No se realizó gasto en este corte | AB10: =IFERROR( IF(OR(AA10="",AA10=0), "No calculado", IF(AA10>1,"Costo eficiente: se está gastando menos de lo presupuestado", IF(AA10=1,"Costo según lo presupuestado", "Costo ineficiente: se está gastando más de lo presupuestado"))), "No calculado") -> Costo eficiente: se está gastando menos de lo presupuestado | AC10: =IFERROR(W10/X10,0) -> 0.52 | AD10: =IF(OR(AC10="",AC10=0),"Sin Línea Base", IF(AC10>1,"Proyecto adelantado respecto al cronograma", IF(AC10=1,"Proyecto a tiempo según lo planificado", IF(AC10<1,"Proyecto atrasado con respecto al cronograma", "No calculado")))) -> Proyecto atrasado con respecto al cronograma | AE10: =IFERROR(L10/AA10,0) -> 0 | AF10: =IFERROR(AE10-L10,0) -> -3323223361 | AG10: =VLOOKUP(Indicador!E33,[1]Diccionario!C$1:AC$150,27,0) -> https://growdatasas.sharepoint.com/:x:/r/sites/Gestiondocumental/Administrativa/GD/Financiera/_layouts/15/Doc.aspx?sourcedoc=%7B4F9BD6BF-F6F0-4033-84A5-4B5D6077FC32%7D&file=314.%20TELEFONICA%20%E2%80%93%20DPC%20%20SALA%20DE%20ANALITICA.xlsx&action=default&mobileredirect=true | AH10: 1 | AI10: 1 | AJ10: ok
A11: 2024 | B11: Octubre | C11: 227b8bc1-c7ab-ee11-ba7f-00155d104f2c | D11: 45296.529 | E11: CCD - DPC - IMPLEMENTACIÓN ERP | F11: Johan Sebastian Rodriguez Niño | G11: https://growdatasas.sharepoint.com/sites/pwa/CCD - DPC - IMPLEMENTACIÓN ERP | H11: Suministro e implementación del sistema de información ADMINISTRATIVO ERP NOVASOFT – versión ENTERPRISE WEB y el GESTOR DE RIESGOS para la entidad Defensoría del Pueblo.Incluye: 14 módulos específicos + 5 módulos financieros con licencia para 5000 usuarios finales, Licenciamiento de la Base de Datos SQL Server (Estándar para 8 Cores), Consultoría estándar de implementación de cada uno de los sistemas ofrecidos, soporte y actualización por 2 años y una bolsa de horas (según acuerdo por 2 años) | I11: DATOS Y SISTEMAS DE INFORMACIÓN | J11: 0318 | K11: Activo.En Ejecución | L11: =VLOOKUP(E11,[1]Diccionario!C$2:AC$150,22,0) -> 3323223361 | M11: =VLOOKUP(E11,[1]Diccionario!C$2:AC$150,24,0) -> 45300 | N11: =VLOOKUP(E11,[1]Diccionario!C$2:AC$150,25,0) -> 45473 | O11: =VLOOKUP(E11,[1]Diccionario!C$2:AC$150,26,0) -> 5.7 | P11: =Q11-O11 -> 20.3 | Q11: =DATEDIF(M11,TODAY(),"m") -> 26 | R11: 6 | S11: 1 | T11: =T10+0.02 -> 0.54 | U11: =U10+TablaIndicador[[#This Row],[Costo Mensual]] -> 0 | W11: =IFERROR(T11*L11,0) -> 1.7945406e+09 | X11: =S11*L11 -> 3323223361 | Y11: =IFERROR(W11-U11,0) -> 1.7945406e+09 | Z11: =W11-X11 -> -1.5286827e+09 | AA11: =IFERROR(W11/U11,"No se realizó gasto en este corte") -> No se realizó gasto en este corte | AB11: =IFERROR( IF(OR(AA11="",AA11=0), "No calculado", IF(AA11>1,"Costo eficiente: se está gastando menos de lo presupuestado", IF(AA11=1,"Costo según lo presupuestado", "Costo ineficiente: se está gastando más de lo presupuestado"))), "No calculado") -> Costo eficiente: se está gastando menos de lo presupuestado | AC11: =IFERROR(W11/X11,0) -> 0.54 | AD11: =IF(OR(AC11="",AC11=0),"Sin Línea Base", IF(AC11>1,"Proyecto adelantado respecto al cronograma", IF(AC11=1,"Proyecto a tiempo según lo planificado", IF(AC11<1,"Proyecto atrasado con respecto al cronograma", "No calculado")))) -> Proyecto atrasado con respecto al cronograma | AE11: =IFERROR(L11/AA11,0) -> 0 | AF11: =IFERROR(AE11-L11,0) -> -3323223361 | AG11: =VLOOKUP(Indicador!E34,[1]Diccionario!C$1:AC$150,27,0) -> https://growdatasas.sharepoint.com/:x:/r/sites/Gestiondocumental/Administrativa/GD/Financiera/_layouts/15/Doc.aspx?sourcedoc=%7BB4DE39AF-1EC1-466C-A807-3FE95776A982%7D&file=17012024%20INFOTIC%20DPC%20SOC%20V2.xlsm&action=default&mobileredirect=true | AH11: 1 | AI11: 1 | AJ11: ok
A12: 2024 | B12: Noviembre | C12: 227b8bc1-c7ab-ee11-ba7f-00155d104f2c | D12: 45296.529 | E12: CCD - DPC - IMPLEMENTACIÓN ERP | F12: Johan Sebastian Rodriguez Niño | G12: https://growdatasas.sharepoint.com/sites/pwa/CCD - DPC - IMPLEMENTACIÓN ERP | H12: Suministro e implementación del sistema de información ADMINISTRATIVO ERP NOVASOFT – versión ENTERPRISE WEB y el GESTOR DE RIESGOS para la entidad Defensoría del Pueblo.Incluye: 14 módulos específicos + 5 módulos financieros con licencia para 5000 usuarios finales, Licenciamiento de la Base de Datos SQL Server (Estándar para 8 Cores), Consultoría estándar de implementación de cada uno de los sistemas ofrecidos, soporte y actualización por 2 años y una bolsa de horas (según acuerdo por 2 años) | I12: DATOS Y SISTEMAS DE INFORMACIÓN | J12: 0318 | K12: Activo.En Ejecución | L12: =VLOOKUP(E12,[1]Diccionario!C$2:AC$150,22,0) -> 3323223361 | M12: =VLOOKUP(E12,[1]Diccionario!C$2:AC$150,24,0) -> 45300 | N12: =VLOOKUP(E12,[1]Diccionario!C$2:AC$150,25,0) -> 45473 | O12: =VLOOKUP(E12,[1]Diccionario!C$2:AC$150,26,0) -> 5.7 | P12: =Q12-O12 -> 20.3 | Q12: =DATEDIF(M12,TODAY(),"m") -> 26 | R12: 6 | S12: 1 | T12: =T11+0.02 -> 0.56 | U12: =U11+TablaIndicador[[#This Row],[Costo Mensual]] -> 0 | W12: =IFERROR(T12*L12,0) -> 1.8610051e+09 | X12: =S12*L12 -> 3323223361 | Y12: =IFERROR(W12-U12,0) -> 1.8610051e+09 | Z12: =W12-X12 -> -1.4622183e+09 | AA12: =IFERROR(W12/U12,"No se realizó gasto en este corte") -> No se realizó gasto en este corte | AB12: =IFERROR( IF(OR(AA12="",AA12=0), "No calculado", IF(AA12>1,"Costo eficiente: se está gastando menos de lo presupuestado", IF(AA12=1,"Costo según lo presupuestado", "Costo ineficiente: se está gastando más de lo presupuestado"))), "No calculado") -> Costo eficiente: se está gastando menos de lo presupuestado | AC12: =IFERROR(W12/X12,0) -> 0.56 | AD12: =IF(OR(AC12="",AC12=0),"Sin Línea Base", IF(AC12>1,"Proyecto adelantado respecto al cronograma", IF(AC12=1,"Proyecto a tiempo según lo planificado", IF(AC12<1,"Proyecto atrasado con respecto al cronograma", "No calculado")))) -> Proyecto atrasado con respecto al cronograma | AE12: =IFERROR(L12/AA12,0) -> 0 | AF12: =IFERROR(AE12-L12,0) -> -3323223361 | AG12: =VLOOKUP(Indicador!E35,[1]Diccionario!C$1:AC$150,27,0) -> https://growdatasas.sharepoint.com/:x:/r/sites/Gestiondocumental/Administrativa/GD/Financiera/_layouts/15/Doc.aspx?sourcedoc=%7BB4DE39AF-1EC1-466C-A807-3FE95776A982%7D&file=17012024%20INFOTIC%20DPC%20SOC%20V2.xlsm&action=default&mobileredirect=true | AH12: 1 | AI12: 1 | AJ12: ok
A13: 2024 | B13: Diciembre | C13: 227b8bc1-c7ab-ee11-ba7f-00155d104f2c | D13: 45296.529 | E13: CCD - DPC - IMPLEMENTACIÓN ERP | F13: Johan Sebastian Rodriguez Niño | G13: https://growdatasas.sharepoint.com/sites/pwa/CCD - DPC - IMPLEMENTACIÓN ERP | H13: Suministro e implementación del sistema de información ADMINISTRATIVO ERP NOVASOFT – versión ENTERPRISE WEB y el GESTOR DE RIESGOS para la entidad Defensoría del Pueblo.Incluye: 14 módulos específicos + 5 módulos financieros con licencia para 5000 usuarios finales, Licenciamiento de la Base de Datos SQL Server (Estándar para 8 Cores), Consultoría estándar de implementación de cada uno de los sistemas ofrecidos, soporte y actualización por 2 años y una bolsa de horas (según acuerdo por 2 años) | I13: DATOS Y SISTEMAS DE INFORMACIÓN | J13: 0318 | K13: Activo.En Ejecución | L13: =VLOOKUP(E13,[1]Diccionario!C$2:AC$150,22,0) -> 3323223361 | M13: =VLOOKUP(E13,[1]Diccionario!C$2:AC$150,24,0) -> 45300 | N13: =VLOOKUP(E13,[1]Diccionario!C$2:AC$150,25,0) -> 45473 | O13: =VLOOKUP(E13,[1]Diccionario!C$2:AC$150,26,0) -> 5.7 | P13: =Q13-O13 -> 20.3 | Q13: =DATEDIF(M13,TODAY(),"m") -> 26 | R13: 6 | S13: 1 | T13: =T12+0.02 -> 0.58 | U13: =U12+TablaIndicador[[#This Row],[Costo Mensual]] -> 0 | W13: =IFERROR(T13*L13,0) -> 1.9274695e+09 | X13: =S13*L13 -> 3323223361 | Y13: =IFERROR(W13-U13,0) -> 1.9274695e+09 | Z13: =W13-X13 -> -1.3957538e+09 | AA13: =IFERROR(W13/U13,"No se realizó gasto en este corte") -> No se realizó gasto en este corte | AB13: =IFERROR( IF(OR(AA13="",AA13=0), "No calculado", IF(AA13>1,"Costo eficiente: se está gastando menos de lo presupuestado", IF(AA13=1,"Costo según lo presupuestado", "Costo ineficiente: se está gastando más de lo presupuestado"))), "No calculado") -> Costo eficiente: se está gastando menos de lo presupuestado | AC13: =IFERROR(W13/X13,0) -> 0.58 | AD13: =IF(OR(AC13="",AC13=0),"Sin Línea Base", IF(AC13>1,"Proyecto adelantado respecto al cronograma", IF(AC13=1,"Proyecto a tiempo según lo planificado", IF(AC13<1,"Proyecto atrasado con respecto al cronograma", "No calculado")))) -> Proyecto atrasado con respecto al cronograma | AE13: =IFERROR(L13/AA13,0) -> 0 | AF13: =IFERROR(AE13-L13,0) -> -3323223361 | AG13: =VLOOKUP(Indicador!E36,[1]Diccionario!C$1:AC$150,27,0) -> https://growdatasas.sharepoint.com/:x:/r/sites/Gestiondocumental/Administrativa/GD/Financiera/_layouts/15/Doc.aspx?sourcedoc=%7BB4DE39AF-1EC1-466C-A807-3FE95776A982%7D&file=17012024%20INFOTIC%20DPC%20SOC%20V2.xlsm&action=default&mobileredirect=true | AH13: 1 | AI13: 1 | AJ13: ok
A14: 2025 | B14: Enero | C14: 227b8bc1-c7ab-ee11-ba7f-00155d104f2c | D14: 45296.529 | E14: CCD - DPC - IMPLEMENTACIÓN ERP | F14: Johan Sebastian Rodriguez Niño | G14: https://growdatasas.sharepoint.com/sites/pwa/CCD - DPC - IMPLEMENTACIÓN ERP | H14: Suministro e implementación del sistema de información ADMINISTRATIVO ERP NOVASOFT – versión ENTERPRISE WEB y el GESTOR DE RIESGOS para la entidad Defensoría del Pueblo.Incluye: 14 módulos específicos + 5 módulos financieros con licencia para 5000 usuarios finales, Licenciamiento de la Base de Datos SQL Server (Estándar para 8 Cores), Consultoría estándar de implementación de cada uno de los sistemas ofrecidos, soporte y actualización por 2 años y una bolsa de horas (según acuerdo por 2 años) | I14: DATOS Y SISTEMAS DE INFORMACIÓN | J14: 0318 | K14: Activo.En Ejecución | L14: =VLOOKUP(E14,[1]Diccionario!C$2:AC$150,22,0) -> 3323223361 | M14: =VLOOKUP(E14,[1]Diccionario!C$2:AC$150,24,0) -> 45300 | N14: =VLOOKUP(E14,[1]Diccionario!C$2:AC$150,25,0) -> 45473 | O14: =VLOOKUP(E14,[1]Diccionario!C$2:AC$150,26,0) -> 5.7 | P14: =Q14-O14 -> 20.3 | Q14: =DATEDIF(M14,TODAY(),"m") -> 26 | R14: 6 | S14: 1 | T14: =T13+0.02 -> 0.6 | U14: =U13+TablaIndicador[[#This Row],[Costo Mensual]] -> 0 | W14: =IFERROR(T14*L14,0) -> 1.993934e+09 | X14: =S14*L14 -> 3323223361 | Y14: =IFERROR(W14-U14,0) -> 1.993934e+09 | Z14: =W14-X14 -> -1.3292893e+09 | AA14: =IFERROR(W14/U14,"No se realizó gasto en este corte") -> No se realizó gasto en este corte | AB14: =IFERROR( IF(OR(AA14="",AA14=0), "No calculado", IF(AA14>1,"Costo eficiente: se está gastando menos de lo presupuestado", IF(AA14=1,"Costo según lo presupuestado", "Costo ineficiente: se está gastando más de lo presupuestado"))), "No calculado") -> Costo eficiente: se está gastando menos de lo presupuestado | AC14: =IFERROR(W14/X14,0) -> 0.6 | AD14: =IF(OR(AC14="",AC14=0),"Sin Línea Base", IF(AC14>1,"Proyecto adelantado respecto al cronograma", IF(AC14=1,"Proyecto a tiempo según lo planificado", IF(AC14<1,"Proyecto atrasado con respecto al cronograma", "No calculado")))) -> Proyecto atrasado con respecto al cronograma | AE14: =IFERROR(L14/AA14,0) -> 0 | AF14: =IFERROR(AE14-L14,0) -> -3323223361 | AG14: =VLOOKUP(Indicador!E37,[1]Diccionario!C$1:AC$150,27,0) -> https://growdatasas.sharepoint.com/:x:/r/sites/Gestiondocumental/Administrativa/GD/Financiera/_layouts/15/Doc.aspx?sourcedoc=%7BB4DE39AF-1EC1-466C-A807-3FE95776A982%7D&file=17012024%20INFOTIC%20DPC%20SOC%20V2.xlsm&action=default&mobileredirect=true | AH14: 1 | AI14: 1
A15: 2025 | B15: Febrero | C15: 227b8bc1-c7ab-ee11-ba7f-00155d104f2c | D15: 45296.529 | E15: CCD - DPC - IMPLEMENTACIÓN ERP | F15: Johan Sebastian Rodriguez Niño | G15: https://growdatasas.sharepoint.com/sites/pwa/CCD - DPC - IMPLEMENTACIÓN ERP | H15: Suministro e implementación del sistema de información ADMINISTRATIVO ERP NOVASOFT – versión ENTERPRISE WEB y el GESTOR DE RIESGOS para la entidad Defensoría del Pueblo.Incluye: 14 módulos específicos + 5 módulos financieros con licencia para 5000 usuarios finales, Licenciamiento de la Base de Datos SQL Server (Estándar para 8 Cores), Consultoría estándar de implementación de cada uno de los sistemas ofrecidos, soporte y actualización por 2 años y una bolsa de horas (según acuerdo por 2 años) | I15: DATOS Y SISTEMAS DE INFORMACIÓN | J15: 0318 | K15: Activo.En Ejecución | L15: =VLOOKUP(E15,[1]Diccionario!C$2:AC$150,22,0) -> 3323223361 | M15: =VLOOKUP(E15,[1]Diccionario!C$2:AC$150,24,0) -> 45300 | N15: =VLOOKUP(E15,[1]Diccionario!C$2:AC$150,25,0) -> 45473 | O15: =VLOOKUP(E15,[1]Diccionario!C$2:AC$150,26,0) -> 5.7 | P15: =Q15-O15 -> 20.3 | Q15: =DATEDIF(M15,TODAY(),"m") -> 26 | R15: 6 | S15: 1 | T15: =T14+0.02 -> 0.62 | U15: =U14+TablaIndicador[[#This Row],[Costo Mensual]] -> 0 | W15: =IFERROR(T15*L15,0) -> 2.0603985e+09 | X15: =S15*L15 -> 3323223361 | Y15: =IFERROR(W15-U15,0) -> 2.0603985e+09 | Z15: =W15-X15 -> -1.2628249e+09 | AA15: =IFERROR(W15/U15,"No se realizó gasto en este corte") -> No se realizó gasto en este corte | AB15: =IFERROR( IF(OR(AA15="",AA15=0), "No calculado", IF(AA15>1,"Costo eficiente: se está gastando menos de lo presupuestado", IF(AA15=1,"Costo según lo presupuestado", "Costo ineficiente: se está gastando más de lo presupuestado"))), "No calculado") -> Costo eficiente: se está gastando menos de lo presupuestado | AC15: =IFERROR(W15/X15,0) -> 0.62 | AD15: =IF(OR(AC15="",AC15=0),"Sin Línea Base", IF(AC15>1,"Proyecto adelantado respecto al cronograma", IF(AC15=1,"Proyecto a tiempo según lo planificado", IF(AC15<1,"Proyecto atrasado con respecto al cronograma", "No calculado")))) -> Proyecto atrasado con respecto al cronograma | AE15: =IFERROR(L15/AA15,0) -> 0 | AF15: =IFERROR(AE15-L15,0) -> -3323223361 | AG15: =VLOOKUP(Indicador!E38,[1]Diccionario!C$1:AC$150,27,0) -> https://growdatasas.sharepoint.com/:x:/r/sites/Gestiondocumental/Administrativa/GD/Financiera/_layouts/15/Doc.aspx?sourcedoc=%7BB4DE39AF-1EC1-466C-A807-3FE95776A982%7D&file=17012024%20INFOTIC%20DPC%20SOC%20V2.xlsm&action=default&mobileredirect=true | AH15: 1 | AI15: 1
A16: 2025 | B16: Marzo | C16: 227b8bc1-c7ab-ee11-ba7f-00155d104f2c | D16: 45296.529 | E16: CCD - DPC - IMPLEMENTACIÓN ERP | F16: Johan Sebastian Rodriguez Niño | G16: https://growdatasas.sharepoint.com/sites/pwa/CCD - DPC - IMPLEMENTACIÓN ERP | H16: Suministro e implementación del sistema de información ADMINISTRATIVO ERP NOVASOFT – versión ENTERPRISE WEB y el GESTOR DE RIESGOS para la entidad Defensoría del Pueblo.Incluye: 14 módulos específicos + 5 módulos financieros con licencia para 5000 usuarios finales, Licenciamiento de la Base de Datos SQL Server (Estándar para 8 Cores), Consultoría estándar de implementación de cada uno de los sistemas ofrecidos, soporte y actualización por 2 años y una bolsa de horas (según acuerdo por 2 años) | I16: DATOS Y SISTEMAS DE INFORMACIÓN | J16: 0318 | K16: Activo.En Ejecución | L16: =VLOOKUP(E16,[1]Diccionario!C$2:AC$150,22,0) -> 3323223361 | M16: =VLOOKUP(E16,[1]Diccionario!C$2:AC$150,24,0) -> 45300 | N16: =VLOOKUP(E16,[1]Diccionario!C$2:AC$150,25,0) -> 45473 | O16: =VLOOKUP(E16,[1]Diccionario!C$2:AC$150,26,0) -> 5.7 | P16: =Q16-O16 -> 20.3 | Q16: =DATEDIF(M16,TODAY(),"m") -> 26 | R16: 6 | S16: 1 | T16: =T15+0.02 -> 0.64 | U16: =U15+TablaIndicador[[#This Row],[Costo Mensual]] -> 0 | W16: =IFERROR(T16*L16,0) -> 2.126863e+09 | X16: =S16*L16 -> 3323223361 | Y16: =IFERROR(W16-U16,0) -> 2.126863e+09 | Z16: =W16-X16 -> -1.1963604e+09 | AA16: =IFERROR(W16/U16,"No se realizó gasto en este corte") -> No se realizó gasto en este corte | AB16: =IFERROR( IF(OR(AA16="",AA16=0), "No calculado", IF(AA16>1,"Costo eficiente: se está gastando menos de lo presupuestado", IF(AA16=1,"Costo según lo presupuestado", "Costo ineficiente: se está gastando más de lo presupuestado"))), "No calculado") -> Costo eficiente: se está gastando menos de lo presupuestado | AC16: =IFERROR(W16/X16,0) -> 0.64 | AD16: =IF(OR(AC16="",AC16=0),"Sin Línea Base", IF(AC16>1,"Proyecto adelantado respecto al cronograma", IF(AC16=1,"Proyecto a tiempo según lo planificado", IF(AC16<1,"Proyecto atrasado con respecto al cronograma", "No calculado")))) -> Proyecto atrasado con respecto al cronograma | AE16: =IFERROR(L16/AA16,0) -> 0 | AF16: =IFERROR(AE16-L16,0) -> -3323223361 | AG16: =VLOOKUP(Indicador!E39,[1]Diccionario!C$1:AC$150,27,0) -> https://growdatasas.sharepoint.com/:x:/r/sites/Gestiondocumental/Administrativa/GD/Financiera/_layouts/15/Doc.aspx?sourcedoc=%7BB4DE39AF-1EC1-466C-A807-3FE95776A982%7D&file=17012024%20INFOTIC%20DPC%20SOC%20V2.xlsm&action=default&mobileredirect=true | AH16: 1 | AI16: 1
A17: 2025 | B17: Abril | C17: 227b8bc1-c7ab-ee11-ba7f-00155d104f2c | D17: 45296.529 | E17: CCD - DPC - IMPLEMENTACIÓN ERP | F17: Johan Sebastian Rodriguez Niño | G17: https://growdatasas.sharepoint.com/sites/pwa/CCD - DPC - IMPLEMENTACIÓN ERP | H17: Suministro e implementación del sistema de información ADMINISTRATIVO ERP NOVASOFT – versión ENTERPRISE WEB y el GESTOR DE RIESGOS para la entidad Defensoría del Pueblo.Incluye: 14 módulos específicos + 5 módulos financieros con licencia para 5000 usuarios finales, Licenciamiento de la Base de Datos SQL Server (Estándar para 8 Cores), Consultoría estándar de implementación de cada uno de los sistemas ofrecidos, soporte y actualización por 2 años y una bolsa de horas (según acuerdo por 2 años) | I17: DATOS Y SISTEMAS DE INFORMACIÓN | J17: 0318 | K17: Activo.En Ejecución | L17: =VLOOKUP(E17,[1]Diccionario!C$2:AC$150,22,0) -> 3323223361 | M17: =VLOOKUP(E17,[1]Diccionario!C$2:AC$150,24,0) -> 45300 | N17: =VLOOKUP(E17,[1]Diccionario!C$2:AC$150,25,0) -> 45473 | O17: =VLOOKUP(E17,[1]Diccionario!C$2:AC$150,26,0) -> 5.7 | P17: =Q17-O17 -> 20.3 | Q17: =DATEDIF(M17,TODAY(),"m") -> 26 | R17: 6 | S17: 1 | T17: =T16+0.02 -> 0.66 | U17: =U16+TablaIndicador[[#This Row],[Costo Mensual]] -> 0 | W17: =IFERROR(T17*L17,0) -> 2.1933274e+09 | X17: =S17*L17 -> 3323223361 | Y17: =IFERROR(W17-U17,0) -> 2.1933274e+09 | Z17: =W17-X17 -> -1.1298959e+09 | AA17: =IFERROR(W17/U17,"No se realizó gasto en este corte") -> No se realizó gasto en este corte | AB17: =IFERROR( IF(OR(AA17="",AA17=0), "No calculado", IF(AA17>1,"Costo eficiente: se está gastando menos de lo presupuestado", IF(AA17=1,"Costo según lo presupuestado", "Costo ineficiente: se está gastando más de lo presupuestado"))), "No calculado") -> Costo eficiente: se está gastando menos de lo presupuestado | AC17: =IFERROR(W17/X17,0) -> 0.66 | AD17: =IF(OR(AC17="",AC17=0),"Sin Línea Base", IF(AC17>1,"Proyecto adelantado respecto al cronograma", IF(AC17=1,"Proyecto a tiempo según lo planificado", IF(AC17<1,"Proyecto atrasado con respecto al cronograma", "No calculado")))) -> Proyecto atrasado con respecto al cronograma | AE17: =IFERROR(L17/AA17,0) -> 0 | AF17: =IFERROR(AE17-L17,0) -> -3323223361 | AG17: =VLOOKUP(Indicador!E40,[1]Diccionario!C$1:AC$150,27,0) -> https://growdatasas.sharepoint.com/:x:/r/sites/Gestiondocumental/Administrativa/GD/Financiera/_layouts/15/Doc.aspx?sourcedoc=%7BB4DE39AF-1EC1-466C-A807-3FE95776A982%7D&file=17012024%20INFOTIC%20DPC%20SOC%20V2.xlsm&action=default&mobileredirect=true | AH17: 1 | AI17: 1
A18: 2025 | B18: Mayo | C18: 227b8bc1-c7ab-ee11-ba7f-00155d104f2c | D18: 45296.529 | E18: CCD - DPC - IMPLEMENTACIÓN ERP | F18: Johan Sebastian Rodriguez Niño | G18: https://growdatasas.sharepoint.com/sites/pwa/CCD - DPC - IMPLEMENTACIÓN ERP | H18: Suministro e implementación del sistema de información ADMINISTRATIVO ERP NOVASOFT – versión ENTERPRISE WEB y el GESTOR DE RIESGOS para la entidad Defensoría del Pueblo.Incluye: 14 módulos específicos + 5 módulos financieros con licencia para 5000 usuarios finales, Licenciamiento de la Base de Datos SQL Server (Estándar para 8 Cores), Consultoría estándar de implementación de cada uno de los sistemas ofrecidos, soporte y actualización por 2 años y una bolsa de horas (según acuerdo por 2 años) | I18: DATOS Y SISTEMAS DE INFORMACIÓN | J18: 0318 | K18: Activo.En Ejecución | L18: =VLOOKUP(E18,[1]Diccionario!C$2:AC$150,22,0) -> 3323223361 | M18: =VLOOKUP(E18,[1]Diccionario!C$2:AC$150,24,0) -> 45300 | N18: =VLOOKUP(E18,[1]Diccionario!C$2:AC$150,25,0) -> 45473 | O18: =VLOOKUP(E18,[1]Diccionario!C$2:AC$150,26,0) -> 5.7 | P18: =Q18-O18 -> 20.3 | Q18: =DATEDIF(M18,TODAY(),"m") -> 26 | R18: 6 | S18: 1 | T18: =T17+0.02 -> 0.68 | U18: =U17+TablaIndicador[[#This Row],[Costo Mensual]] -> 0 | W18: =IFERROR(T18*L18,0) -> 2.2597919e+09 | X18: =S18*L18 -> 3323223361 | Y18: =IFERROR(W18-U18,0) -> 2.2597919e+09 | Z18: =W18-X18 -> -1.0634315e+09 | AA18: =IFERROR(W18/U18,"No se realizó gasto en este corte") -> No se realizó gasto en este corte | AB18: =IFERROR( IF(OR(AA18="",AA18=0), "No calculado", IF(AA18>1,"Costo eficiente: se está gastando menos de lo presupuestado", IF(AA18=1,"Costo según lo presupuestado", "Costo ineficiente: se está gastando más de lo presupuestado"))), "No calculado") -> Costo eficiente: se está gastando menos de lo presupuestado | AC18: =IFERROR(W18/X18,0) -> 0.68 | AD18: =IF(OR(AC18="",AC18=0),"Sin Línea Base", IF(AC18>1,"Proyecto adelantado respecto al cronograma", IF(AC18=1,"Proyecto a tiempo según lo planificado", IF(AC18<1,"Proyecto atrasado con respecto al cronograma", "No calculado")))) -> Proyecto atrasado con respecto al cronograma | AE18: =IFERROR(L18/AA18,0) -> 0 | AF18: =IFERROR(AE18-L18,0) -> -3323223361 | AG18: =VLOOKUP(Indicador!E41,[1]Diccionario!C$1:AC$150,27,0) -> https://growdatasas.sharepoint.com/:x:/r/sites/Gestiondocumental/Administrativa/GD/Financiera/_layouts/15/Doc.aspx?sourcedoc=%7BB4DE39AF-1EC1-466C-A807-3FE95776A982%7D&file=17012024%20INFOTIC%20DPC%20SOC%20V2.xlsm&action=default&mobileredirect=true | AH18: 1 | AI18: 1
A19: 2025 | B19: Junio | C19: 227b8bc1-c7ab-ee11-ba7f-00155d104f2c | D19: 45296.529 | E19: CCD - DPC - IMPLEMENTACIÓN ERP | F19: Johan Sebastian Rodriguez Niño | G19: https://growdatasas.sharepoint.com/sites/pwa/CCD - DPC - IMPLEMENTACIÓN ERP | H19: Suministro e implementación del sistema de información ADMINISTRATIVO ERP NOVASOFT – versión ENTERPRISE WEB y el GESTOR DE RIESGOS para la entidad Defensoría del Pueblo.Incluye: 14 módulos específicos + 5 módulos financieros con licencia para 5000 usuarios finales, Licenciamiento de la Base de Datos SQL Server (Estándar para 8 Cores), Consultoría estándar de implementación de cada uno de los sistemas ofrecidos, soporte y actualización por 2 años y una bolsa de horas (según acuerdo por 2 años) | I19: DATOS Y SISTEMAS DE INFORMACIÓN | J19: 0318 | K19: Activo.En Ejecución | L19: =VLOOKUP(E19,[1]Diccionario!C$2:AC$150,22,0) -> 3323223361 | M19: =VLOOKUP(E19,[1]Diccionario!C$2:AC$150,24,0) -> 45300 | N19: =VLOOKUP(E19,[1]Diccionario!C$2:AC$150,25,0) -> 45473 | O19: =VLOOKUP(E19,[1]Diccionario!C$2:AC$150,26,0) -> 5.7 | P19: =Q19-O19 -> 20.3 | Q19: =DATEDIF(M19,TODAY(),"m") -> 26 | R19: 6 | S19: 1 | T19: =T18+0.02 -> 0.7 | U19: =U18+TablaIndicador[[#This Row],[Costo Mensual]] -> 0 | W19: =IFERROR(T19*L19,0) -> 2.3262564e+09 | X19: =S19*L19 -> 3323223361 | Y19: =IFERROR(W19-U19,0) -> 2.3262564e+09 | Z19: =W19-X19 -> -9.9696701e+08 | AA19: =IFERROR(W19/U19,"No se realizó gasto en este corte") -> No se realizó gasto en este corte | AB19: =IFERROR( IF(OR(AA19="",AA19=0), "No calculado", IF(AA19>1,"Costo eficiente: se está gastando menos de lo presupuestado", IF(AA19=1,"Costo según lo presupuestado", "Costo ineficiente: se está gastando más de lo presupuestado"))), "No calculado") -> Costo eficiente: se está gastando menos de lo presupuestado | AC19: =IFERROR(W19/X19,0) -> 0.7 | AD19: =IF(OR(AC19="",AC19=0),"Sin Línea Base", IF(AC19>1,"Proyecto adelantado respecto al cronograma", IF(AC19=1,"Proyecto a tiempo según lo planificado", IF(AC19<1,"Proyecto atrasado con respecto al cronograma", "No calculado")))) -> Proyecto atrasado con respecto al cronograma | AE19: =IFERROR(L19/AA19,0) -> 0 | AF19: =IFERROR(AE19-L19,0) -> -3323223361 | AG19: =VLOOKUP(Indicador!E42,[1]Diccionario!C$1:AC$150,27,0) -> https://growdatasas.sharepoint.com/:x:/r/sites/Gestiondocumental/Administrativa/GD/Financiera/_layouts/15/Doc.aspx?sourcedoc=%7B453B6AA8-B631-4722-B916-8323F8C43E87%7D&file=315%20CORP%20COLOMBIA%20DIGITAL%20FNA%20AE.xlsm&action=default&mobileredirect=true | AH19: 1 | AI19: 1
A20: 2025 | B20: Julio | C20: 227b8bc1-c7ab-ee11-ba7f-00155d104f2c | D20: 45296.529 | E20: CCD - DPC - IMPLEMENTACIÓN ERP | F20: Johan Sebastian Rodriguez Niño | G20: https://growdatasas.sharepoint.com/sites/pwa/CCD - DPC - IMPLEMENTACIÓN ERP | H20: Suministro e implementación del sistema de información ADMINISTRATIVO ERP NOVASOFT – versión ENTERPRISE WEB y el GESTOR DE RIESGOS para la entidad Defensoría del Pueblo.Incluye: 14 módulos específicos + 5 módulos financieros con licencia para 5000 usuarios finales, Licenciamiento de la Base de Datos SQL Server (Estándar para 8 Cores), Consultoría estándar de implementación de cada uno de los sistemas ofrecidos, soporte y actualización por 2 años y una bolsa de horas (según acuerdo por 2 años) | I20: DATOS Y SISTEMAS DE INFORMACIÓN | J20: 0318 | K20: Activo.En Ejecución | L20: =VLOOKUP(E20,[1]Diccionario!C$2:AC$150,22,0) -> 3323223361 | M20: =VLOOKUP(E20,[1]Diccionario!C$2:AC$150,24,0) -> 45300 | N20: =VLOOKUP(E20,[1]Diccionario!C$2:AC$150,25,0) -> 45473 | O20: =VLOOKUP(E20,[1]Diccionario!C$2:AC$150,26,0) -> 5.7 | P20: =Q20-O20 -> 20.3 | Q20: =DATEDIF(M20,TODAY(),"m") -> 26 | R20: 6 | S20: 1 | T20: =T19+0.02 -> 0.72 | U20: =U19+TablaIndicador[[#This Row],[Costo Mensual]] -> 0 | W20: =IFERROR(T20*L20,0) -> 2.3927208e+09 | X20: =S20*L20 -> 3323223361 | Y20: =IFERROR(W20-U20,0) -> 2.3927208e+09 | Z20: =W20-X20 -> -9.3050254e+08 | AA20: =IFERROR(W20/U20,"No se realizó gasto en este corte") -> No se realizó gasto en este corte | AB20: =IFERROR( IF(OR(AA20="",AA20=0), "No calculado", IF(AA20>1,"Costo eficiente: se está gastando menos de lo presupuestado", IF(AA20=1,"Costo según lo presupuestado", "Costo ineficiente: se está gastando más de lo presupuestado"))), "No calculado") -> Costo eficiente: se está gastando menos de lo presupuestado | AC20: =IFERROR(W20/X20,0) -> 0.72 | AD20: =IF(OR(AC20="",AC20=0),"Sin Línea Base", IF(AC20>1,"Proyecto adelantado respecto al cronograma", IF(AC20=1,"Proyecto a tiempo según lo planificado", IF(AC20<1,"Proyecto atrasado con respecto al cronograma", "No calculado")))) -> Proyecto atrasado con respecto al cronograma | AE20: =IFERROR(L20/AA20,0) -> 0 | AF20: =IFERROR(AE20-L20,0) -> -3323223361 | AG20: =VLOOKUP(Indicador!E43,[1]Diccionario!C$1:AC$150,27,0) -> https://growdatasas.sharepoint.com/:x:/r/sites/Gestiondocumental/Administrativa/GD/Financiera/_layouts/15/Doc.aspx?sourcedoc=%7B453B6AA8-B631-4722-B916-8323F8C43E87%7D&file=315%20CORP%20COLOMBIA%20DIGITAL%20FNA%20AE.xlsm&action=default&mobileredirect=true | AH20: 1 | AI20: 1
A21: 2025 | B21: Agosto | C21: 227b8bc1-c7ab-ee11-ba7f-00155d104f2c | D21: 45296.529 | E21: CCD - DPC - IMPLEMENTACIÓN ERP | F21: Johan Sebastian Rodriguez Niño | G21: https://growdatasas.sharepoint.com/sites/pwa/CCD - DPC - IMPLEMENTACIÓN ERP | H21: Suministro e implementación del sistema de información ADMINISTRATIVO ERP NOVASOFT – versión ENTERPRISE WEB y el GESTOR DE RIESGOS para la entidad Defensoría del Pueblo.Incluye: 14 módulos específicos + 5 módulos financieros con licencia para 5000 usuarios finales, Licenciamiento de la Base de Datos SQL Server (Estándar para 8 Cores), Consultoría estándar de implementación de cada uno de los sistemas ofrecidos, soporte y actualización por 2 años y una bolsa de horas (según acuerdo por 2 años) | I21: DATOS Y SISTEMAS DE INFORMACIÓN | J21: 0318 | K21: Activo.En Ejecución | L21: =VLOOKUP(E21,[1]Diccionario!C$2:AC$150,22,0) -> 3323223361 | M21: =VLOOKUP(E21,[1]Diccionario!C$2:AC$150,24,0) -> 45300 | N21: =VLOOKUP(E21,[1]Diccionario!C$2:AC$150,25,0) -> 45473 | O21: =VLOOKUP(E21,[1]Diccionario!C$2:AC$150,26,0) -> 5.7 | P21: =Q21-O21 -> 20.3 | Q21: =DATEDIF(M21,TODAY(),"m") -> 26 | R21: 6 | S21: 1 | T21: =T20+0.02 -> 0.74 | U21: =U20+TablaIndicador[[#This Row],[Costo Mensual]] -> 0 | W21: =IFERROR(T21*L21,0) -> 2.4591853e+09 | X21: =S21*L21 -> 3323223361 | Y21: =IFERROR(W21-U21,0) -> 2.4591853e+09 | Z21: =W21-X21 -> -8.6403807e+08 | AA21: =IFERROR(W21/U21,"No se realizó gasto en este corte") -> No se realizó gasto en este corte | AB21: =IFERROR( IF(OR(AA21="",AA21=0), "No calculado", IF(AA21>1,"Costo eficiente: se está gastando menos de lo presupuestado", IF(AA21=1,"Costo según lo presupuestado", "Costo ineficiente: se está gastando más de lo presupuestado"))), "No calculado") -> Costo eficiente: se está gastando menos de lo presupuestado | AC21: =IFERROR(W21/X21,0) -> 0.74 | AD21: =IF(OR(AC21="",AC21=0),"Sin Línea Base", IF(AC21>1,"Proyecto adelantado respecto al cronograma", IF(AC21=1,"Proyecto a tiempo según lo planificado", IF(AC21<1,"Proyecto atrasado con respecto al cronograma", "No calculado")))) -> Proyecto atrasado con respecto al cronograma | AE21: =IFERROR(L21/AA21,0) -> 0 | AF21: =IFERROR(AE21-L21,0) -> -3323223361 | AG21: =VLOOKUP(Indicador!E44,[1]Diccionario!C$1:AC$150,27,0) -> https://growdatasas.sharepoint.com/:x:/r/sites/Gestiondocumental/Administrativa/GD/Financiera/_layouts/15/Doc.aspx?sourcedoc=%7B453B6AA8-B631-4722-B916-8323F8C43E87%7D&file=315%20CORP%20COLOMBIA%20DIGITAL%20FNA%20AE.xlsm&action=default&mobileredirect=true | AH21: 1 | AI21: 1
A22: 2025 | B22: Septiembre | C22: 227b8bc1-c7ab-ee11-ba7f-00155d104f2c | D22: 45296.529 | E22: CCD - DPC - IMPLEMENTACIÓN ERP | F22: Johan Sebastian Rodriguez Niño | G22: https://growdatasas.sharepoint.com/sites/pwa/CCD - DPC - IMPLEMENTACIÓN ERP | H22: Suministro e implementación del sistema de información ADMINISTRATIVO ERP NOVASOFT – versión ENTERPRISE WEB y el GESTOR DE RIESGOS para la entidad Defensoría del Pueblo.Incluye: 14 módulos específicos + 5 módulos financieros con licencia para 5000 usuarios finales, Licenciamiento de la Base de Datos SQL Server (Estándar para 8 Cores), Consultoría estándar de implementación de cada uno de los sistemas ofrecidos, soporte y actualización por 2 años y una bolsa de horas (según acuerdo por 2 años) | I22: DATOS Y SISTEMAS DE INFORMACIÓN | J22: 0318 | K22: Activo.En Ejecución | L22: =VLOOKUP(E22,[1]Diccionario!C$2:AC$150,22,0) -> 3323223361 | M22: =VLOOKUP(E22,[1]Diccionario!C$2:AC$150,24,0) -> 45300 | N22: =VLOOKUP(E22,[1]Diccionario!C$2:AC$150,25,0) -> 45473 | O22: =VLOOKUP(E22,[1]Diccionario!C$2:AC$150,26,0) -> 5.7 | P22: =Q22-O22 -> 20.3 | Q22: =DATEDIF(M22,TODAY(),"m") -> 26 | R22: 6 | S22: 1 | T22: =T21+0.02 -> 0.76 | U22: =U21+TablaIndicador[[#This Row],[Costo Mensual]] -> 0 | W22: =IFERROR(T22*L22,0) -> 2.5256498e+09 | X22: =S22*L22 -> 3323223361 | Y22: =IFERROR(W22-U22,0) -> 2.5256498e+09 | Z22: =W22-X22 -> -7.9757361e+08 | AA22: =IFERROR(W22/U22,"No se realizó gasto en este corte") -> No se realizó gasto en este corte | AB22: =IFERROR( IF(OR(AA22="",AA22=0), "No calculado", IF(AA22>1,"Costo eficiente: se está gastando menos de lo presupuestado", IF(AA22=1,"Costo según lo presupuestado", "Costo ineficiente: se está gastando más de lo presupuestado"))), "No calculado") -> Costo eficiente: se está gastando menos de lo presupuestado | AC22: =IFERROR(W22/X22,0) -> 0.76 | AD22: =IF(OR(AC22="",AC22=0),"Sin Línea Base", IF(AC22>1,"Proyecto adelantado respecto al cronograma", IF(AC22=1,"Proyecto a tiempo según lo planificado", IF(AC22<1,"Proyecto atrasado con respecto al cronograma", "No calculado")))) -> Proyecto atrasado con respecto al cronograma | AE22: =IFERROR(L22/AA22,0) -> 0 | AF22: =IFERROR(AE22-L22,0) -> -3323223361 | AG22: =VLOOKUP(Indicador!E45,[1]Diccionario!C$1:AC$150,27,0) -> https://growdatasas.sharepoint.com/:x:/r/sites/Gestiondocumental/Administrativa/GD/Financiera/_layouts/15/Doc.aspx?sourcedoc=%7B453B6AA8-B631-4722-B916-8323F8C43E87%7D&file=315%20CORP%20COLOMBIA%20DIGITAL%20FNA%20AE.xlsm&action=default&mobileredirect=true | AH22: 1 | AI22: 1
A23: 2025 | B23: Octubre | C23: 227b8bc1-c7ab-ee11-ba7f-00155d104f2c | D23: 45296.529 | E23: CCD - DPC - IMPLEMENTACIÓN ERP | F23: Johan Sebastian Rodriguez Niño | G23: https://growdatasas.sharepoint.com/sites/pwa/CCD - DPC - IMPLEMENTACIÓN ERP | H23: Suministro e implementación del sistema de información ADMINISTRATIVO ERP NOVASOFT – versión ENTERPRISE WEB y el GESTOR DE RIESGOS para la entidad Defensoría del Pueblo.Incluye: 14 módulos específicos + 5 módulos financieros con licencia para 5000 usuarios finales, Licenciamiento de la Base de Datos SQL Server (Estándar para 8 Cores), Consultoría estándar de implementación de cada uno de los sistemas ofrecidos, soporte y actualización por 2 años y una bolsa de horas (según acuerdo por 2 años) | I23: DATOS Y SISTEMAS DE INFORMACIÓN | J23: 0318 | K23: Activo.En Ejecución | L23: =VLOOKUP(E23,[1]Diccionario!C$2:AC$150,22,0) -> 3323223361 | M23: =VLOOKUP(E23,[1]Diccionario!C$2:AC$150,24,0) -> 45300 | N23: =VLOOKUP(E23,[1]Diccionario!C$2:AC$150,25,0) -> 45473 | O23: =VLOOKUP(E23,[1]Diccionario!C$2:AC$150,26,0) -> 5.7 | P23: =Q23-O23 -> 20.3 | Q23: =DATEDIF(M23,TODAY(),"m") -> 26 | R23: 6 | S23: 1 | T23: =T22+0.02 -> 0.78 | U23: =U22+TablaIndicador[[#This Row],[Costo Mensual]] -> 0 | W23: =IFERROR(T23*L23,0) -> 2.5921142e+09 | X23: =S23*L23 -> 3323223361 | Y23: =IFERROR(W23-U23,0) -> 2.5921142e+09 | Z23: =W23-X23 -> -7.3110914e+08 | AA23: =IFERROR(W23/U23,"No se realizó gasto en este corte") -> No se realizó gasto en este corte | AB23: =IFERROR( IF(OR(AA23="",AA23=0), "No calculado", IF(AA23>1,"Costo eficiente: se está gastando menos de lo presupuestado", IF(AA23=1,"Costo según lo presupuestado", "Costo ineficiente: se está gastando más de lo presupuestado"))), "No calculado") -> Costo eficiente: se está gastando menos de lo presupuestado | AC23: =IFERROR(W23/X23,0) -> 0.78 | AD23: =IF(OR(AC23="",AC23=0),"Sin Línea Base", IF(AC23>1,"Proyecto adelantado respecto al cronograma", IF(AC23=1,"Proyecto a tiempo según lo planificado", IF(AC23<1,"Proyecto atrasado con respecto al cronograma", "No calculado")))) -> Proyecto atrasado con respecto al cronograma | AE23: =IFERROR(L23/AA23,0) -> 0 | AF23: =IFERROR(AE23-L23,0) -> -3323223361 | AG23: =VLOOKUP(Indicador!E46,[1]Diccionario!C$1:AC$150,27,0) -> https://growdatasas.sharepoint.com/:x:/r/sites/Gestiondocumental/Administrativa/GD/Financiera/_layouts/15/Doc.aspx?sourcedoc=%7B453B6AA8-B631-4722-B916-8323F8C43E87%7D&file=315%20CORP%20COLOMBIA%20DIGITAL%20FNA%20AE.xlsm&action=default&mobileredirect=true | AH23: 1 | AI23: 1
A24: 2025 | B24: Noviembre | C24: 227b8bc1-c7ab-ee11-ba7f-00155d104f2c | D24: 45296.529 | E24: CCD - DPC - IMPLEMENTACIÓN ERP | F24: Johan Sebastian Rodriguez Niño | G24: https://growdatasas.sharepoint.com/sites/pwa/CCD - DPC - IMPLEMENTACIÓN ERP | H24: Suministro e implementación del sistema de información ADMINISTRATIVO ERP NOVASOFT – versión ENTERPRISE WEB y el GESTOR DE RIESGOS para la entidad Defensoría del Pueblo.Incluye: 14 módulos específicos + 5 módulos financieros con licencia para 5000 usuarios finales, Licenciamiento de la Base de Datos SQL Server (Estándar para 8 Cores), Consultoría estándar de implementación de cada uno de los sistemas ofrecidos, soporte y actualización por 2 años y una bolsa de horas (según acuerdo por 2 años) | I24: DATOS Y SISTEMAS DE INFORMACIÓN | J24: 0318 | K24: Activo.En Ejecución | L24: =VLOOKUP(E24,[1]Diccionario!C$2:AC$150,22,0) -> 3323223361 | M24: =VLOOKUP(E24,[1]Diccionario!C$2:AC$150,24,0) -> 45300 | N24: =VLOOKUP(E24,[1]Diccionario!C$2:AC$150,25,0) -> 45473 | O24: =VLOOKUP(E24,[1]Diccionario!C$2:AC$150,26,0) -> 5.7 | P24: =Q24-O24 -> 20.3 | Q24: =DATEDIF(M24,TODAY(),"m") -> 26 | R24: 6 | S24: 1 | T24: =T23+0.02 -> 0.8 | U24: =U23+TablaIndicador[[#This Row],[Costo Mensual]] -> 0 | W24: =IFERROR(T24*L24,0) -> 2.6585787e+09 | X24: =S24*L24 -> 3323223361 | Y24: =IFERROR(W24-U24,0) -> 2.6585787e+09 | Z24: =W24-X24 -> -6.6464467e+08 | AA24: =IFERROR(W24/U24,"No se realizó gasto en este corte") -> No se realizó gasto en este corte | AB24: =IFERROR( IF(OR(AA24="",AA24=0), "No calculado", IF(AA24>1,"Costo eficiente: se está gastando menos de lo presupuestado", IF(AA24=1,"Costo según lo presupuestado", "Costo ineficiente: se está gastando más de lo presupuestado"))), "No calculado") -> Costo eficiente: se está gastando menos de lo presupuestado | AC24: =IFERROR(W24/X24,0) -> 0.8 | AD24: =IF(OR(AC24="",AC24=0),"Sin Línea Base", IF(AC24>1,"Proyecto adelantado respecto al cronograma", IF(AC24=1,"Proyecto a tiempo según lo planificado", IF(AC24<1,"Proyecto atrasado con respecto al cronograma", "No calculado")))) -> Proyecto atrasado con respecto al cronograma | AE24: =IFERROR(L24/AA24,0) -> 0 | AF24: =IFERROR(AE24-L24,0) -> -3323223361 | AG24: =VLOOKUP(Indicador!E47,[1]Diccionario!C$1:AC$150,27,0) -> https://growdatasas.sharepoint.com/:x:/r/sites/Gestiondocumental/Administrativa/GD/Financiera/_layouts/15/Doc.aspx?sourcedoc=%7B453B6AA8-B631-4722-B916-8323F8C43E87%7D&file=315%20CORP%20COLOMBIA%20DIGITAL%20FNA%20AE.xlsm&action=default&mobileredirect=true | AH24: 1 | AI24: 1
