Workbook

Sheet Calidad de Datos
B1: Se realiza sobre las entidades Integradas | E1: Entidades con % > 0 / Cantidad total de entidades integradas
B2: COMPLETITUD: Mide el grado en que todos los atributos de la entidad se encuentran diligenciados | E2: Completitud = (número de registros completos/númerto total de registros)*100 | H2: Compeltitud por registro = (número de atributos completos / número total de atributor) * 100
B3: OPORTUNIDAD: Mide si los datos se encuentran disponibles en el momento que se necesitan | E3: % datos disponibles = porcentaje de datos que se pueden acceder en un tiempo definido | H3: Tasa de cumplimiento = mide si el sistema de datos cumple con los tiempos de entrega
B4: CONSISTENCIA: Mide la uniformidad y coherencia de los datos entre diferentes sistemas, asegurando que no haya discrepancias | E4: % de registros consistentes = % de registros que cumplen con las reglas de consistencia
B5: CONFORMIDAD: Mide que los datos se adhieran a las políticas, regulaciones y estándares establecidos | E5: Calidad de datos = % de datos que cumplen los estándares de precisión, integridad y consistencia
C6: =IFERROR(AVERAGEIF(Tabla1[Completitud Ago/2024],">0",Tabla1[Completitud Ago/2024]),0) -> 0.95342105 | D6: =IFERROR(AVERAGEIF(Tabla1[Oportunidad Ago/2024],">0",Tabla1[Oportunidad Ago/2024]),0) -> 0.99710526 | E6: =IFERROR(AVERAGEIF(Tabla1[Consistencia Ago/2024],">0",Tabla1[Consistencia Ago/2024]),0) -> 0.99210526 | F6: =IFERROR(AVERAGEIF(Tabla1[Conformidad Ago/2024],">0",Tabla1[Conformidad Ago/2024]),0) -> 0.8 | G6: =IFERROR(AVERAGEIF(Tabla1[Completitud Sep/2024],">0",Tabla1[Completitud Sep/2024]),0) -> 0.95342105 | H6: =IFERROR(AVERAGEIF(Tabla1[Oportunidad Sep/2024],">0",Tabla1[Oportunidad Sep/2024]),0) -> 1 | I6: =IFERROR(AVERAGEIF(Tabla1[Consistencia Sep/2024],">0",Tabla1[Consistencia Sep/2024]),0) -> 0.99210526 | J6: =IFERROR(AVERAGEIF(Tabla1[Conformidad Sep/2024],">0",Tabla1[Conformidad Sep/2024]),0) -> 0.85 | K6: =IFERROR(AVERAGEIF(Tabla1[Completitud Oct/2024],">0",Tabla1[Completitud Oct/2024]),0) -> 0.95342105 | L6: =IFERROR(AVERAGEIF(Tabla1[Oportunidad Oct/2024],">0",Tabla1[Oportunidad Oct/2024]),0) -> 0.99763158 | M6: =IFERROR(AVERAGEIF(Tabla1[Consistencia Oct/2024],">0",Tabla1[Consistencia Oct/2024]),0) -> 0.99447368 | N6: =IFERROR(AVERAGEIF(Tabla1[Conformidad Oct/2024],">0",Tabla1[Conformidad Oct/2024]),0) -> 0.85 | O6: =IFERROR(AVERAGEIF(Tabla1[Completitud Nov/2024],">0",Tabla1[Completitud Nov/2024]),0) -> 0.93142857 | P6: =IFERROR(AVERAGEIF(Tabla1[Oportunidad Nov/2024],">0",Tabla1[Oportunidad Nov/2024]),0) -> 1 | Q6: =IFERROR(AVERAGEIF(Tabla1[Consistencia Nov/2024],">0",Tabla1[Consistencia Nov/2024]),0) -> 0.96785714 | R6: =IFERROR(AVERAGEIF(Tabla1[Conformidad Nov/2024],">0",Tabla1[Conformidad Nov/2024]),0) -> 0.9 | S6: =IFERROR(AVERAGEIF(Tabla1[Completitud Dic/2024],">0",Tabla1[Completitud Dic/2024]),0) -> 0.93142857 | T6: =IFERROR(AVERAGEIF(Tabla1[Oportunidad Dic/2024],">0",Tabla1[Oportunidad Dic/2024]),0) -> 0.99839286 | U6: =IFERROR(AVERAGEIF(Tabla1[Consistencia Dic/2024],">0",Tabla1[Consistencia Dic/2024]),0) -> 0.97089286 | V6: =IFERROR(AVERAGEIF(Tabla1[Conformidad Dic/2024],">0",Tabla1[Conformidad Dic/2024]),0) -> 0.95 | W6: =IFERROR(AVERAGEIF(Tabla1[Completitud Ene/2025],">0",Tabla1[Completitud Ene/2025]),0) -> 0.96035714 | X6: =IFERROR(AVERAGEIF(Tabla1[Oportunidad Ene/2025],">0",Tabla1[Oportunidad Ene/2025]),0) -> 1 | Y6: =IFERROR(AVERAGEIF(Tabla1[Consistencia Ene/2025],">0",Tabla1[Consistencia Ene/2025]),0) -> 0.97285714 | Z6: =IFERROR(AVERAGEIF(Tabla1[Conformidad Ene/2025],">0",Tabla1[Conformidad Ene/2025]),0) -> 0.975 | AA6: =IFERROR(AVERAGEIF(Tabla1[Completitud Feb/2025],">0",Tabla1[Completitud Feb/2025]),0) -> 0.96566667 | AB6: =IFERROR(AVERAGEIF(Tabla1[Oportunidad Feb/2025],">0",Tabla1[Oportunidad Feb/2025]),0) -> 1 | AC6: =IFERROR(AVERAGEIF(Tabla1[Consistencia Feb/2025],">0",Tabla1[Consistencia Feb/2025]),0) -> 0.979 | AD6: =IFERROR(AVERAGEIF(Tabla1[Conformidad Feb/2025],">0",Tabla1[Conformidad Feb/2025]),0) -> 1 | AE6: =IFERROR(AVERAGEIF(Tabla1[Completitud Mar/2025],">0",Tabla1[Completitud Mar/2025]),0) -> 0.96816667 | AF6: =IFERROR(AVERAGEIF(Tabla1[Oportunidad Mar/2025],">0",Tabla1[Oportunidad Mar/2025]),0) -> 1 | AG6: =IFERROR(AVERAGEIF(Tabla1[Consistencia Mar/2025],">0",Tabla1[Consistencia Mar/2025]),0) -> 0.979 | AH6: =IFERROR(AVERAGEIF(Tabla1[Conformidad Mar/2025],">0",Tabla1[Conformidad Mar/2025]),0) -> 1 | AI6: =IFERROR(AVERAGEIF(Tabla1[Completitud Abr/2025],">0",Tabla1[Completitud Abr/2025]),0) -> 0.976125 | AJ6: =IFERROR(AVERAGEIF(Tabla1[Oportunidad Abr/2025],">0",Tabla1[Oportunidad Abr/2025]),0) -> 0.9325 | AK6: =IFERROR(AVERAGEIF(Tabla1[Consistencia Abr/2025],">0",Tabla1[Consistencia Abr/2025]),0) -> 0.8875 | AL6: =IFERROR(AVERAGEIF(Tabla1[Conformidad Abr/2025],">0",Tabla1[Conformidad Abr/2025]),0) -> 0.9625 | AM6: =IFERROR(AVERAGEIF(Tabla1[Completitud May/2025],">0",Tabla1[Completitud May/2025]),0) -> 0.989 | AN6: =IFERROR(AVERAGEIF(Tabla1[Oportunidad May/2025],">0",Tabla1[Oportunidad May/2025]),0) -> 1 | AO6: =IFERROR(AVERAGEIF(Tabla1[Consistencia May/2025],">0",Tabla1[Consistencia May/2025]),0) -> 0.998 | AP6: =IFERROR(AVERAGEIF(Tabla1[Conformidad May/2025],">0",Tabla1[Conformidad May/2025]),0) -> 1 | AQ6: =IFERROR(AVERAGEIF(Tabla1[Completitud Jun/2025],">0",Tabla1[Completitud Jun/2025]),0) -> 0.9915 | AR6: =IFERROR(AVERAGEIF(Tabla1[Oportunidad Jun/2025],">0",Tabla1[Oportunidad Jun/2025]),0) -> 1 | AS6: =IFERROR(AVERAGEIF(Tabla1[Consistencia Jun/2025],">0",Tabla1[Consistencia Jun/2025]),0) -> 0.998 | AT6: =IFERROR(AVERAGEIF(Tabla1[Conformidad Jun/2025],">0",Tabla1[Conformidad Jun/2025]),0) -> 1 | AU6: =IFERROR(AVERAGEIF(Tabla1[Completitud Sep/2025],">0",Tabla1[Completitud Sep/2025]),0) -> 1 | AV6: =IFERROR(AVERAGEIF(Tabla1[Oportunidad Sep/2025],">0",Tabla1[Oportunidad Sep/2025]),0) -> 1 | AW6: =IFERROR(AVERAGEIF(Tabla1[Consistencia Sep/2025],">0",Tabla1[Consistencia Sep/2025]),0) -> 1 | AX6: =IFERROR(AVERAGEIF(Tabla1[Conformidad Sep/2025],">0",Tabla1[Conformidad Sep/2025]),0) -> 1 | AY6: =IFERROR(AVERAGEIF(Tabla1[Completitud Dic/2025],">0",Tabla1[Completitud Dic/2025]),0) -> 0.89792857 | AZ6: =IFERROR(AVERAGEIF(Tabla1[Oportunidad Dic/2025],">0",Tabla1[Oportunidad Dic/2025]),0) -> 1 | BA6: =IFERROR(AVERAGEIF(Tabla1[Consistencia Dic/2025],">0",Tabla1[Consistencia Dic/2025]),0) -> 0.88813559 | BB6: =IFERROR(AVERAGEIF(Tabla1[Conformidad Dic/2025],">0",Tabla1[Conformidad Dic/2025]),0) -> 1 | BC6: =IFERROR(AVERAGEIF(Tabla1[Completitud Mar/2026],">0",Tabla1[Completitud Mar/2026]),0) -> 0.92676056 | BD6: =IFERROR(AVERAGEIF(Tabla1[Oportunidad Mar/2026],">0",Tabla1[Oportunidad Mar/2026]),0) -> 1 | BE6: =IFERROR(AVERAGEIF(Tabla1[Consistencia Mar/2026],">0",Tabla1[Consistencia Mar/2026]),0) -> 0.98481013 | BF6: =IFERROR(AVERAGEIF(Tabla1[Conformidad Mar/2026],">0",Tabla1[Conformidad Mar/2026]),0) -> 1
B7: Entidades | C7: Completitud Ago/2024 | D7: Oportunidad Ago/2024 | E7: Consistencia Ago/2024 | F7: Conformidad Ago/2024 | G7: Completitud Sep/2024 | H7: Oportunidad Sep/2024 | I7: Consistencia Sep/2024 | J7: Conformidad Sep/2024 | K7: Completitud Oct/2024 | L7: Oportunidad Oct/2024 | M7: Consistencia Oct/2024 | N7: Conformidad Oct/2024 | O7: Completitud Nov/2024 | P7: Oportunidad Nov/2024 | Q7: Consistencia Nov/2024 | R7: Conformidad Nov/2024 | S7: Completitud Dic/2024 | T7: Oportunidad Dic/2024 | U7: Consistencia Dic/2024 | V7: Conformidad Dic/2024 | W7: Completitud Ene/2025 | X7: Oportunidad Ene/2025 | Y7: Consistencia Ene/2025 | Z7: Conformidad Ene/2025 | AA7: Completitud Feb/2025 | AB7: Oportunidad Feb/2025 | AC7: Consistencia Feb/2025 | AD7: Conformidad Feb/2025 | AE7: Completitud Mar/2025 | AF7: Oportunidad Mar/2025 | AG7: Consistencia Mar/2025 | AH7: Conformidad Mar/2025 | AI7: Completitud Abr/2025 | AJ7: Oportunidad Abr/2025 | AK7: Consistencia Abr/2025 | AL7: Conformidad Abr/2025 | AM7: Completitud May/2025 | AN7: Oportunidad May/2025 | AO7: Consistencia May/2025 | AP7: Conformidad May/2025 | AQ7: Completitud Jun/2025 | AR7: Oportunidad Jun/2025 | AS7: Consistencia Jun/2025 | AT7: Conformidad Jun/2025 | AU7: Completitud Sep/2025 | AV7: Oportunidad Sep/2025 | AW7: Consistencia Sep/2025 | AX7: Conformidad Sep/2025 | AY7: Completitud Dic/2025 | AZ7: Oportunidad Dic/2025 | BA7: Consistencia Dic/2025 | BB7: Conformidad Dic/2025 | BC7: Completitud Mar/2026 | BD7: Oportunidad Mar/2026 | BE7: Consistencia Mar/2026 | BF7: Conformidad Mar/2026
B8: Oportunidades | C8: 0.7 | D8: 0.94 | E8: 0.9 | F8: 0.4 | G8: 0.7 | H8: 1 | I8: 0.9 | J8: 0.55 | K8: 0.7 | L8: 0.95 | M8: 0.93 | N8: 0.55 | O8: 0.7 | P8: 1 | Q8: 0.95 | R8: 0.85 | S8: 0.7 | T8: 0.95 | U8: 0.995 | V8: 1 | W8: 0.7 | X8: 1 | Y8: 1 | Z8: 1 | AA8: 0.7 | AB8: 1 | AC8: 1 | AD8: 1 | AE8: 0.7 | AF8: 1 | AG8: 1 | AH8: 1 | AI8: 0.7 | AJ8: 1 | AK8: 1 | AL8: 1 | AM8: 0.8 | AN8: 1 | AO8: 1 | AP8: 1 | AQ8: 0.85 | AR8: 1 | AS8: 1 | AT8: 1 | AU8: 1 | AV8: 1 | AW8: 1 | AX8: 1 | AY8: 0.5255 | AZ8: 1 | BA8: 1 | BB8: 1 | BC8: 0.85 | BD8: 1 | BE8: 1 | BF8: 1
B9: Línea de negocios | C9: 1 | D9: 1 | E9: 1 | F9: 1 | G9: 1 | H9: 1 | I9: 1 | J9: 1 | K9: 1 | L9: 1 | M9: 1 | N9: 1 | O9: 1 | P9: 1 | Q9: 1 | R9: 1 | S9: 1 | T9: 1 | U9: 1 | V9: 1 | W9: 1 | X9: 1 | Y9: 1 | Z9: 1 | AA9: 1 | AB9: 1 | AC9: 1 | AD9: 1 | AE9: 1 | AF9: 1 | AG9: 1 | AH9: 1 | AI9: 1 | AJ9: 1 | AK9: 1 | AL9: 1 | AM9: 1 | AN9: 1 | AO9: 1 | AP9: 1 | AQ9: 1 | AR9: 1 | AS9: 1 | AT9: 1 | AU9: 1 | AV9: 1 | AW9: 1 | AX9: 1 | AY9: 1 | AZ9: 1 | BA9: 1 | BB9: 1 | BC9: 1 | BD9: 1 | BE9: 1 | BF9: 1
B10: Equipo de ventas | C10: 1 | D10: 1 | E10: 1 | F10: 1 | G10: 1 | H10: 1 | I10: 1 | J10: 1 | K10: 1 | L10: 1 | M10: 1 | N10: 1 | O10: 1 | P10: 1 | Q10: 1 | R10: 1 | S10: 1 | T10: 1 | U10: 1 | V10: 1 | W10: 1 | X10: 1 | Y10: 1 | Z10: 1 | AA10: 1 | AB10: 1 | AC10: 1 | AD10: 1 | AE10: 1 | AF10: 1 | AG10: 1 | AH10: 1 | AI10: 1 | AJ10: 1 | AK10: 1 | AL10: 1 | AM10: 1 | AN10: 1 | AO10: 1 | AP10: 1 | AQ10: 1 | AR10: 1 | AS10: 1 | AT10: 1 | AU10: 1 | AV10: 1 | AW10: 1 | AX10: 1 | AY10: 1 | AZ10: 1 | BA10: 1 | BB10: 1 | BC10: 1 | BD10: 1 | BE10: 1 | BF10: 1
B11: Tipo de cliente | C11: 1 | D11: 1 | E11: 1 | F11: 1 | G11: 1 | H11: 1 | I11: 1 | J11: 1 | K11: 1 | L11: 1 | M11: 1 | N11: 1 | O11: 1 | P11: 1 | Q11: 1 | R11: 1 | S11: 1 | T11: 1 | U11: 1 | V11: 1 | W11: 1 | X11: 1 | Y11: 1 | Z11: 1 | AA11: 1 | AB11: 1 | AC11: 1 | AD11: 1 | AE11: 1 | AF11: 1 | AG11: 1 | AH11: 1 | AI11: 1 | AJ11: 1 | AK11: 1 | AL11: 1 | AM11: 1 | AN11: 1 | AO11: 1 | AP11: 1 | AQ11: 1 | AR11: 1 | AS11: 1 | AT11: 1 | AU11: 1 | AV11: 1 | AW11: 1 | AX11: 1 | AY11: 1 | AZ11: 1 | BA11: 1 | BB11: 1 | BC11: 1 | BD11: 1 | BE11: 1 | BF11: 1
B12: Cliente | C12: 0.3 | D12: 1 | E12: 0.9 | F12: 0.3 | G12: 0.3 | H12: 1 | I12: 0.9 | J12: 0.3 | K12: 0.3 | L12: 1 | M12: 0.93 | N12: 0.3 | O12: 0.3 | P12: 1 | Q12: 0.95 | R12: 0.8 | S12: 0.3 | T12: 1 | U12: 0.995 | V12: 1 | W12: 0.3 | X12: 1 | Y12: 1 | Z12: 1 | AA12: 0.3 | AB12: 1 | AC12: 1 | AD12: 1 | AE12: 0.3 | AF12: 1 | AG12: 1 | AH12: 1 | AI12: 0.3 | AJ12: 1 | AK12: 1 | AL12: 1 | AM12: 0.3 | AN12: 1 | AO12: 1 | AP12: 1 | AQ12: 0.5 | AR12: 1 | AS12: 1 | AT12: 1 | AU12: 1 | AV12: 1 | AW12: 1 | AX12: 1 | AY12: 0.354 | AZ12: 1 | BA12: 1 | BB12: 1 | BC12: 0.9 | BD12: 1 | BE12: 0.6 | BF12: 1
B13: Tipo de venta | C13: 1 | D13: 1 | E13: 1 | F13: 1 | G13: 1 | H13: 1 | I13: 1 | J13: 1 | K13: 1 | L13: 1 | M13: 1 | N13: 1 | O13: 1 | P13: 1 | Q13: 1 | R13: 1 | S13: 1 | T13: 1 | U13: 1 | V13: 1 | W13: 1 | X13: 1 | Y13: 1 | Z13: 1 | AA13: 1 | AB13: 1 | AC13: 1 | AD13: 1 | AE13: 1 | AF13: 1 | AG13: 1 | AH13: 1 | AI13: 1 | AJ13: 1 | AK13: 1 | AL13: 1 | AM13: 1 | AN13: 1 | AO13: 1 | AP13: 1 | AQ13: 1 | AR13: 1 | AS13: 1 | AT13: 1 | AU13: 1 | AV13: 1 | AW13: 1 | AX13: 1 | AY13: 1 | AZ13: 1 | BA13: 1 | BB13: 1 | BC13: 1 | BD13: 1 | BE13: 1 | BF13: 1
B14: Tipo de oportunidad | C14: 1 | D14: 1 | E14: 1 | F14: 1 | G14: 1 | H14: 1 | I14: 1 | J14: 1 | K14: 1 | L14: 1 | M14: 1 | N14: 1 | O14: 1 | P14: 1 | Q14: 1 | R14: 1 | S14: 1 | T14: 1 | U14: 1 | V14: 1 | W14: 1 | X14: 1 | Y14: 1 | Z14: 1 | AA14: 1 | AB14: 1 | AC14: 1 | AD14: 1 | AE14: 1 | AF14: 1 | AG14: 1 | AH14: 1 | AI14: 1 | AJ14: 1 | AK14: 1 | AL14: 1 | AM14: 1 | AN14: 1 | AO14: 1 | AP14: 1 | AQ14: 1 | AR14: 1 | AS14: 1 | AT14: 1 | AU14: 1 | AV14: 1 | AW14: 1 | AX14: 1 | AY14: 1 | AZ14: 1 | BA14: 1 | BB14: 1 | BC14: 1 | BD14: 1 | BE14: 1 | BF14: 1
B15: Etapa actual | C15: 1 | D15: 1 | E15: 1 | F15: 1 | G15: 1 | H15: 1 | I15: 1 | J15: 1 | K15: 1 | L15: 1 | M15: 1 | N15: 1 | O15: 1 | P15: 1 | Q15: 1 | R15: 1 | S15: 1 | T15: 1 | U15: 1 | V15: 1 | W15: 1 | X15: 1 | Y15: 1 | Z15: 1 | AA15: 1 | AB15: 1 | AC15: 1 | AD15: 1 | AE15: 1 | AF15: 1 | AG15: 1 | AH15: 1 | AI15: 1 | AJ15: 1 | AK15: 1 | AL15: 1 | AM15: 1 | AN15: 1 | AO15: 1 | AP15: 1 | AQ15: 1 | AR15: 1 | AS15: 1 | AT15: 1 | AU15: 1 | AV15: 1 | AW15: 1 | AX15: 1 | AY15: 1 | AZ15: 1 | BA15: 1 | BB15: 1 | BC15: 1 | BD15: 1 | BE15: 1 | BF15: 1
B16: Ganado | C16: 1 | D16: 1 | E16: 1 | F16: 1 | G16: 1 | H16: 1 | I16: 1 | J16: 1 | K16: 1 | L16: 1 | M16: 1 | N16: 1 | O16: 1 | P16: 1 | Q16: 1 | R16: 1 | S16: 1 | T16: 1 | U16: 1 | V16: 1 | W16: 1 | X16: 1 | Y16: 1 | Z16: 1 | AA16: 1 | AB16: 1 | AC16: 1 | AD16: 1 | AE16: 1 | AF16: 1 | AG16: 1 | AH16: 1 | AI16: 1 | AJ16: 1 | AK16: 1 | AL16: 1 | AM16: 1 | AN16: 1 | AO16: 1 | AP16: 1 | AQ16: 1 | AR16: 1 | AS16: 1 | AT16: 1 | AU16: 1 | AV16: 1 | AW16: 1 | AX16: 1 | AY16: 1 | AZ16: 1 | BA16: 1 | BB16: 1 | BC16: 1 | BD16: 1 | BE16: 1 | BF16: 1
B17: Metas | C17: 1 | D17: 1 | E17: 1 | F17: 1 | G17: 1 | H17: 1 | I17: 1 | J17: 1 | K17: 1 | L17: 1 | M17: 1 | N17: 1 | O17: 1 | P17: 1 | Q17: 1 | R17: 1 | S17: 1 | T17: 1 | U17: 1 | V17: 1 | W17: 1 | X17: 1 | Y17: 1 | Z17: 1 | AA17: 1 | AB17: 1 | AC17: 1 | AD17: 1 | AE17: 1 | AF17: 1 | AG17: 1 | AH17: 1 | AI17: 1 | AJ17: 1 | AK17: 1 | AL17: 1 | AM17: 1 | AN17: 1 | AO17: 1 | AP17: 1 | AQ17: 1 | AR17: 1 | AS17: 1 | AT17: 1 | AU17: 1 | AV17: 1 | AW17: 1 | AX17: 1 | AY17: 1 | AZ17: 1 | BA17: 1 | BB17: 1 | BC17: 1 | BD17: 1 | BE17: 1 | BF17: 1
B18: Metas de Comercial | C18: 1 | D18: 1 | E18: 1 | F18: 1 | G18: 1 | H18: 1 | I18: 1 | J18: 1 | K18: 1 | L18: 1 | M18: 1 | N18: 1 | O18: 1 | P18: 1 | Q18: 1 | R18: 1 | S18: 1 | T18: 1 | U18: 1 | V18: 1 | W18: 1 | X18: 1 | Y18: 1 | Z18: 1 | AA18: 1 | AB18: 1 | AC18: 1 | AD18: 1 | AE18: 1 | AF18: 1 | AG18: 1 | AH18: 1 | AI18: 1 | AJ18: 1 | AK18: 1 | AL18: 1 | AM18: 1 | AN18: 1 | AO18: 1 | AP18: 1 | AQ18: 1 | AR18: 1 | AS18: 1 | AT18: 1 | AU18: 1 | AV18: 1 | AW18: 1 | AX18: 1 | AY18: 1 | AZ18: 1 | BA18: 1 | BB18: 1 | BC18: 1 | BD18: 1 | BE18: 1 | BF18: 1
B19: Área | C19: 1 | D19: 1 | E19: 1 | F19: 1 | G19: 1 | H19: 1 | I19: 1 | J19: 1 | K19: 1 | L19: 1 | M19: 1 | N19: 1 | O19: 1 | P19: 1 | Q19: 1 | R19: 1 | S19: 1 | T19: 1 | U19: 1 | V19: 1 | W19: 1 | X19: 1 | Y19: 1 | Z19: 1 | AA19: 1 | AB19: 1 | AC19: 1 | AD19: 1 | AE19: 1 | AF19: 1 | AG19: 1 | AH19: 1 | AI19: 1 | AJ19: 1 | AK19: 1 | AL19: 1 | AM19: 1 | AN19: 1 | AO19: 1 | AP19: 1 | AQ19: 1 | AR19: 1 | AS19: 1 | AT19: 1 | AU19: 1 | AV19: 1 | AW19: 1 | AX19: 1 | AY19: 1 | AZ19: 1 | BA19: 1 | BB19: 1 | BC19: 1 | BD19: 1 | BE19: 1 | BF19: 1
... B58: Plan de capacitaciones | C58: 0 | D58: 0 | E58: 0 | F58: 0 | G58: 0 | H58: 0 | I58: 0 | J58: 0 | K58: 0 | L58: 0 | M58: 0 | N58: 0 | O58: 0.72 | P58: 1 | Q58: 0.8 | R58: 0.5 | S58: 0.72 | T58: 1 | U58: 0.8 | V58: 0.7 | W58: 0.9 | X58: 1 | Y58: 0.9 | Z58: 0.9 | AA58: 0.95 | AB58: 1 | AC58: 0.9 | AD58: 1 | AE58: 1 | AF58: 1 | AG58: 0.9 | AH58: 1 | AI58: 1 | AJ58: 1 | AK58: 1 | AL58: 1 | AM58: 1 | AN58: 1 | AO58: 1 | AP58: 1 | AQ58: 1 | AR58: 1 | AS58: 1 | AT58: 1 | AU58: 1 | AV58: 1 | AW58: 1 | AX58: 1 | AY58: 1 | AZ58: 1 | BA58: 1 | BB58: 1 | BC58: 1 | BD58: 1 | BE58: 1 | BF58: 1
B59: Ordenes de compras | AI59: 1 | AJ59: 0.4 | AK59: 0.4 | AL59: 0.4 | AM59: 1 | AN59: 1 | AO59: 1 | AP59: 1 | AQ59: 1 | AR59: 1 | AS59: 1 | AT59: 1 | AU59: 1 | AV59: 1 | AW59: 1 | AX59: 1 | AY59: 1 | AZ59: 1 | BA59: 1 | BB59: 1 | BC59: 1 | BD59: 1 | BE59: 1 | BF59: 1
B60: Proveedores | AI60: 1 | AJ60: 0.4 | AK60: 0.4 | AL60: 0.4 | AM60: 1 | AN60: 1 | AO60: 1 | AP60: 1 | AQ60: 1 | AR60: 1 | AS60: 1 | AT60: 1 | AU60: 1 | AV60: 1 | AW60: 1 | AX60: 1 | AY60: 1 | AZ60: 1 | BA60: 1 | BB60: 1 | BC60: 1 | BD60: 1 | BE60: 1 | BF60: 1
B61: Requisiciones | AI61: 1 | AJ61: 0.4 | AK61: 0.4 | AL61: 0.4 | AM61: 1 | AN61: 1 | AO61: 1 | AP61: 1 | AQ61: 1 | AR61: 1 | AS61: 1 | AT61: 1 | AU61: 1 | AV61: 1 | AW61: 1 | AX61: 1 | AY61: 1 | AZ61: 1 | BA61: 1 | BB61: 1 | BC61: 1 | BD61: 1 | BE61: 1 | BF61: 1
B62: Contratos | AI62: 1 | AJ62: 0.4 | AK62: 0.4 | AL62: 1 | AM62: 1 | AN62: 1 | AO62: 1 | AP62: 1 | AQ62: 1 | AR62: 1 | AS62: 1 | AT62: 1 | AU62: 1 | AV62: 1 | AW62: 1 | AX62: 1 | AY62: 1 | AZ62: 1 | BA62: 1 | BB62: 1 | BC62: 1 | BD62: 1 | BE62: 1 | BF62: 1
B63: Solicitud de contratación logistica | AI63: 1 | AJ63: 0.4 | AK63: 0.4 | AL63: 1 | AM63: 1 | AN63: 1 | AO63: 1 | AP63: 1 | AQ63: 1 | AR63: 1 | AS63: 1 | AT63: 1 | AU63: 1 | AV63: 1 | AW63: 1 | AX63: 1 | AY63: 1 | AZ63: 1 | BA63: 1 | BB63: 1 | BC63: 1 | BD63: 1 | BE63: 1 | BF63: 1
B64: Registro de ahorros | AI64: 1 | AJ64: 0.4 | AK64: 0.4 | AL64: 1 | AM64: 1 | AN64: 1 | AO64: 1 | AP64: 1 | AQ64: 1 | AR64: 1 | AS64: 1 | AT64: 1 | AU64: 1 | AV64: 1 | AW64: 1 | AX64: 1 | AY64: 1 | AZ64: 1 | BA64: 1 | BB64: 1 | BC64: 1 | BD64: 1 | BE64: 1 | BF64: 1
B65: Modelo financiero | AM65: 1 | AN65: 1 | AO65: 1 | AP65: 1 | AQ65: 1 | AR65: 1 | AS65: 1 | AT65: 1 | AU65: 1 | AV65: 1 | AW65: 1 | AX65: 1 | AY65: 1 | AZ65: 1 | BA65: 1 | BB65: 1 | BC65: 1 | BD65: 1 | BE65: 1 | BF65: 1
B66: Oferta comercial | AY66: 0.8 | AZ66: 1 | BA66: 1 | BB66: 1 | BC66: 1 | BD66: 1 | BE66: 1 | BF66: 1
B67: Acta | AY67: 1 | AZ67: 1 | BA67: 1 | BB67: 1 | BC67: 1 | BD67: 1 | BE67: 1 | BF67: 1
B68: Fabricante | AI68: 1 | AJ68: 1 | AK68: 1 | AL68: 1 | AM68: 1 | AN68: 1 | AO68: 1 | AP68: 1 | AQ68: 1 | AR68: 1 | AS68: 1 | AT68: 1 | AU68: 1 | AV68: 1 | AW68: 1 | AX68: 1 | AY68: 1 | AZ68: 1 | BA68: 1 | BB68: 1 | BC68: 1 | BD68: 1 | BE68: 1 | BF68: 1
B69: Proceso | AY69: 0.8 | AZ69: 1 | BA69: 1 | BB69: 1 | BC69: 0.8 | BD69: 1 | BE69: 1 | BF69: 1
B70: Productos | AY70: 0.8 | AZ70: 1 | BA70: 1 | BB70: 1 | BC70: 0.8 | BD70: 1 | BE70: 1 | BF70: 1
B71: Servicio | AI71: 1 | AJ71: 1 | AK71: 1 | AL71: 1 | AM71: 1 | AN71: 1 | AO71: 1 | AP71: 1 | AQ71: 1 | AR71: 1 | AS71: 1 | AT71: 1 | AU71: 1 | AV71: 1 | AW71: 1 | AX71: 1 | AY71: 1 | AZ71: 1 | BA71: 1 | BB71: 1 | BC71: 1 | BD71: 1 | BE71: 1 | BF71: 1
B72: Entregable | AY72: 0.4 | AZ72: 1 | BA72: 1 | BB72: 1 | BC72: 0.4 | BD72: 1 | BE72: 1 | BF72: 1
B73: Artefacto | AY73: 0.4 | AZ73: 1 | BA73: 1 | BB73: 1 | BC73: 0.4 | BD73: 1 | BE73: 1 | BF73: 1
B74: Riesgos y Oportunidades | AY74: 0.4 | AZ74: 1 | BA74: 1 | BB74: 1 | BC74: 0.4 | BD74: 1 | BE74: 1 | BF74: 1
B75: Política | AY75: 0.8 | AZ75: 1 | BA75: 1 | BB75: 1 | BC75: 0.8 | BD75: 1 | BE75: 1 | BF75: 1
B76: Guía | AY76: 0.8 | AZ76: 1 | BA76: 1 | BB76: 1 | BC76: 0.8 | BD76: 1 | BE76: 1 | BF76: 1
B77: Requisitos Norma ISO 9001 | AY77: 0.4 | AZ77: 1 | BA77: 1 | BB77: 1 | BC77: 0.4 | BD77: 1 | BE77: 1 | BF77: 1
B78: Salidas no conformes | AY78: 0.7 | AZ78: 1 | BA78: 1 | BB78: 1 | BC78: 0.8 | BD78: 1 | BE78: 1 | BF78: 1
...

Sheet Uso-Acceso Datos
B1: Se realiza sobre las entidades identificadas en los procesos
C2: =AVERAGE(Tabla13[Uso y acceso Ago/2024]) -> 0.86971154 | D2: =AVERAGE(Tabla13[Uso y acceso Sep/2024]) -> 0.87163462 | E2: =AVERAGE(Tabla13[Uso y acceso Oct/2024]) -> 0.94182692 | F2: =AVERAGE(Tabla13[Uso y acceso Nov/2024]) -> 0.94459135 | G2: =AVERAGE(Tabla13[Uso y acceso Dic/2024]) -> 0.95766827 | H2: =AVERAGE(Tabla13[Uso y acceso Ene/2025]) -> 0.95766827 | I2: =AVERAGE(Tabla13[Uso y acceso Feb/2025]) -> 0.95941038 | J2: =AVERAGE(Tabla13[Uso y acceso Mar/2025]) -> 0.95941038 | K2: =AVERAGE(Tabla13[Uso y acceso Abr/2025]) -> 0.96052752 | L2: =AVERAGE(Tabla13[Uso y acceso May/2025]) -> 0.97845291 | M2: =AVERAGE(Tabla13[Uso y acceso Jun/2025]) -> 0.97847534 | N2: =AVERAGE(Tabla13[Uso y acceso Sep/2025]) -> 0.97847534 | O2: =AVERAGE(Tabla13[Uso y acceso Dic/2025]) -> 0.98779412 | P2: =AVERAGE(Tabla13[Uso y acceso Mar/2026]) -> 0.98403361
B3: Entidades | C3: Uso y acceso Ago/2024 | D3: Uso y acceso Sep/2024 | E3: Uso y acceso Oct/2024 | F3: Uso y acceso Nov/2024 | G3: Uso y acceso Dic/2024 | H3: Uso y acceso Ene/2025 | I3: Uso y acceso Feb/2025 | J3: Uso y acceso Mar/2025 | K3: Uso y acceso Abr/2025 | L3: Uso y acceso May/2025 | M3: Uso y acceso Jun/2025 | N3: Uso y acceso Sep/2025 | O3: Uso y acceso Dic/2025 | P3: Uso y acceso Mar/2026
B4: Oportunidades | C4: 1 | D4: 1 | E4: 1 | F4: 1 | G4: 1 | H4: 1 | I4: 1 | J4: 1 | K4: 1 | L4: 1 | M4: 1 | N4: 1 | O4: 1 | P4: 1
B5: Línea de negocios | C5: 1 | D5: 1 | E5: 1 | F5: 1 | G5: 1 | H5: 1 | I5: 1 | J5: 1 | K5: 1 | L5: 1 | M5: 1 | N5: 1 | O5: 1 | P5: 1
B6: Equipo de ventas | C6: 1 | D6: 1 | E6: 1 | F6: 1 | G6: 1 | H6: 1 | I6: 1 | J6: 1 | K6: 1 | L6: 1 | M6: 1 | N6: 1 | O6: 1 | P6: 1
B7: Tipo de cliente | C7: 1 | D7: 1 | E7: 1 | F7: 1 | G7: 1 | H7: 1 | I7: 1 | J7: 1 | K7: 1 | L7: 1 | M7: 1 | N7: 1 | O7: 1 | P7: 1
B8: Cliente | C8: 1 | D8: 1 | E8: 1 | F8: 1 | G8: 1 | H8: 1 | I8: 1 | J8: 1 | K8: 1 | L8: 1 | M8: 1 | N8: 1 | O8: 1 | P8: 1
B9: Tipo de venta | C9: 1 | D9: 1 | E9: 1 | F9: 1 | G9: 1 | H9: 1 | I9: 1 | J9: 1 | K9: 1 | L9: 1 | M9: 1 | N9: 1 | O9: 1 | P9: 1
B10: Tipo de oportunidad | C10: 1 | D10: 1 | E10: 1 | F10: 1 | G10: 1 | H10: 1 | I10: 1 | J10: 1 | K10: 1 | L10: 1 | M10: 1 | N10: 1 | O10: 1 | P10: 1
B11: Etapa actual | C11: 1 | D11: 1 | E11: 1 | F11: 1 | G11: 1 | H11: 1 | I11: 1 | J11: 1 | K11: 1 | L11: 1 | M11: 1 | N11: 1 | O11: 1 | P11: 1
B12: Ganado | C12: 1 | D12: 1 | E12: 1 | F12: 1 | G12: 1 | H12: 1 | I12: 1 | J12: 1 | K12: 1 | L12: 1 | M12: 1 | N12: 1 | O12: 1 | P12: 1
B13: Metas | C13: 1 | D13: 1 | E13: 1 | F13: 1 | G13: 1 | H13: 1 | I13: 1 | J13: 1 | K13: 1 | L13: 1 | M13: 1 | N13: 1 | O13: 1 | P13: 1
B14: Metas de Comercial | C14: 1 | D14: 1 | E14: 1 | F14: 1 | G14: 1 | H14: 1 | I14: 1 | J14: 1 | K14: 1 | L14: 1 | M14: 1 | N14: 1 | O14: 1 | P14: 1
B15: Área | C15: 1 | D15: 1 | E15: 1 | F15: 1 | G15: 1 | H15: 1 | I15: 1 | J15: 1 | K15: 1 | L15: 1 | M15: 1 | N15: 1 | O15: 1 | P15: 1
... B211: Hallazgos | C211: 1 | D211: 1 | E211: 1 | F211: 1 | G211: 1 | H211: 1 | I211: 1 | J211: 1 | K211: 1 | L211: 1 | M211: 1 | N211: 1 | O211: 1 | P211: 1
B212: Tipo de retiro | I212: 1 | J212: 1 | K212: 1 | L212: 1 | M212: 1 | N212: 1 | O212: 1 | P212: 1
B213: Tipo de movimiento laboral | I213: 1 | J213: 1 | K213: 1 | L213: 1 | M213: 1 | N213: 1 | O213: 1 | P213: 1
B214: Tipo de fuero | I214: 1 | J214: 1 | K214: 1 | L214: 1 | M214: 1 | N214: 1 | O214: 1 | P214: 1
B215: Generación por año de nacimiento | I215: 1 | J215: 1 | K215: 1 | L215: 1 | M215: 1 | N215: 1 | O215: 1 | P215: 1
B216: Identificación del proceso | K216: 1 | L216: 1 | M216: 1 | N216: 1 | O216: 1 | P216: 1
B217: Modalidad de contratación | K217: 1 | L217: 1 | M217: 1 | N217: 1 | O217: 1 | P217: 1
B218: Sector | K218: 1 | L218: 1 | M218: 1 | N218: 1 | O218: 1 | P218: 1
B219: Subsector | K219: 1 | L219: 1 | M219: 1 | N219: 1 | O219: 1 | P219: 1
B220: Orden de servicio | K220: 1 | L220: 1 | M220: 1 | N220: 1 | O220: 1 | P220: 1
B221: Orden de trabajo | K221: 1 | L221: 1 | M221: 1 | N221: 1 | O221: 1 | P221: 1
B222: Categoría servicios TI | L222: 1 | M222: 1 | N222: 1 | O222: 1 | P222: 1
B223: Servicios TI | L223: 1 | M223: 1 | N223: 1 | O223: 1 | P223: 1
B224: Control de acceso | L224: 1 | M224: 1 | N224: 1 | O224: 1 | P224: 1
B225: Evento | L225: 1 | M225: 1 | N225: 1 | O225: 1 | P225: 1
B226: Canales digitales | L226: 1 | M226: 1 | N226: 1 | O226: 1 | P226: 1
B227: Medio de solicitud a doit | O227: 1 | P227: 1
B228: Prioridad del Ticket | O228: 1 | P228: 1
B229: Naturaleza del caso | O229: 1 | P229: 1
B230: Estados de los tickets TI | O230: 1 | P230: 1
B231: Estado orden de servicio | O231: 1 | P231: 1
B232: Canal de recepción | O232: 1 | P232: 1
B233: Canal de comunicación | O233: 1 | P233: 1
B234: Tipo de entregable | O234: 1 | P234: 1
B235: Segmentación Proyectos | O235: 1 | P235: 1
...

Sheet Integracion-Flujo Datos
B1: Se realiza sobre las entidades identificadas en los procesos
C2: =AVERAGE(Tabla58[Integración Ago/2024]) -> 0.18028846 | D2: =AVERAGE(Tabla58[Integración Sep/2024]) -> 0.18125 | E2: =AVERAGE(Tabla58[Integración Oct/2024]) -> 0.19591346 | F2: =AVERAGE(Tabla58[Integración Nov/2024]) -> 0.21730769 | G2: =AVERAGE(Tabla58[Integración Dic/2024]) -> 0.25192308 | H2: =AVERAGE(Tabla58[Integración Ene/2025]) -> 0.25528846 | I2: =AVERAGE(Tabla58[Integración Feb/2025]) -> 0.29292453 | J2: =AVERAGE(Tabla58[Integración Mar/2025]) -> 0.29292453 | K2: =AVERAGE(Tabla58[Integración Abr/2025]) -> 0.32981651 | L2: =AVERAGE(Tabla58[Integración May/2025]) -> 0.34394619 | M2: =AVERAGE(Tabla58[Integración Jun/2025]) -> 0.35560538 | N2: =AVERAGE(Tabla58[Integración Sep/2025]) -> 0.3632287 | O2: =AVERAGE(Tabla58[Integración Dic/2025]) -> 0.80042017 | P2: =AVERAGE(Tabla58[Integración Mar/2026]) -> 0.79957983
B3: Entidades | C3: Integración Ago/2024 | D3: Integración Sep/2024 | E3: Integración Oct/2024 | F3: Integración Nov/2024 | G3: Integración Dic/2024 | H3: Integración Ene/2025 | I3: Integración Feb/2025 | J3: Integración Mar/2025 | K3: Integración Abr/2025 | L3: Integración May/2025 | M3: Integración Jun/2025 | N3: Integración Sep/2025 | O3: Integración Dic/2025 | P3: Integración Mar/2026
B4: Oportunidades | C4: 1 | D4: 1 | E4: 1 | F4: 1 | G4: 1 | H4: 1 | I4: 1 | J4: 1 | K4: 1 | L4: 1 | M4: 1 | N4: 1 | O4: 1 | P4: 1
B5: Línea de negocios | C5: 1 | D5: 1 | E5: 1 | F5: 1 | G5: 1 | H5: 1 | I5: 1 | J5: 1 | K5: 1 | L5: 1 | M5: 1 | N5: 1 | O5: 1 | P5: 1
B6: Equipo de ventas | C6: 1 | D6: 1 | E6: 1 | F6: 1 | G6: 1 | H6: 1 | I6: 1 | J6: 1 | K6: 1 | L6: 1 | M6: 1 | N6: 1 | O6: 1 | P6: 1
B7: Tipo de cliente | C7: 1 | D7: 1 | E7: 1 | F7: 1 | G7: 1 | H7: 1 | I7: 1 | J7: 1 | K7: 1 | L7: 1 | M7: 1 | N7: 1 | O7: 1 | P7: 1
B8: Cliente | C8: 1 | D8: 1 | E8: 1 | F8: 1 | G8: 1 | H8: 1 | I8: 1 | J8: 1 | K8: 1 | L8: 1 | M8: 1 | N8: 1 | O8: 1 | P8: 1
B9: Tipo de venta | C9: 1 | D9: 1 | E9: 1 | F9: 1 | G9: 1 | H9: 1 | I9: 1 | J9: 1 | K9: 1 | L9: 1 | M9: 1 | N9: 1 | O9: 1 | P9: 1
B10: Tipo de oportunidad | C10: 1 | D10: 1 | E10: 1 | F10: 1 | G10: 1 | H10: 1 | I10: 1 | J10: 1 | K10: 1 | L10: 1 | M10: 1 | N10: 1 | O10: 1 | P10: 1
B11: Etapa actual | C11: 1 | D11: 1 | E11: 1 | F11: 1 | G11: 1 | H11: 1 | I11: 1 | J11: 1 | K11: 1 | L11: 1 | M11: 1 | N11: 1 | O11: 1 | P11: 1
B12: Ganado | C12: 1 | D12: 1 | E12: 1 | F12: 1 | G12: 1 | H12: 1 | I12: 1 | J12: 1 | K12: 1 | L12: 1 | M12: 1 | N12: 1 | O12: 1 | P12: 1
B13: Metas | C13: 1 | D13: 1 | E13: 1 | F13: 1 | G13: 1 | H13: 1 | I13: 1 | J13: 1 | K13: 1 | L13: 1 | M13: 1 | N13: 1 | O13: 1 | P13: 1
B14: Metas de Comercial | C14: 1 | D14: 1 | E14: 1 | F14: 1 | G14: 1 | H14: 1 | I14: 1 | J14: 1 | K14: 1 | L14: 1 | M14: 1 | N14: 1 | O14: 1 | P14: 1
B15: Área | C15: 1 | D15: 1 | E15: 1 | F15: 1 | G15: 1 | H15: 1 | I15: 1 | J15: 1 | K15: 1 | L15: 1 | M15: 1 | N15: 1 | O15: 1 | P15: 1
... B211: Hallazgos | C211: 0 | D211: 0 | E211: 0 | F211: 0 | G211: 0 | H211: 0 | I211: 0 | J211: 0 | K211: 0 | L211: 0.3 | M211: 0.3 | N211: 0.3 | O211: 0.6 | P211: 0.6
B212: Tipo de retiro | I212: 1 | J212: 1 | K212: 1 | L212: 1 | M212: 1 | N212: 1 | O212: 1 | P212: 1
B213: Tipo de movimiento laboral | I213: 1 | J213: 1 | K213: 1 | L213: 1 | M213: 1 | N213: 1 | O213: 1 | P213: 1
B214: Tipo de fuero | I214: 1 | J214: 1 | K214: 1 | L214: 1 | M214: 1 | N214: 1 | O214: 1 | P214: 1
B215: Generación por año de nacimiento | I215: 1 | J215: 1 | K215: 1 | L215: 1 | M215: 1 | N215: 1 | O215: 1 | P215: 1
B216: Identificación del proceso | K216: 1 | L216: 1 | M216: 1 | N216: 1 | O216: 1 | P216: 1
B217: Modalidad de contratación | K217: 1 | L217: 1 | M217: 1 | N217: 1 | O217: 1 | P217: 1
B218: Sector | K218: 1 | L218: 1 | M218: 1 | N218: 1 | O218: 1 | P218: 1
B219: Subsector | K219: 1 | L219: 1 | M219: 1 | N219: 1 | O219: 1 | P219: 1
B220: Orden de servicio | K220: 0.3 | L220: 0.3 | M220: 0.3 | N220: 0.3 | O220: 0.8 | P220: 0.8
B221: Orden de trabajo | K221: 0.3 | L221: 0.3 | M221: 0.3 | N221: 0.3 | O221: 0.8 | P221: 0.8
B222: Categoría servicios TI | L222: 0.3 | M222: 0.3 | N222: 0.3 | O222: 1 | P222: 1
B223: Servicios TI | L223: 0.3 | M223: 0.3 | N223: 0.3 | O223: 1 | P223: 1
B224: Control de acceso | L224: 0.3 | M224: 0.3 | N224: 0.3 | O224: 0.8 | P224: 0.8
B225: Evento | L225: 0.3 | M225: 0.3 | N225: 0.3 | O225: 0.8 | P225: 0.8
B226: Canales digitales | L226: 0.3 | M226: 0.3 | N226: 0.3 | O226: 1 | P226: 1
B227: Medio de solicitud a doit | O227: 1 | P227: 1
B228: Prioridad del Ticket | O228: 1 | P228: 1
B229: Naturaleza del caso | O229: 1 | P229: 1
B230: Estados de los tickets TI | O230: 1 | P230: 1
B231: Estado orden de servicio | O231: 1 | P231: 1
B232: Canal de recepción | O232: 1 | P232: 1
B233: Canal de comunicación | O233: 1 | P233: 1
B234: Tipo de entregable | O234: 1 | P234: 1
B235: Segmentación Proyectos | O235: 1 | P235: 1
...

Sheet Gestion Ciclo-Vida Datos
B1: Se realiza sobre las entidades identificadas en los procesos. Esta definido por los indicadores Calidad de datos, Uso-Acceso Datos, Integración-Flujo de datos; adicional a estos Creación y captura, Almacenamiento y registro
C2: =IFERROR(AVERAGEIF(Tabla4[Creación y captura Ago/2024],">0",Tabla4[Creación y captura Ago/2024]),0) -> 0.99605263 | D2: =IFERROR(AVERAGEIF(Tabla4[Almacenamiento y registro Ago/2024],">0",Tabla4[Almacenamiento y registro Ago/2024]),0) -> 0.98684211 | E2: =IFERROR(AVERAGEIF(Tabla4[Calidad de datos Ago/2024],">0",Tabla4[Calidad de datos Ago/2024]),0) -> 0.93565789 | F2: =IF(ISERROR(AVERAGE(Tabla4[Uso y acceso Ago/2024])),"",AVERAGE(Tabla4[Uso y acceso Ago/2024])) -> 0.86971154 | G2: =IF(ISERROR(AVERAGE(Tabla4[Compartición e Interoperabilidad Ago/2024])),"",AVERAGE(Tabla4[Compartición e Interoperabilidad Ago/2024])) -> 0.18028846 | H2: =IF(ISERROR(AVERAGE(C2:G2)),"",AVERAGE(C2:G2)) -> 0.79371053 | I2: =IFERROR(AVERAGEIF(Tabla4[Creación y captura Sep/2024],">0",Tabla4[Creación y captura Sep/2024]),0) -> 0.97948718 | J2: =IFERROR(AVERAGEIF(Tabla4[Almacenamiento y registro Sep/2024],">0",Tabla4[Almacenamiento y registro Sep/2024]),0) -> 0.96666667 | K2: =IFERROR(AVERAGEIF(Tabla4[Calidad de datos Sep/2024],">0",Tabla4[Calidad de datos Sep/2024]),0) -> 0.94888158 | L2: =IF(ISERROR(AVERAGE(Tabla4[Uso y acceso Sep/2024])),"",AVERAGE(Tabla4[Uso y acceso Sep/2024])) -> 0.87163462 | M2: =IF(ISERROR(AVERAGE(Tabla4[Compartición e Interoperabilidad Sep/2024])),"",AVERAGE(Tabla4[Compartición e Interoperabilidad Sep/2024])) -> 0.18125 | N2: =IF(ISERROR(AVERAGE(I2:M2)),"",AVERAGE(I2:M2)) -> 0.78958401 | O2: =IFERROR(AVERAGEIF(Tabla4[Creación y captura Oct/2024],">0",Tabla4[Creación y captura Oct/2024]),0) -> 0.86666667 | P2: =IFERROR(AVERAGEIF(Tabla4[Almacenamiento y registro Oct/2024],">0",Tabla4[Almacenamiento y registro Oct/2024]),0) -> 0.79901961 | Q2: =IFERROR(AVERAGEIF(Tabla4[Calidad de datos Oct/2024],">0",Tabla4[Calidad de datos Oct/2024]),0) -> 0.94888158 | R2: =IF(ISERROR(AVERAGE(Tabla4[Uso y acceso Oct/2024])),"",AVERAGE(Tabla4[Uso y acceso Oct/2024])) -> 0.94182692 | S2: =IF(ISERROR(AVERAGE(Tabla4[Compartición e Interoperabilidad Oct/2024])),"",AVERAGE(Tabla4[Compartición e Interoperabilidad Oct/2024])) -> 0.19591346 | T2: =IF(ISERROR(AVERAGE(O2:S2)),"",AVERAGE(O2:S2)) -> 0.75046165 | U2: =IFERROR(AVERAGEIF(Tabla4[Creación y captura Nov/2024],">0",Tabla4[Creación y captura Nov/2024]),0) -> 0.96785714 | V2: =IFERROR(AVERAGEIF(Tabla4[Almacenamiento y registro Nov/2024],">0",Tabla4[Almacenamiento y registro Nov/2024]),0) -> 0.91730769 | W2: =IFERROR(AVERAGEIF(Tabla4[Calidad de datos Nov/2024],">0",Tabla4[Calidad de datos Nov/2024]),0) -> 0.94982143 | X2: =IF(ISERROR(AVERAGE(Tabla4[Uso y acceso Nov/2024])),"",AVERAGE(Tabla4[Uso y acceso Nov/2024])) -> 0.94459135 | Y2: =IF(ISERROR(AVERAGE(Tabla4[Compartición e Interoperabilidad Nov/2024])),"",AVERAGE(Tabla4[Compartición e Interoperabilidad Nov/2024])) -> 0.21730769 | Z2: =IF(ISERROR(AVERAGE(U2:Y2)),"",AVERAGE(U2:Y2)) -> 0.79937706 | AA2: =IFERROR(AVERAGEIF(Tabla4[Creación y captura Dic/2024],">0",Tabla4[Creación y captura Dic/2024]),0) -> 0.97142857 | AB2: =IFERROR(AVERAGEIF(Tabla4[Almacenamiento y registro Dic/2024],">0",Tabla4[Almacenamiento y registro Dic/2024]),0) -> 0.98867925 | AC2: =IFERROR(AVERAGEIF(Tabla4[Calidad de datos Dic/2024],">0",Tabla4[Calidad de datos Dic/2024]),0) -> 0.96267857 | AD2: =IF(ISERROR(AVERAGE(Tabla4[Uso y acceso Dic/2024])),"",AVERAGE(Tabla4[Uso y acceso Dic/2024])) -> 0.95766827 | AE2: =IF(ISERROR(AVERAGE(Tabla4[Compartición e Interoperabilidad Dic/2024])),"",AVERAGE(Tabla4[Compartición e Interoperabilidad Dic/2024])) -> 0.25192308 | AF2: =IF(ISERROR(AVERAGE(AA2:AE2)),"",AVERAGE(AA2:AE2)) -> 0.82647555 | AG2: =IFERROR(AVERAGEIF(Tabla4[Creación y captura Ene/2025],">0",Tabla4[Creación y captura Ene/2025]),0) -> 0.98571429 | AH2: =IFERROR(AVERAGEIF(Tabla4[Almacenamiento y registro Ene/2025],">0",Tabla4[Almacenamiento y registro Ene/2025]),0) -> 0.98611111 | AI2: =IFERROR(AVERAGEIF(Tabla4[Calidad de datos Ene/2025],">0",Tabla4[Calidad de datos Ene/2025]),0) -> 0.97705357 | AJ2: =IF(ISERROR(AVERAGE(Tabla4[Uso y acceso Ene/2025])),"",AVERAGE(Tabla4[Uso y acceso Ene/2025])) -> 0.95766827 | AK2: =IF(ISERROR(AVERAGE(Tabla4[Compartición e Interoperabilidad Ene/2025])),"",AVERAGE(Tabla4[Compartición e Interoperabilidad Ene/2025])) -> 0.25528846 | AL2: =IF(ISERROR(AVERAGE(AG2:AK2)),"",AVERAGE(AG2:AK2)) -> 0.83236714 | AM2: =IFERROR(AVERAGEIF(Tabla4[Creación y captura Feb/2025],">0",Tabla4[Creación y captura Feb/2025]),0) -> 0.98934426 | AN2: =IFERROR(AVERAGEIF(Tabla4[Almacenamiento y registro Feb/2025],">0",Tabla4[Almacenamiento y registro Feb/2025]),0) -> 0.99344262 | AO2: =IFERROR(AVERAGEIF(Tabla4[Calidad de datos Feb/2025],">0",Tabla4[Calidad de datos Feb/2025]),0) -> 0.98616667 | AP2: =IF(ISERROR(AVERAGE(Tabla4[Uso y acceso Feb/2025])),"",AVERAGE(Tabla4[Uso y acceso Feb/2025])) -> 0.95941038 | AQ2: =IF(ISERROR(AVERAGE(Tabla4[Compartición e Interoperabilidad Feb/2025])),"",AVERAGE(Tabla4[Compartición e Interoperabilidad Feb/2025])) -> 0.29292453 | AR2: =IF(ISERROR(AVERAGE(AM2:AQ2)),"",AVERAGE(AM2:AQ2)) -> 0.84425769 | AS2: =IFERROR(AVERAGEIF(Tabla4[Creación y captura Mar/2025],">0",Tabla4[Creación y captura Mar/2025]),0) -> 0.99166667 | AT2: =IFERROR(AVERAGEIF(Tabla4[Almacenamiento y registro Mar/2025],">0",Tabla4[Almacenamiento y registro Mar/2025]),0) -> 1 | AU2: =IFERROR(AVERAGEIF(Tabla4[Calidad de datos Mar/2025],">0",Tabla4[Calidad de datos Mar/2025]),0) -> 0.98679167 | AV2: =IF(ISERROR(AVERAGE(Tabla4[Uso y acceso Mar/2025])),"",AVERAGE(Tabla4[Uso y acceso Mar/2025])) -> 0.95941038 | AW2: =IF(ISERROR(AVERAGE(Tabla4[Compartición e Interoperabilidad Mar/2025])),"",AVERAGE(Tabla4[Compartición e Interoperabilidad Mar/2025])) -> 0.29292453 | AX2: =IF(ISERROR(AVERAGE(AS2:AW2)),"",AVERAGE(AS2:AW2)) -> 0.84615865 | AY2: =IFERROR(AVERAGEIF(Tabla4[Creación y captura Abr/2025],">0",Tabla4[Creación y captura Abr/2025]),0) -> 0.9575 | AZ2: =IFERROR(AVERAGEIF(Tabla4[Almacenamiento y registro Abr/2025],">0",Tabla4[Almacenamiento y registro Abr/2025]),0) -> 0.9025 | BA2: =IFERROR(AVERAGEIF(Tabla4[Calidad de datos Abr/2025],">0",Tabla4[Calidad de datos Abr/2025]),0) -> 0.93965625 | BB2: =IF(ISERROR(AVERAGE(Tabla4[Uso y acceso Abr/2025])),"",AVERAGE(Tabla4[Uso y acceso Abr/2025])) -> 0.96052752 | BC2: =IF(ISERROR(AVERAGE(Tabla4[Compartición e Interoperabilidad Abr/2025])),"",AVERAGE(Tabla4[Compartición e Interoperabilidad Abr/2025])) -> 0.32981651 | BD2: =IF(ISERROR(AVERAGE(AY2:BC2)),"",AVERAGE(AY2:BC2)) -> 0.81800006 | BE2: =IFERROR(AVERAGEIF(Tabla4[Creación y captura May/2025],">0",Tabla4[Creación y captura May/2025]),0) -> 0.927 | BF2: =IFERROR(AVERAGEIF(Tabla4[Almacenamiento y registro May/2025],">0",Tabla4[Almacenamiento y registro May/2025]),0) -> 0.837 | BG2: =IFERROR(AVERAGEIF(Tabla4[Calidad de datos May/2025],">0",Tabla4[Calidad de datos May/2025]),0) -> 0.99675 | BH2: =IF(ISERROR(AVERAGE(Tabla4[Uso y acceso May/2025])),"",AVERAGE(Tabla4[Uso y acceso May/2025])) -> 0.97845291 | BI2: =IF(ISERROR(AVERAGE(Tabla4[Compartición e Interoperabilidad May/2025])),"",AVERAGE(Tabla4[Compartición e Interoperabilidad May/2025])) -> 0.34394619 | BJ2: =IF(ISERROR(AVERAGE(BE2:BI2)),"",AVERAGE(BE2:BI2)) -> 0.81662982 | BK2: =IFERROR(AVERAGEIF(Tabla4[Creación y captura Jun/2025],">0",Tabla4[Creación y captura Jun/2025]),0) -> 0.91553398 | BL2: =IFERROR(AVERAGEIF(Tabla4[Almacenamiento y registro Jun/2025],">0",Tabla4[Almacenamiento y registro Jun/2025]),0) -> 0.83009709 | BM2: =IFERROR(AVERAGEIF(Tabla4[Calidad de datos Jun/2025],">0",Tabla4[Calidad de datos Jun/2025]),0) -> 0.997375 | BN2: =IF(ISERROR(AVERAGE(Tabla4[Uso y acceso Jun/2025])),"",AVERAGE(Tabla4[Uso y acceso Jun/2025])) -> 0.97847534 | BO2: =IF(ISERROR(AVERAGE(Tabla4[Compartición e Interoperabilidad Jun/2025])),"",AVERAGE(Tabla4[Compartición e Interoperabilidad Jun/2025])) -> 0.35560538 | BP2: =IF(ISERROR(AVERAGE(BK2:BO2)),"",AVERAGE(BK2:BO2)) -> 0.81541736 | BQ2: =IFERROR(AVERAGEIF(Tabla4[Creación y captura Sep/2025],">0",Tabla4[Creación y captura Sep/2025]),0) -> 0.8968254 | BR2: =IFERROR(AVERAGEIF(Tabla4[Almacenamiento y registro Sep/2025],">0",Tabla4[Almacenamiento y registro Sep/2025]),0) -> 0.78015873 | BS2: =IFERROR(AVERAGEIF(Tabla4[Calidad de datos Sep/2025],">0",Tabla4[Calidad de datos Sep/2025]),0) -> 1 | BT2: =IF(ISERROR(AVERAGE(Tabla4[Uso y acceso Sep/2025])),"",AVERAGE(Tabla4[Uso y acceso Sep/2025])) -> 0.97847534 | BU2: =IF(ISERROR(AVERAGE(Tabla4[Compartición e Interoperabilidad Sep/2025])),"",AVERAGE(Tabla4[Compartición e Interoperabilidad Sep/2025])) -> 0.3632287 | BV2: =IF(ISERROR(AVERAGE(BQ2:BU2)),"",AVERAGE(BQ2:BU2)) -> 0.80373763 | BW2: =IFERROR(AVERAGEIF(Tabla4[Creación y captura Dic/2025],">0",Tabla4[Creación y captura Dic/2025]),0) -> 0.95766423 | BX2: =IFERROR(AVERAGEIF(Tabla4[Almacenamiento y registro Dic/2025],">0",Tabla4[Almacenamiento y registro Dic/2025]),0) -> 0.90510949 | BY2: =IFERROR(AVERAGEIF(Tabla4[Calidad de datos Dic/2025],">0",Tabla4[Calidad de datos Dic/2025]),0) -> 0.91163813 | BZ2: =IF(ISERROR(AVERAGE(Tabla4[Uso y acceso Dic/2025])),"",AVERAGE(Tabla4[Uso y acceso Dic/2025])) -> 0.98779412 | CA2: =IF(ISERROR(AVERAGE(Tabla4[Compartición e Interoperabilidad Dic/2025])),"",AVERAGE(Tabla4[Compartición e Interoperabilidad Dic/2025])) -> 0.80042017 | CB2: =IF(ISERROR(AVERAGE(BW2:CA2)),"",AVERAGE(BW2:CA2)) -> 0.91252523 | CC2: =IFERROR(AVERAGEIF(Tabla4[Creación y captura Mar/2026],">0",Tabla4[Creación y captura Mar/2026]),0) -> 0.81344538 | CD2: =IFERROR(AVERAGEIF(Tabla4[Almacenamiento y registro Mar/2026],">0",Tabla4[Almacenamiento y registro Mar/2026]),0) -> 0.76596639 | CE2: =IFERROR(AVERAGEIF(Tabla4[Calidad de datos Mar/2026],">0",Tabla4[Calidad de datos Mar/2026]),0) -> 0.95252101 | CF2: =IF(ISERROR(AVERAGE(Tabla4[Uso y acceso Mar/2026])),"",AVERAGE(Tabla4[Uso y acceso Mar/2026])) -> 0.98403361 | CG2: =IF(ISERROR(AVERAGE(Tabla4[Compartición e Interoperabilidad Mar/2026])),"",AVERAGE(Tabla4[Compartición e Interoperabilidad Mar/2026])) -> 0.79957983 | CH2: =IF(ISERROR(AVERAGE(CC2:CG2)),"",AVERAGE(CC2:CG2)) -> 0.86310924
B3: Entidades | C3: Creación y captura Ago/2024 | D3: Almacenamiento y registro Ago/2024 | E3: Calidad de datos Ago/2024 | F3: Uso y acceso Ago/2024 | G3: Compartición e Interoperabilidad Ago/2024 | H3: Gestión ciclo de Vida Ago/2024 | I3: Creación y captura Sep/2024 | J3: Almacenamiento y registro Sep/2024 | K3: Calidad de datos Sep/2024 | L3: Uso y acceso Sep/2024 | M3: Compartición e Interoperabilidad Sep/2024 | N3: Gestión ciclo de Vida Sep/2024 | O3: Creación y captura Oct/2024 | P3: Almacenamiento y registro Oct/2024 | Q3: Calidad de datos Oct/2024 | R3: Uso y acceso Oct/2024 | S3: Compartición e Interoperabilidad Oct/2024 | T3: Gestión ciclo de Vida Oct/2024 | U3: Creación y captura Nov/2024 | V3: Almacenamiento y registro Nov/2024 | W3: Calidad de datos Nov/2024 | X3: Uso y acceso Nov/2024 | Y3: Compartición e Interoperabilidad Nov/2024 | Z3: Gestión ciclo de Vida Nov/2024 | AA3: Creación y captura Dic/2024 | AB3: Almacenamiento y registro Dic/2024 | AC3: Calidad de datos Dic/2024 | AD3: Uso y acceso Dic/2024 | AE3: Compartición e Interoperabilidad Dic/2024 | AF3: Gestión ciclo de Vida Dic/2024 | AG3: Creación y captura Ene/2025 | AH3: Almacenamiento y registro Ene/2025 | AI3: Calidad de datos Ene/2025 | AJ3: Uso y acceso Ene/2025 | AK3: Compartición e Interoperabilidad Ene/2025 | AL3: Gestión ciclo de Vida Ene/2025 | AM3: Creación y captura Feb/2025 | AN3: Almacenamiento y registro Feb/2025 | AO3: Calidad de datos Feb/2025 | AP3: Uso y acceso Feb/2025 | AQ3: Compartición e Interoperabilidad Feb/2025 | AR3: Gestión ciclo de Vida Feb/2025 | AS3: Creación y captura Mar/2025 | AT3: Almacenamiento y registro Mar/2025 | AU3: Calidad de datos Mar/2025 | AV3: Uso y acceso Mar/2025 | AW3: Compartición e Interoperabilidad Mar/2025 | AX3: Gestión ciclo de Vida Mar/2025 | AY3: Creación y captura Abr/2025 | AZ3: Almacenamiento y registro Abr/2025 | BA3: Calidad de datos Abr/2025 | BB3: Uso y acceso Abr/2025 | BC3: Compartición e Interoperabilidad Abr/2025 | BD3: Gestión ciclo de Vida Abr/2025 | BE3: Creación y captura May/2025 | BF3: Almacenamiento y registro May/2025 | BG3: Calidad de datos May/2025 | BH3: Uso y acceso May/2025 | BI3: Compartición e Interoperabilidad May/2025 | BJ3: Gestión ciclo de Vida May/2025 | BK3: Creación y captura Jun/2025 | BL3: Almacenamiento y registro Jun/2025 | BM3: Calidad de datos Jun/2025 | BN3: Uso y acceso Jun/2025 | BO3: Compartición e Interoperabilidad Jun/2025 | BP3: Gestión ciclo de Vida Jun/2025 | BQ3: Creación y captura Sep/2025 | BR3: Almacenamiento y registro Sep/2025 | BS3: Calidad de datos Sep/2025 | BT3: Uso y acceso Sep/2025 | BU3: Compartición e Interoperabilidad Sep/2025 | BV3: Gestión ciclo de Vida Sep/2025 | BW3: Creación y captura Dic/2025 | BX3: Almacenamiento y registro Dic/2025 | BY3: Calidad de datos Dic/2025 | BZ3: Uso y acceso Dic/2025 | CA3: Compartición e Interoperabilidad Dic/2025 | CB3: Gestión ciclo de Vida Dic/2025 | CC3: Creación y captura Mar/2026 | CD3: Almacenamiento y registro Mar/2026 | CE3: Calidad de datos Mar/2026 | CF3: Uso y acceso Mar/2026 | CG3: Compartición e Interoperabilidad Mar/2026 | CH3: Gestión ciclo de Vida Mar/2026
B4: Oportunidades | C4: 1 | D4: 1 | E4: =IF(ISERROR(AVERAGE('Calidad de Datos'!C8:F8)),"",AVERAGE('Calidad de Datos'!C8:F8)) -> 0.735 | F4: =IF(Tabla13[[#This Row],[Uso y acceso Ago/2024]]="","",Tabla13[[#This Row],[Uso y acceso Ago/2024]]) -> 1 | G4: =IF(Tabla58[[#This Row],[Integración Ago/2024]]="","",Tabla58[[#This Row],[Integración Ago/2024]]) -> 1 | H4: =IF(ISERROR(AVERAGE(Tabla4[[#This Row],[Creación y captura Ago/2024]:[Compartición e Interoperabilidad Ago/2024]])),"",AVERAGE(Tabla4[[#This Row],[Creación y captura Ago/2024]:[Compartición e Interoperabilidad Ago/2024]])) -> 0.947 | I4: 1 | J4: 1 | K4: =IF(ISERROR(AVERAGE('Calidad de Datos'!G8:J8)),"",AVERAGE('Calidad de Datos'!G8:J8)) -> 0.7875 | L4: =IF(Tabla13[[#This Row],[Uso y acceso Sep/2024]]="","",Tabla13[[#This Row],[Uso y acceso Sep/2024]]) -> 1 | M4: =IF(Tabla58[[#This Row],[Integración Sep/2024]]="","",Tabla58[[#This Row],[Integración Sep/2024]]) -> 1 | N4: =IF(ISERROR(AVERAGE(Tabla4[[#This Row],[Creación y captura Sep/2024]:[Compartición e Interoperabilidad Sep/2024]])),"",AVERAGE(Tabla4[[#This Row],[Creación y captura Sep/2024]:[Compartición e Interoperabilidad Sep/2024]])) -> 0.9575 | O4: 1 | P4: 1 | Q4: =IF(ISERROR(AVERAGE('Calidad de Datos'!K8:N8)),"",AVERAGE('Calidad de Datos'!K8:N8)) -> 0.7825 | R4: =IF(Tabla13[[#This Row],[Uso y acceso Oct/2024]]="","",Tabla13[[#This Row],[Uso y acceso Oct/2024]]) -> 1 | S4: =IF(Tabla58[[#This Row],[Integración Oct/2024]]="","",Tabla58[[#This Row],[Integración Oct/2024]]) -> 1 | T4: =IF(ISERROR(AVERAGE(Tabla4[[#This Row],[Creación y captura Oct/2024]:[Compartición e Interoperabilidad Oct/2024]])),"",AVERAGE(Tabla4[[#This Row],[Creación y captura Oct/2024]:[Compartición e Interoperabilidad Oct/2024]])) -> 0.9565 | U4: 1 | V4: 1 | W4: =IF(ISERROR(AVERAGE('Calidad de Datos'!O8:R8)),"",AVERAGE('Calidad de Datos'!O8:R8)) -> 0.875 | X4: =IF(Tabla13[[#This Row],[Uso y acceso Nov/2024]]="","",Tabla13[[#This Row],[Uso y acceso Nov/2024]]) -> 1 | Y4: =IF(Tabla58[[#This Row],[Integración Nov/2024]]="","",Tabla58[[#This Row],[Integración Nov/2024]]) -> 1 | Z4: =IF(ISERROR(AVERAGE(Tabla4[[#This Row],[Creación y captura Nov/2024]:[Compartición e Interoperabilidad Nov/2024]])),"",AVERAGE(Tabla4[[#This Row],[Creación y captura Nov/2024]:[Compartición e Interoperabilidad Nov/2024]])) -> 0.975 | AA4: 1 | AB4: 1 | AC4: =IF(ISERROR(AVERAGE('Calidad de Datos'!S8:V8)),"",AVERAGE('Calidad de Datos'!S8:V8)) -> 0.91125 | AD4: =IF(Tabla13[[#This Row],[Uso y acceso Dic/2024]]="","",Tabla13[[#This Row],[Uso y acceso Dic/2024]]) -> 1 | AE4: =IF(Tabla58[[#This Row],[Integración Dic/2024]]="","",Tabla58[[#This Row],[Integración Dic/2024]]) -> 1 | AF4: =IF(ISERROR(AVERAGE(Tabla4[[#This Row],[Creación y captura Dic/2024]:[Compartición e Interoperabilidad Dic/2024]])),"",AVERAGE(Tabla4[[#This Row],[Creación y captura Dic/2024]:[Compartición e Interoperabilidad Dic/2024]])) -> 0.98225 | AG4: 1 | AH4: 1 | AI4: =IF(ISERROR(AVERAGE('Calidad de Datos'!W8:Z8)),"",AVERAGE('Calidad de Datos'!W8:Z8)) -> 0.925 | AJ4: =IF(Tabla13[[#This Row],[Uso y acceso Ene/2025]]="","",Tabla13[[#This Row],[Uso y acceso Ene/2025]]) -> 1 | AK4: =IF(Tabla58[[#This Row],[Integración Ene/2025]]="","",Tabla58[[#This Row],[Integración Ene/2025]]) -> 1 | AL4: =IF(ISERROR(AVERAGE(Tabla4[[#This Row],[Creación y captura Ene/2025]:[Compartición e Interoperabilidad Ene/2025]])),"",AVERAGE(Tabla4[[#This Row],[Creación y captura Ene/2025]:[Compartición e Interoperabilidad Ene/2025]])) -> 0.985 | AM4: 1 | AN4: 1 | AO4: =IF(ISERROR(AVERAGE('Calidad de Datos'!AA8:AD8)),"",AVERAGE('Calidad de Datos'!AA8:AD8)) -> 0.925 | AP4: =IF(Tabla13[[#This Row],[Uso y acceso Feb/2025]]="","",Tabla13[[#This Row],[Uso y acceso Feb/2025]]) -> 1 | AQ4: =IF(Tabla58[[#This Row],[Integración Feb/2025]]="","",Tabla58[[#This Row],[Integración Feb/2025]]) -> 1 | AR4: =IF(ISERROR(AVERAGE(Tabla4[[#This Row],[Creación y captura Feb/2025]:[Compartición e Interoperabilidad Feb/2025]])),"",AVERAGE(Tabla4[[#This Row],[Creación y captura Feb/2025]:[Compartición e Interoperabilidad Feb/2025]])) -> 0.985 | AS4: 1 | AT4: 1 | AU4: =IF(ISERROR(AVERAGE('Calidad de Datos'!AE8:AH8)),"",AVERAGE('Calidad de Datos'!AE8:AH8)) -> 0.925 | AV4: =IF(Tabla13[[#This Row],[Uso y acceso Mar/2025]]="","",Tabla13[[#This Row],[Uso y acceso Mar/2025]]) -> 1 | AW4: =IF(Tabla58[[#This Row],[Integración Mar/2025]]="","",Tabla58[[#This Row],[Integración Mar/2025]]) -> 1 | AX4: =IF(ISERROR(AVERAGE(Tabla4[[#This Row],[Creación y captura Mar/2025]:[Compartición e Interoperabilidad Mar/2025]])),"",AVERAGE(Tabla4[[#This Row],[Creación y captura Mar/2025]:[Compartición e Interoperabilidad Mar/2025]])) -> 0.985 | AY4: 1 | AZ4: 1 | BA4: =IF(ISERROR(AVERAGE('Calidad de Datos'!AI8:AL8)),"",AVERAGE('Calidad de Datos'!AI8:AL8)) -> 0.925 | BB4: =IF(Tabla13[[#This Row],[Uso y acceso Abr/2025]]="","",Tabla13[[#This Row],[Uso y acceso Abr/2025]]) -> 1 | BC4: =IF(Tabla58[[#This Row],[Integración Abr/2025]]="","",Tabla58[[#This Row],[Integración Abr/2025]]) -> 1 | BD4: =IF(ISERROR(AVERAGE(Tabla4[[#This Row],[Creación y captura Abr/2025]:[Compartición e Interoperabilidad Abr/2025]])),"",AVERAGE(Tabla4[[#This Row],[Creación y captura Abr/2025]:[Compartición e Interoperabilidad Abr/2025]])) -> 0.985 | BE4: 1 | BF4: 1 | BG4: =IF(ISERROR(AVERAGE('Calidad de Datos'!AM8:AP8)),"",AVERAGE('Calidad de Datos'!AM8:AP8)) -> 0.95 | BH4: =IF(Tabla13[[#This Row],[Uso y acceso May/2025]]="","",Tabla13[[#This Row],[Uso y acceso May/2025]]) -> 1 | BI4: =IF(Tabla58[[#This Row],[Integración May/2025]]="","",Tabla58[[#This Row],[Integración May/2025]]) -> 1 | BJ4: =IF(ISERROR(AVERAGE(Tabla4[[#This Row],[Creación y captura May/2025]:[Compartición e Interoperabilidad May/2025]])),"",AVERAGE(Tabla4[[#This Row],[Creación y captura May/2025]:[Compartición e Interoperabilidad May/2025]])) -> 0.99 | BK4: 1 | BL4: 1 | BM4: =IF(ISERROR(AVERAGE('Calidad de Datos'!AQ8:AT8)),"",AVERAGE('Calidad de Datos'!AQ8:AT8)) -> 0.9625 | BN4: =IF(Tabla13[[#This Row],[Uso y acceso Jun/2025]]="","",Tabla13[[#This Row],[Uso y acceso Jun/2025]]) -> 1 | BO4: =IF(Tabla58[[#This Row],[Integración Jun/2025]]="","",Tabla58[[#This Row],[Integración Jun/2025]]) -> 1 | BP4: =IF(ISERROR(AVERAGE(Tabla4[[#This Row],[Creación y captura Jun/2025]:[Compartición e Interoperabilidad Jun/2025]])),"",AVERAGE(Tabla4[[#This Row],[Creación y captura Jun/2025]:[Compartición e Interoperabilidad Jun/2025]])) -> 0.9925 | BQ4: 1 | BR4: 1 | BS4: =IF(ISERROR(AVERAGE('Calidad de Datos'!AU8:AX8)),"",AVERAGE('Calidad de Datos'!AU8:AX8)) -> 1 | BT4: =IF(Tabla13[[#This Row],[Uso y acceso Sep/2025]]="","",Tabla13[[#This Row],[Uso y acceso Sep/2025]]) -> 1 | BU4: =IF(Tabla58[[#This Row],[Integración Sep/2025]]="","",Tabla58[[#This Row],[Integración Sep/2025]]) -> 1 | BV4: =IF(ISERROR(AVERAGE(Tabla4[[#This Row],[Creación y captura Sep/2025]:[Compartición e Interoperabilidad Sep/2025]])),"",AVERAGE(Tabla4[[#This Row],[Creación y captura Sep/2025]:[Compartición e Interoperabilidad Sep/2025]])) -> 1 | BW4: 1 | BX4: 1 | BY4: =IF(ISERROR(AVERAGE('Calidad de Datos'!AY8:BB8)),"",AVERAGE('Calidad de Datos'!AY8:BB8)) -> 0.881375 | BZ4: =IF(ISERROR(Tabla13[[#This Row],[Uso y acceso Dic/2025]]),"",Tabla13[[#This Row],[Uso y acceso Dic/2025]]) -> 1 | CA4: =IF(ISERROR(Tabla58[[#This Row],[Integración Dic/2025]]),"",Tabla58[[#This Row],[Integración Dic/2025]]) -> 1 | CB4: =IF(ISERROR(AVERAGE(Tabla4[[#This Row],[Creación y captura Dic/2025]:[Compartición e Interoperabilidad Dic/2025]])),"",AVERAGE(Tabla4[[#This Row],[Creación y captura Dic/2025]:[Compartición e Interoperabilidad Dic/2025]])) -> 0.976275 | CC4: 1 | CD4: 1 | CE4: =IF(ISERROR(AVERAGE('Calidad de Datos'!BC8:BF8)),"",AVERAGE('Calidad de Datos'!BC8:BF8)) -> 0.9625 | CF4: =IF(ISERROR(Tabla13[[#This Row],[Uso y acceso Mar/2026]]),"",Tabla13[[#This Row],[Uso y acceso Mar/2026]]) -> 1 | CG4: =IF(ISERROR(Tabla58[[#This Row],[Integración Mar/2026]]),"",Tabla58[[#This Row],[Integración Mar/2026]]) -> 1 | CH4: =IF(ISERROR(AVERAGE(Tabla4[[#This Row],[Creación y captura Mar/2026]:[Compartición e Interoperabilidad Mar/2026]])),"",AVERAGE(Tabla4[[#This Row],[Creación y captura Mar/2026]:[Compartición e Interoperabilidad Mar/2026]])) -> 0.9925
B5: Línea de negocios | C5: 1 | D5: 1 | E5: =IF(ISERROR(AVERAGE('Calidad de Datos'!C9:F9)),"",AVERAGE('Calidad de Datos'!C9:F9)) -> 1 | F5: =IF(Tabla13[[#This Row],[Uso y acceso Ago/2024]]="","",Tabla13[[#This Row],[Uso y acceso Ago/2024]]) -> 1 | G5: =IF(Tabla58[[#This Row],[Integración Ago/2024]]="","",Tabla58[[#This Row],[Integración Ago/2024]]) -> 1 | H5: =IF(ISERROR(AVERAGE(Tabla4[[#This Row],[Creación y captura Ago/2024]:[Compartición e Interoperabilidad Ago/2024]])),"",AVERAGE(Tabla4[[#This Row],[Creación y captura Ago/2024]:[Compartición e Interoperabilidad Ago/2024]])) -> 1 | I5: 1 | J5: 1 | K5: =IF(ISERROR(AVERAGE('Calidad de Datos'!G9:J9)),"",AVERAGE('Calidad de Datos'!G9:J9)) -> 1 | L5: =IF(Tabla13[[#This Row],[Uso y acceso Sep/2024]]="","",Tabla13[[#This Row],[Uso y acceso Sep/2024]]) -> 1 | M5: =IF(Tabla58[[#This Row],[Integración Sep/2024]]="","",Tabla58[[#This Row],[Integración Sep/2024]]) -> 1 | N5: =IF(ISERROR(AVERAGE(Tabla4[[#This Row],[Creación y captura Sep/2024]:[Compartición e Interoperabilidad Sep/2024]])),"",AVERAGE(Tabla4[[#This Row],[Creación y captura Sep/2024]:[Compartición e Interoperabilidad Sep/2024]])) -> 1 | O5: 1 | P5: 1 | Q5: =IF(ISERROR(AVERAGE('Calidad de Datos'!K9:N9)),"",AVERAGE('Calidad de Datos'!K9:N9)) -> 1 | R5: =IF(Tabla13[[#This Row],[Uso y acceso Oct/2024]]="","",Tabla13[[#This Row],[Uso y acceso Oct/2024]]) -> 1 | S5: =IF(Tabla58[[#This Row],[Integración Oct/2024]]="","",Tabla58[[#This Row],[Integración Oct/2024]]) -> 1 | T5: =IF(ISERROR(AVERAGE(Tabla4[[#This Row],[Creación y captura Oct/2024]:[Compartición e Interoperabilidad Oct/2024]])),"",AVERAGE(Tabla4[[#This Row],[Creación y captura Oct/2024]:[Compartición e Interoperabilidad Oct/2024]])) -> 1 | U5: 1 | V5: 1 | W5: =IF(ISERROR(AVERAGE('Calidad de Datos'!O9:R9)),"",AVERAGE('Calidad de Datos'!O9:R9)) -> 1 | X5: =IF(Tabla13[[#This Row],[Uso y acceso Nov/2024]]="","",Tabla13[[#This Row],[Uso y acceso Nov/2024]]) -> 1 | Y5: =IF(Tabla58[[#This Row],[Integración Nov/2024]]="","",Tabla58[[#This Row],[Integración Nov/2024]]) -> 1 | Z5: =IF(ISERROR(AVERAGE(Tabla4[[#This Row],[Creación y captura Nov/2024]:[Compartición e Interoperabilidad Nov/2024]])),"",AVERAGE(Tabla4[[#This Row],[Creación y captura Nov/2024]:[Compartición e Interoperabilidad Nov/2024]])) -> 1 | AA5: 1 | AB5: 1 | AC5: =IF(ISERROR(AVERAGE('Calidad de Datos'!S9:V9)),"",AVERAGE('Calidad de Datos'!S9:V9)) -> 1 | AD5: =IF(Tabla13[[#This Row],[Uso y acceso Dic/2024]]="","",Tabla13[[#This Row],[Uso y acceso Dic/2024]]) -> 1 | AE5: =IF(Tabla58[[#This Row],[Integración Dic/2024]]="","",Tabla58[[#This Row],[Integración Dic/2024]]) -> 1 | AF5: =IF(ISERROR(AVERAGE(Tabla4[[#This Row],[Creación y captura Dic/2024]:[Compartición e Interoperabilidad Dic/2024]])),"",AVERAGE(Tabla4[[#This Row],[Creación y captura Dic/2024]:[Compartición e Interoperabilidad Dic/2024]])) -> 1 | AG5: 1 | AH5: 1 | AI5: =IF(ISERROR(AVERAGE('Calidad de Datos'!W9:Z9)),"",AVERAGE('Calidad de Datos'!W9:Z9)) -> 1 | AJ5: =IF(Tabla13[[#This Row],[Uso y acceso Ene/2025]]="","",Tabla13[[#This Row],[Uso y acceso Ene/2025]]) -> 1 | AK5: =IF(Tabla58[[#This Row],[Integración Ene/2025]]="","",Tabla58[[#This Row],[Integración Ene/2025]]) -> 1 | AL5: =IF(ISERROR(AVERAGE(Tabla4[[#This Row],[Creación y captura Ene/2025]:[Compartición e Interoperabilidad Ene/2025]])),"",AVERAGE(Tabla4[[#This Row],[Creación y captura Ene/2025]:[Compartición e Interoperabilidad Ene/2025]])) -> 1 | AM5: 1 | AN5: 1 | AO5: =IF(ISERROR(AVERAGE('Calidad de Datos'!AA9:AD9)),"",AVERAGE('Calidad de Datos'!AA9:AD9)) -> 1 | AP5: =IF(Tabla13[[#This Row],[Uso y acceso Feb/2025]]="","",Tabla13[[#This Row],[Uso y acceso Feb/2025]]) -> 1 | AQ5: =IF(Tabla58[[#This Row],[Integración Feb/2025]]="","",Tabla58[[#This Row],[Integración Feb/2025]]) -> 1 | AR5: =IF(ISERROR(AVERAGE(Tabla4[[#This Row],[Creación y captura Feb/2025]:[Compartición e Interoperabilidad Feb/2025]])),"",AVERAGE(Tabla4[[#This Row],[Creación y captura Feb/2025]:[Compartición e Interoperabilidad Feb/2025]])) -> 1 | AS5: 1 | AT5: 1 | AU5: =IF(ISERROR(AVERAGE('Calidad de Datos'!AE9:AH9)),"",AVERAGE('Calidad de Datos'!AE9:AH9)) -> 1 | AV5: =IF(Tabla13[[#This Row],[Uso y acceso Mar/2025]]="","",Tabla13[[#This Row],[Uso y acceso Mar/2025]]) -> 1 | AW5: =IF(Tabla58[[#This Row],[Integración Mar/2025]]="","",Tabla58[[#This Row],[Integración Mar/2025]]) -> 1 | AX5: =IF(ISERROR(AVERAGE(Tabla4[[#This Row],[Creación y captura Mar/2025]:[Compartición e Interoperabilidad Mar/2025]])),"",AVERAGE(Tabla4[[#This Row],[Creación y captura Mar/2025]:[Compartición e Interoperabilidad Mar/2025]])) -> 1 | AY5: 1 | AZ5: 1 | BA5: =IF(ISERROR(AVERAGE('Calidad de Datos'!AI9:AL9)),"",AVERAGE('Calidad de Datos'!AI9:AL9)) -> 1 | BB5: =IF(Tabla13[[#This Row],[Uso y acceso Abr/2025]]="","",Tabla13[[#This Row],[Uso y acceso Abr/2025]]) -> 1 | BC5: =IF(Tabla58[[#This Row],[Integración Abr/2025]]="","",Tabla58[[#This Row],[Integración Abr/2025]]) -> 1 | BD5: =IF(ISERROR(AVERAGE(Tabla4[[#This Row],[Creación y captura Abr/2025]:[Compartición e Interoperabilidad Abr/2025]])),"",AVERAGE(Tabla4[[#This Row],[Creación y captura Abr/2025]:[Compartición e Interoperabilidad Abr/2025]])) -> 1 | BE5: 1 | BF5: 1 | BG5: =IF(ISERROR(AVERAGE('Calidad de Datos'!AM9:AP9)),"",AVERAGE('Calidad de Datos'!AM9:AP9)) -> 1 | BH5: =IF(Tabla13[[#This Row],[Uso y acceso May/2025]]="","",Tabla13[[#This Row],[Uso y acceso May/2025]]) -> 1 | BI5: =IF(Tabla58[[#This Row],[Integración May/2025]]="","",Tabla58[[#This Row],[Integración May/2025]]) -> 1 | BJ5: =IF(ISERROR(AVERAGE(Tabla4[[#This Row],[Creación y captura May/2025]:[Compartición e Interoperabilidad May/2025]])),"",AVERAGE(Tabla4[[#This Row],[Creación y captura May/2025]:[Compartición e Interoperabilidad May/2025]])) -> 1 | BK5: 1 | BL5: 1 | BM5: =IF(ISERROR(AVERAGE('Calidad de Datos'!AQ9:AT9)),"",AVERAGE('Calidad de Datos'!AQ9:AT9)) -> 1 | BN5: =IF(Tabla13[[#This Row],[Uso y acceso Jun/2025]]="","",Tabla13[[#This Row],[Uso y acceso Jun/2025]]) -> 1 | BO5: =IF(Tabla58[[#This Row],[Integración Jun/2025]]="","",Tabla58[[#This Row],[Integración Jun/2025]]) -> 1 | BP5: =IF(ISERROR(AVERAGE(Tabla4[[#This Row],[Creación y captura Jun/2025]:[Compartición e Interoperabilidad Jun/2025]])),"",AVERAGE(Tabla4[[#This Row],[Creación y captura Jun/2025]:[Compartición e Interoperabilidad Jun/2025]])) -> 1 | BQ5: 1 | BR5: 1 | BS5: =IF(ISERROR(AVERAGE('Calidad de Datos'!AU9:AX9)),"",AVERAGE('Calidad de Datos'!AU9:AX9)) -> 1 | BT5: =IF(Tabla13[[#This Row],[Uso y acceso Sep/2025]]="","",Tabla13[[#This Row],[Uso y acceso Sep/2025]]) -> 1 | BU5: =IF(Tabla58[[#This Row],[Integración Sep/2025]]="","",Tabla58[[#This Row],[Integración Sep/2025]]) -> 1 | BV5: =IF(ISERROR(AVERAGE(Tabla4[[#This Row],[Creación y captura Sep/2025]:[Compartición e Interoperabilidad Sep/2025]])),"",AVERAGE(Tabla4[[#This Row],[Creación y captura Sep/2025]:[Compartición e Interoperabilidad Sep/2025]])) -> 1 | BW5: 1 | BX5: 1 | BY5: =IF(ISERROR(AVERAGE('Calidad de Datos'!AY9:BB9)),"",AVERAGE('Calidad de Datos'!AY9:BB9)) -> 1 | BZ5: =IF(ISERROR(Tabla13[[#This Row],[Uso y acceso Dic/2025]]),"",Tabla13[[#This Row],[Uso y acceso Dic/2025]]) -> 1 | CA5: =IF(ISERROR(Tabla58[[#This Row],[Integración Dic/2025]]),"",Tabla58[[#This Row],[Integración Dic/2025]]) -> 1 | CB5: =IF(ISERROR(AVERAGE(Tabla4[[#This Row],[Creación y captura Dic/2025]:[Compartición e Interoperabilidad Dic/2025]])),"",AVERAGE(Tabla4[[#This Row],[Creación y captura Dic/2025]:[Compartición e Interoperabilidad Dic/2025]])) -> 1 | CC5: 1 | CD5: 1 | CE5: =IF(ISERROR(AVERAGE('Calidad de Datos'!BC9:BF9)),"",AVERAGE('Calidad de Datos'!BC9:BF9)) -> 1 | CF5: =IF(ISERROR(Tabla13[[#This Row],[Uso y acceso Mar/2026]]),"",Tabla13[[#This Row],[Uso y acceso Mar/2026]]) -> 1 | CG5: =IF(ISERROR(Tabla58[[#This Row],[Integración Mar/2026]]),"",Tabla58[[#This Row],[Integración Mar/2026]]) -> 1 | CH5: =IF(ISERROR(AVERAGE(Tabla4[[#This Row],[Creación y captura Mar/2026]:[Compartición e Interoperabilidad Mar/2026]])),"",AVERAGE(Tabla4[[#This Row],[Creación y captura Mar/2026]:[Compartición e Interoperabilidad Mar/2026]])) -> 1
