Workbook

Sheet Calidad de Datos
B1: Se realiza sobre las entidades Integradas | E1: Entidades con % > 0 / Cantidad total de entidades integradas
B2: COMPLETITUD: Mide el grado en que todos los atributos de la entidad se encuentran diligenciados | E2: Completitud = (número de registros completos/númerto total de registros)*100 | H2: Compeltitud por registro = (número de atributos completos / número total de atributor) * 100
B3: OPORTUNIDAD: Mide si los datos se encuentran disponibles en el momento que se necesitan | E3: % datos disponibles = porcentaje de datos que se pueden acceder en un tiempo definido | H3: Tasa de cumplimiento = mide si el sistema de datos cumple con los tiempos de entrega
B4: CONSISTENCIA: Mide la uniformidad y coherencia de los datos entre diferentes sistemas, asegurando que no haya discrepancias | E4: % de registros consistentes = % de registros que cumplen con las reglas de consistencia
B5: CONFORMIDAD: Mide que los datos se adhieran a las políticas, regulaciones y estándares establecidos | E5: Calidad de datos = % de datos que cumplen los estándares de precisión, integridad y consistencia
C6: Completitud | D6: Oportunidad | E6: Consistencia | F6: Conformidad | G6: Completitud | H6: Oportunidad | I6: Consistencia | J6: Conformidad | K6: Completitud | L6: Oportunidad | M6: Consistencia | N6: Conformidad | O6: Completitud | P6: Oportunidad | Q6: Consistencia | R6: Conformidad | S6: Completitud | T6: Oportunidad | U6: Consistencia | V6: Conformidad | W6: Completitud | X6: Oportunidad | Y6: Consistencia | Z6: Conformidad | AA6: Completitud | AB6: Oportunidad | AC6: Consistencia | AD6: Conformidad | AE6: Completitud | AF6: Oportunidad | AG6: Consistencia | AH6: Conformidad | AI6: Completitud | AJ6: Oportunidad | AK6: Consistencia | AL6: Conformidad | AM6: Completitud | AN6: Oportunidad | AO6: Consistencia | AP6: Conformidad | AQ6: Completitud | AR6: Oportunidad | AS6: Consistencia | AT6: Conformidad
C7: 1 | D7: 1 | E7: 1 | F7: 1 | G7: 2 | H7: 2 | I7: 2 | J7: 2 | K7: 3 | L7: 3 | M7: 3 | N7: 3 | O7: 4 | P7: 4 | Q7: 4 | R7: 4 | S7: 5 | T7: 5 | U7: 5 | V7: 5 | W7: 6 | X7: 6 | Y7: 6 | Z7: 6 | AA7: 7 | AB7: 7 | AC7: 7 | AD7: 7 | AE7: 8 | AF7: 8 | AG7: 8 | AH7: 8 | AI7: 9 | AJ7: 9 | AK7: 9 | AL7: 9 | AM7: 10 | AN7: 10 | AO7: 10 | AP7: 10 | AQ7: 17 | AR7: 17 | AS7: 17 | AT7: 17
C8: =SUMIF(C11:C217,">0")/COUNTIF(C11:C217,">0") -> 0.95342105 | D8: =SUMIF(D11:D217,">0")/COUNTIF(D11:D217,">0") -> 0.99710526 | E8: =SUMIF(E11:E217,">0")/COUNTIF(E11:E217,">0") -> 0.99210526 | F8: =SUMIF(F11:F217,">0")/COUNTIF(F11:F217,">0") -> 0.8 | G8: =SUMIF(G11:G217,">0")/COUNTIF(G11:G217,">0") -> 0.95342105 | H8: =SUMIF(H11:H217,">0")/COUNTIF(H11:H217,">0") -> 1 | I8: =SUMIF(I11:I217,">0")/COUNTIF(I11:I217,">0") -> 0.99210526 | J8: =SUMIF(J11:J217,">0")/COUNTIF(J11:J217,">0") -> 0.85 | ... AT8: =SUMIF(AT11:AT217,">0")/COUNTIF(AT11:AT217,">0") -> 1
C9: =IFERROR(AVERAGEIF(Tabla1[Completitud Ago/2024],">0",Tabla1[Completitud Ago/2024]),0) -> 0.95342105 | D9: =IFERROR(AVERAGEIF(Tabla1[Oportunidad Ago/2024],">0",Tabla1[Oportunidad Ago/2024]),0) -> 0.99710526 | E9: =IFERROR(AVERAGEIF(Tabla1[Consistencia Ago/2024],">0",Tabla1[Consistencia Ago/2024]),0) -> 0.99210526 | F9: =IFERROR(AVERAGEIF(Tabla1[Conformidad Ago/2024],">0",Tabla1[Conformidad Ago/2024]),0) -> 0.8 | G9: =IFERROR(AVERAGEIF(Tabla1[Completitud Sep/2024],">0",Tabla1[Completitud Sep/2024]),0) -> 0.95342105 | H9: =IFERROR(AVERAGEIF(Tabla1[Oportunidad Sep/2024],">0",Tabla1[Oportunidad Sep/2024]),0) -> 1 | I9: =IFERROR(AVERAGEIF(Tabla1[Consistencia Sep/2024],">0",Tabla1[Consistencia Sep/2024]),0) -> 0.99210526 | J9: =IFERROR(AVERAGEIF(Tabla1[Conformidad Sep/2024],">0",Tabla1[Conformidad Sep/2024]),0) -> 0.85 | K9: =IFERROR(AVERAGEIF(Tabla1[Completitud Oct/2024],">0",Tabla1[Completitud Oct/2024]),0) -> 0.95342105 | L9: =IFERROR(AVERAGEIF(Tabla1[Oportunidad Oct/2024],">0",Tabla1[Oportunidad Oct/2024]),0) -> 0.99763158 | M9: =IFERROR(AVERAGEIF(Tabla1[Consistencia Oct/2024],">0",Tabla1[Consistencia Oct/2024]),0) -> 0.99447368 | N9: =IFERROR(AVERAGEIF(Tabla1[Conformidad Oct/2024],">0",Tabla1[Conformidad Oct/2024]),0) -> 0.85 | O9: =IFERROR(AVERAGEIF(Tabla1[Completitud Nov/2024],">0",Tabla1[Completitud Nov/2024]),0) -> 0.93142857 | P9: =IFERROR(AVERAGEIF(Tabla1[Oportunidad Nov/2024],">0",Tabla1[Oportunidad Nov/2024]),0) -> 1 | Q9: =IFERROR(AVERAGEIF(Tabla1[Consistencia Nov/2024],">0",Tabla1[Consistencia Nov/2024]),0) -> 0.96785714 | R9: =IFERROR(AVERAGEIF(Tabla1[Conformidad Nov/2024],">0",Tabla1[Conformidad Nov/2024]),0) -> 0.9 | S9: =IFERROR(AVERAGEIF(Tabla1[Completitud Dic/2024],">0",Tabla1[Completitud Dic/2024]),0) -> 0.93142857 | T9: =IFERROR(AVERAGEIF(Tabla1[Oportunidad Dic/2024],">0",Tabla1[Oportunidad Dic/2024]),0) -> 0.99839286 | U9: =IFERROR(AVERAGEIF(Tabla1[Consistencia Dic/2024],">0",Tabla1[Consistencia Dic/2024]),0) -> 0.97089286 | V9: =IFERROR(AVERAGEIF(Tabla1[Conformidad Dic/2024],">0",Tabla1[Conformidad Dic/2024]),0) -> 0.95 | W9: =IFERROR(AVERAGEIF(Tabla1[Completitud Ene/2025],">0",Tabla1[Completitud Ene/2025]),0) -> 0.96035714 | X9: =IFERROR(AVERAGEIF(Tabla1[Oportunidad Ene/2025],">0",Tabla1[Oportunidad Ene/2025]),0) -> 1 | Y9: =IFERROR(AVERAGEIF(Tabla1[Consistencia Ene/2025],">0",Tabla1[Consistencia Ene/2025]),0) -> 0.97285714 | Z9: =IFERROR(AVERAGEIF(Tabla1[Conformidad Ene/2025],">0",Tabla1[Conformidad Ene/2025]),0) -> 0.975 | AA9: =IFERROR(AVERAGEIF(Tabla1[Completitud Feb/2025],">0",Tabla1[Completitud Feb/2025]),0) -> 0.96566667 | AB9: =IFERROR(AVERAGEIF(Tabla1[Oportunidad Feb/2025],">0",Tabla1[Oportunidad Feb/2025]),0) -> 1 | AC9: =IFERROR(AVERAGEIF(Tabla1[Consistencia Feb/2025],">0",Tabla1[Consistencia Feb/2025]),0) -> 0.979 | AD9: =IFERROR(AVERAGEIF(Tabla1[Conformidad Feb/2025],">0",Tabla1[Conformidad Feb/2025]),0) -> 1 | AE9: =IFERROR(AVERAGEIF(Tabla1[Completitud Mar/2025],">0",Tabla1[Completitud Mar/2025]),0) -> 0.96816667 | AF9: =IFERROR(AVERAGEIF(Tabla1[Oportunidad Mar/2025],">0",Tabla1[Oportunidad Mar/2025]),0) -> 1 | AG9: =IFERROR(AVERAGEIF(Tabla1[Consistencia Mar/2025],">0",Tabla1[Consistencia Mar/2025]),0) -> 0.979 | AH9: =IFERROR(AVERAGEIF(Tabla1[Conformidad Mar/2025],">0",Tabla1[Conformidad Mar/2025]),0) -> 1 | AI9: =IFERROR(AVERAGEIF(Tabla1[Completitud Abr/2025],">0",Tabla1[Completitud Abr/2025]),0) -> 0.976125 | AJ9: =IFERROR(AVERAGEIF(Tabla1[Oportunidad Abr/2025],">0",Tabla1[Oportunidad Abr/2025]),0) -> 0.9325 | AK9: =IFERROR(AVERAGEIF(Tabla1[Consistencia Abr/2025],">0",Tabla1[Consistencia Abr/2025]),0) -> 0.8875 | AL9: =IFERROR(AVERAGEIF(Tabla1[Conformidad Abr/2025],">0",Tabla1[Conformidad Abr/2025]),0) -> 0.9625 | AM9: =IFERROR(AVERAGEIF(Tabla1[Completitud May/2025],">0",Tabla1[Completitud May/2025]),0) -> 0.989 | AN9: =IFERROR(AVERAGEIF(Tabla1[Oportunidad May/2025],">0",Tabla1[Oportunidad May/2025]),0) -> 1 | AO9: =IFERROR(AVERAGEIF(Tabla1[Consistencia May/2025],">0",Tabla1[Consistencia May/2025]),0) -> 0.998 | AP9: =IFERROR(AVERAGEIF(Tabla1[Conformidad May/2025],">0",Tabla1[Conformidad May/2025]),0) -> 1 | AQ9: =IFERROR(AVERAGEIF(Tabla1[Completitud Dic/2025],">0",Tabla1[Completitud Dic/2025]),0) -> 0.89792857 | AR9: =IFERROR(AVERAGEIF(Tabla1[Oportunidad Dic/2025],">0",Tabla1[Oportunidad Dic/2025]),0) -> 1 | AS9: =IFERROR(AVERAGEIF(Tabla1[Consistencia Dic/2025],">0",Tabla1[Consistencia Dic/2025]),0) -> 0.88813559 | AT9: =IFERROR(AVERAGEIF(Tabla1[Conformidad Dic/2025],">0",Tabla1[Conformidad Dic/2025]),0) -> 1
B10: Entidades | C10: Completitud Ago/2024 | D10: Oportunidad Ago/2024 | E10: Consistencia Ago/2024 | F10: Conformidad Ago/2024 | G10: Completitud Sep/2024 | H10: Oportunidad Sep/2024 | I10: Consistencia Sep/2024 | J10: Conformidad Sep/2024 | K10: Completitud Oct/2024 | L10: Oportunidad Oct/2024 | M10: Consistencia Oct/2024 | N10: Conformidad Oct/2024 | O10: Completitud Nov/2024 | P10: Oportunidad Nov/2024 | Q10: Consistencia Nov/2024 | R10: Conformidad Nov/2024 | S10: Completitud Dic/2024 | T10: Oportunidad Dic/2024 | U10: Consistencia Dic/2024 | V10: Conformidad Dic/2024 | W10: Completitud Ene/2025 | X10: Oportunidad Ene/2025 | Y10: Consistencia Ene/2025 | Z10: Conformidad Ene/2025 | AA10: Completitud Feb/2025 | AB10: Oportunidad Feb/2025 | AC10: Consistencia Feb/2025 | AD10: Conformidad Feb/2025 | AE10: Completitud Mar/2025 | AF10: Oportunidad Mar/2025 | AG10: Consistencia Mar/2025 | AH10: Conformidad Mar/2025 | AI10: Completitud Abr/2025 | AJ10: Oportunidad Abr/2025 | AK10: Consistencia Abr/2025 | AL10: Conformidad Abr/2025 | AM10: Completitud May/2025 | AN10: Oportunidad May/2025 | AO10: Consistencia May/2025 | AP10: Conformidad May/2025 | AQ10: Completitud Dic/2025 | AR10: Oportunidad Dic/2025 | AS10: Consistencia Dic/2025 | AT10: Conformidad Dic/2025
B11: Oportunidades | C11: 0.7 | D11: 0.94 | E11: 0.9 | F11: 0.4 | G11: 0.7 | H11: 1 | I11: 0.9 | J11: 0.55 | K11: 0.7 | L11: 0.95 | M11: 0.93 | N11: 0.55 | O11: 0.7 | P11: 1 | Q11: 0.95 | R11: 0.85 | S11: 0.7 | T11: 0.95 | U11: 0.995 | V11: 1 | W11: 0.7 | X11: 1 | Y11: 1 | Z11: 1 | AA11: 0.7 | AB11: 1 | AC11: 1 | AD11: 1 | AE11: 0.7 | AF11: 1 | AG11: 1 | AH11: 1 | AI11: 0.7 | AJ11: 1 | AK11: 1 | AL11: 1 | AM11: 0.8 | AN11: 1 | AO11: 1 | AP11: 1 | AQ11: 0.5255 | AR11: 1 | AS11: 1 | AT11: 1
B12: Línea de negocios | C12: 1 | D12: 1 | E12: 1 | F12: 1 | G12: 1 | H12: 1 | I12: 1 | J12: 1 | K12: 1 | L12: 1 | M12: 1 | N12: 1 | O12: 1 | P12: 1 | Q12: 1 | R12: 1 | S12: 1 | T12: 1 | U12: 1 | V12: 1 | W12: 1 | X12: 1 | Y12: 1 | Z12: 1 | AA12: 1 | AB12: 1 | AC12: 1 | AD12: 1 | AE12: 1 | AF12: 1 | AG12: 1 | AH12: 1 | AI12: 1 | AJ12: 1 | AK12: 1 | AL12: 1 | AM12: 1 | AN12: 1 | AO12: 1 | AP12: 1 | AQ12: 1 | AR12: 1 | AS12: 1 | AT12: 1
B13: Equipo de ventas | C13: 1 | D13: 1 | E13: 1 | F13: 1 | G13: 1 | H13: 1 | I13: 1 | J13: 1 | K13: 1 | L13: 1 | M13: 1 | N13: 1 | O13: 1 | P13: 1 | Q13: 1 | R13: 1 | S13: 1 | T13: 1 | U13: 1 | V13: 1 | W13: 1 | X13: 1 | Y13: 1 | Z13: 1 | AA13: 1 | AB13: 1 | AC13: 1 | AD13: 1 | AE13: 1 | AF13: 1 | AG13: 1 | AH13: 1 | AI13: 1 | AJ13: 1 | AK13: 1 | AL13: 1 | AM13: 1 | AN13: 1 | AO13: 1 | AP13: 1 | AQ13: 1 | AR13: 1 | AS13: 1 | AT13: 1
B14: Tipo de cliente | C14: 1 | D14: 1 | E14: 1 | F14: 1 | G14: 1 | H14: 1 | I14: 1 | J14: 1 | K14: 1 | L14: 1 | M14: 1 | N14: 1 | O14: 1 | P14: 1 | Q14: 1 | R14: 1 | S14: 1 | T14: 1 | U14: 1 | V14: 1 | W14: 1 | X14: 1 | Y14: 1 | Z14: 1 | AA14: 1 | AB14: 1 | AC14: 1 | AD14: 1 | AE14: 1 | AF14: 1 | AG14: 1 | AH14: 1 | AI14: 1 | AJ14: 1 | AK14: 1 | AL14: 1 | AM14: 1 | AN14: 1 | AO14: 1 | AP14: 1 | AQ14: 1 | AR14: 1 | AS14: 1 | AT14: 1
B15: Cliente | C15: 0.3 | D15: 1 | E15: 0.9 | F15: 0.3 | G15: 0.3 | H15: 1 | I15: 0.9 | J15: 0.3 | K15: 0.3 | L15: 1 | M15: 0.93 | N15: 0.3 | O15: 0.3 | P15: 1 | Q15: 0.95 | R15: 0.8 | S15: 0.3 | T15: 1 | U15: 0.995 | V15: 1 | W15: 0.3 | X15: 1 | Y15: 1 | Z15: 1 | AA15: 0.3 | AB15: 1 | AC15: 1 | AD15: 1 | AE15: 0.3 | AF15: 1 | AG15: 1 | AH15: 1 | AI15: 0.3 | AJ15: 1 | AK15: 1 | AL15: 1 | AM15: 0.3 | AN15: 1 | AO15: 1 | AP15: 1 | AQ15: 0.354 | AR15: 1 | AS15: 1 | AT15: 1
B16: Tipo de venta | C16: 1 | D16: 1 | E16: 1 | F16: 1 | G16: 1 | H16: 1 | I16: 1 | J16: 1 | K16: 1 | L16: 1 | M16: 1 | N16: 1 | O16: 1 | P16: 1 | Q16: 1 | R16: 1 | S16: 1 | T16: 1 | U16: 1 | V16: 1 | W16: 1 | X16: 1 | Y16: 1 | Z16: 1 | AA16: 1 | AB16: 1 | AC16: 1 | AD16: 1 | AE16: 1 | AF16: 1 | AG16: 1 | AH16: 1 | AI16: 1 | AJ16: 1 | AK16: 1 | AL16: 1 | AM16: 1 | AN16: 1 | AO16: 1 | AP16: 1 | AQ16: 1 | AR16: 1 | AS16: 1 | AT16: 1
B17: Tipo de oportunidad | C17: 1 | D17: 1 | E17: 1 | F17: 1 | G17: 1 | H17: 1 | I17: 1 | J17: 1 | K17: 1 | L17: 1 | M17: 1 | N17: 1 | O17: 1 | P17: 1 | Q17: 1 | R17: 1 | S17: 1 | T17: 1 | U17: 1 | V17: 1 | W17: 1 | X17: 1 | Y17: 1 | Z17: 1 | AA17: 1 | AB17: 1 | AC17: 1 | AD17: 1 | AE17: 1 | AF17: 1 | AG17: 1 | AH17: 1 | AI17: 1 | AJ17: 1 | AK17: 1 | AL17: 1 | AM17: 1 | AN17: 1 | AO17: 1 | AP17: 1 | AQ17: 1 | AR17: 1 | AS17: 1 | AT17: 1
B18: Etapa actual | C18: 1 | D18: 1 | E18: 1 | F18: 1 | G18: 1 | H18: 1 | I18: 1 | J18: 1 | K18: 1 | L18: 1 | M18: 1 | N18: 1 | O18: 1 | P18: 1 | Q18: 1 | R18: 1 | S18: 1 | T18: 1 | U18: 1 | V18: 1 | W18: 1 | X18: 1 | Y18: 1 | Z18: 1 | AA18: 1 | AB18: 1 | AC18: 1 | AD18: 1 | AE18: 1 | AF18: 1 | AG18: 1 | AH18: 1 | AI18: 1 | AJ18: 1 | AK18: 1 | AL18: 1 | AM18: 1 | AN18: 1 | AO18: 1 | AP18: 1 | AQ18: 1 | AR18: 1 | AS18: 1 | AT18: 1
B19: Ganado | C19: 1 | D19: 1 | E19: 1 | F19: 1 | G19: 1 | H19: 1 | I19: 1 | J19: 1 | K19: 1 | L19: 1 | M19: 1 | N19: 1 | O19: 1 | P19: 1 | Q19: 1 | R19: 1 | S19: 1 | T19: 1 | U19: 1 | V19: 1 | W19: 1 | X19: 1 | Y19: 1 | Z19: 1 | AA19: 1 | AB19: 1 | AC19: 1 | AD19: 1 | AE19: 1 | AF19: 1 | AG19: 1 | AH19: 1 | AI19: 1 | AJ19: 1 | AK19: 1 | AL19: 1 | AM19: 1 | AN19: 1 | AO19: 1 | AP19: 1 | AQ19: 1 | AR19: 1 | AS19: 1 | AT19: 1
B20: Metas | C20: 1 | D20: 1 | E20: 1 | F20: 1 | G20: 1 | H20: 1 | I20: 1 | J20: 1 | K20: 1 | L20: 1 | M20: 1 | N20: 1 | O20: 1 | P20: 1 | Q20: 1 | R20: 1 | S20: 1 | T20: 1 | U20: 1 | V20: 1 | W20: 1 | X20: 1 | Y20: 1 | Z20: 1 | AA20: 1 | AB20: 1 | AC20: 1 | AD20: 1 | AE20: 1 | AF20: 1 | AG20: 1 | AH20: 1 | AI20: 1 | AJ20: 1 | AK20: 1 | AL20: 1 | AM20: 1 | AN20: 1 | AO20: 1 | AP20: 1 | AQ20: 1 | AR20: 1 | AS20: 1 | AT20: 1
B21: Metas de Comercial | C21: 1 | D21: 1 | E21: 1 | F21: 1 | G21: 1 | H21: 1 | I21: 1 | J21: 1 | K21: 1 | L21: 1 | M21: 1 | N21: 1 | O21: 1 | P21: 1 | Q21: 1 | R21: 1 | S21: 1 | T21: 1 | U21: 1 | V21: 1 | W21: 1 | X21: 1 | Y21: 1 | Z21: 1 | AA21: 1 | AB21: 1 | AC21: 1 | AD21: 1 | AE21: 1 | AF21: 1 | AG21: 1 | AH21: 1 | AI21: 1 | AJ21: 1 | AK21: 1 | AL21: 1 | AM21: 1 | AN21: 1 | AO21: 1 | AP21: 1 | AQ21: 1 | AR21: 1 | AS21: 1 | AT21: 1
B22: Área | C22: 1 | D22: 1 | E22: 1 | F22: 1 | G22: 1 | H22: 1 | I22: 1 | J22: 1 | K22: 1 | L22: 1 | M22: 1 | N22: 1 | O22: 1 | P22: 1 | Q22: 1 | R22: 1 | S22: 1 | T22: 1 | U22: 1 | V22: 1 | W22: 1 | X22: 1 | Y22: 1 | Z22: 1 | AA22: 1 | AB22: 1 | AC22: 1 | AD22: 1 | AE22: 1 | AF22: 1 | AG22: 1 | AH22: 1 | AI22: 1 | AJ22: 1 | AK22: 1 | AL22: 1 | AM22: 1 | AN22: 1 | AO22: 1 | AP22: 1 | AQ22: 1 | AR22: 1 | AS22: 1 | AT22: 1
... B61: Plan de capacitaciones | C61: 0 | D61: 0 | E61: 0 | F61: 0 | G61: 0 | H61: 0 | I61: 0 | J61: 0 | K61: 0 | L61: 0 | M61: 0 | N61: 0 | O61: 0.72 | P61: 1 | Q61: 0.8 | R61: 0.5 | S61: 0.72 | T61: 1 | U61: 0.8 | V61: 0.7 | W61: 0.9 | X61: 1 | Y61: 0.9 | Z61: 0.9 | AA61: 0.95 | AB61: 1 | AC61: 0.9 | AD61: 1 | AE61: 1 | AF61: 1 | AG61: 0.9 | AH61: 1 | AI61: 1 | AJ61: 1 | AK61: 1 | AL61: 1 | AM61: 1 | AN61: 1 | AO61: 1 | AP61: 1 | AQ61: 1 | AR61: 1 | AS61: 1 | AT61: 1
B62: Ordenes de compras | AI62: 1 | AJ62: 0.4 | AK62: 0.4 | AL62: 0.4 | AM62: 1 | AN62: 1 | AO62: 1 | AP62: 1 | AQ62: 1 | AR62: 1 | AS62: 1 | AT62: 1
B63: Proveedores | AI63: 1 | AJ63: 0.4 | AK63: 0.4 | AL63: 0.4 | AM63: 1 | AN63: 1 | AO63: 1 | AP63: 1 | AQ63: 1 | AR63: 1 | AS63: 1 | AT63: 1
B64: Requisiciones | AI64: 1 | AJ64: 0.4 | AK64: 0.4 | AL64: 0.4 | AM64: 1 | AN64: 1 | AO64: 1 | AP64: 1 | AQ64: 1 | AR64: 1 | AS64: 1 | AT64: 1
B65: Contratos | AI65: 1 | AJ65: 0.4 | AK65: 0.4 | AL65: 1 | AM65: 1 | AN65: 1 | AO65: 1 | AP65: 1 | AQ65: 1 | AR65: 1 | AS65: 1 | AT65: 1
B66: Solicitud de contratación logistica | AI66: 1 | AJ66: 0.4 | AK66: 0.4 | AL66: 1 | AM66: 1 | AN66: 1 | AO66: 1 | AP66: 1 | AQ66: 1 | AR66: 1 | AS66: 1 | AT66: 1
B67: Registro de ahorros | AI67: 1 | AJ67: 0.4 | AK67: 0.4 | AL67: 1 | AM67: 1 | AN67: 1 | AO67: 1 | AP67: 1 | AQ67: 1 | AR67: 1 | AS67: 1 | AT67: 1
B68: Modelo financiero | AM68: 1 | AN68: 1 | AO68: 1 | AP68: 1 | AQ68: 1 | AR68: 1 | AS68: 1 | AT68: 1
B69: Oferta comercial | AQ69: 0.8 | AR69: 1 | AS69: 1 | AT69: 1
B70: Acta | AQ70: 1 | AR70: 1 | AS70: 1 | AT70: 1
B71: Fabricante | AI71: 1 | AJ71: 1 | AK71: 1 | AL71: 1 | AM71: 1 | AN71: 1 | AO71: 1 | AP71: 1 | AQ71: 1 | AR71: 1 | AS71: 1 | AT71: 1
B72: Proceso | AQ72: 0.8 | AR72: 1 | AS72: 1 | AT72: 1
B73: Productos | AQ73: 0.8 | AR73: 1 | AS73: 1 | AT73: 1
B74: Servicio | AI74: 1 | AJ74: 1 | AK74: 1 | AL74: 1 | AM74: 1 | AN74: 1 | AO74: 1 | AP74: 1 | AQ74: 1 | AR74: 1 | AS74: 1 | AT74: 1
B75: Entregable | AQ75: 0.4 | AR75: 1 | AS75: 1 | AT75: 1
B76: Artefacto | AQ76: 0.4 | AR76: 1 | AS76: 1 | AT76: 1
B77: Riesgos y Oportunidades | AQ77: 0.4 | AR77: 1 | AS77: 1 | AT77: 1
B78: Política | AQ78: 0.8 | AR78: 1 | AS78: 1 | AT78: 1
...

Sheet Uso-Acceso Datos
B1: Se realiza sobre las entidades identificadas en los procesos
C2: Uso y acceso | D2: Uso y acceso | E2: Uso y acceso | F2: Uso y acceso | G2: Uso y acceso | H2: Uso y acceso | I2: Uso y acceso | J2: Uso y acceso | K2: Uso y acceso | L2: Uso y acceso | M2: Uso y acceso
C3: 1 | D3: 2 | E3: 3 | F3: 4 | G3: 5 | H3: 6 | I3: 7 | J3: 8 | K3: 9 | L3: 10 | M3: 17
C4: =SUMIF(C7:C244,">0")/COUNTIF(C7:C244,">0") -> 0.88676471 | D4: =SUMIF(D7:D244,">0")/COUNTIF(D7:D244,">0") -> 0.88872549 | E4: =SUMIF(E7:E244,">0")/COUNTIF(E7:E244,">0") -> 0.95097087 | F4: =SUMIF(F7:F244,">0")/COUNTIF(F7:F244,">0") -> 0.95376214 | G4: =SUMIF(G7:G244,">0")/COUNTIF(G7:G244,">0") -> 0.96696602 | H4: =SUMIF(H7:H244,">0")/COUNTIF(H7:H244,">0") -> 0.96696602 | I4: =SUMIF(I7:I244,">0")/COUNTIF(I7:I244,">0") -> 0.96854762 | J4: =SUMIF(J7:J244,">0")/COUNTIF(J7:J244,">0") -> 0.96854762 | ... M4: =SUMIF(M7:M244,">0")/COUNTIF(M7:M244,">0") -> 0.99196203
C5: =AVERAGE(Tabla13[Uso y acceso Ago/2024]) -> 0.86971154 | D5: =AVERAGE(Tabla13[Uso y acceso Sep/2024]) -> 0.87163462 | E5: =AVERAGE(Tabla13[Uso y acceso Oct/2024]) -> 0.94182692 | F5: =AVERAGE(Tabla13[Uso y acceso Nov/2024]) -> 0.94459135 | G5: =AVERAGE(Tabla13[Uso y acceso Dic/2024]) -> 0.95766827 | H5: =AVERAGE(Tabla13[Uso y acceso Ene/2025]) -> 0.95766827 | I5: =AVERAGE(Tabla13[Uso y acceso Feb/2025]) -> 0.95941038 | J5: =AVERAGE(Tabla13[Uso y acceso Mar/2025]) -> 0.95941038 | K5: =AVERAGE(Tabla13[Uso y acceso Abr/2025]) -> 0.96052752 | L5: =AVERAGE(Tabla13[Uso y acceso May/2025]) -> 0.97845291 | M5: =AVERAGE(Tabla13[Uso y acceso Dic/2025]) -> 0.98779412
B6: Entidades | C6: Uso y acceso Ago/2024 | D6: Uso y acceso Sep/2024 | E6: Uso y acceso Oct/2024 | F6: Uso y acceso Nov/2024 | G6: Uso y acceso Dic/2024 | H6: Uso y acceso Ene/2025 | I6: Uso y acceso Feb/2025 | J6: Uso y acceso Mar/2025 | K6: Uso y acceso Abr/2025 | L6: Uso y acceso May/2025 | M6: Uso y acceso Dic/2025
B7: Oportunidades | C7: 1 | D7: 1 | E7: 1 | F7: 1 | G7: 1 | H7: 1 | I7: 1 | J7: 1 | K7: 1 | L7: 1 | M7: 1
B8: Línea de negocios | C8: 1 | D8: 1 | E8: 1 | F8: 1 | G8: 1 | H8: 1 | I8: 1 | J8: 1 | K8: 1 | L8: 1 | M8: 1
B9: Equipo de ventas | C9: 1 | D9: 1 | E9: 1 | F9: 1 | G9: 1 | H9: 1 | I9: 1 | J9: 1 | K9: 1 | L9: 1 | M9: 1
B10: Tipo de cliente | C10: 1 | D10: 1 | E10: 1 | F10: 1 | G10: 1 | H10: 1 | I10: 1 | J10: 1 | K10: 1 | L10: 1 | M10: 1
B11: Cliente | C11: 1 | D11: 1 | E11: 1 | F11: 1 | G11: 1 | H11: 1 | I11: 1 | J11: 1 | K11: 1 | L11: 1 | M11: 1
B12: Tipo de venta | C12: 1 | D12: 1 | E12: 1 | F12: 1 | G12: 1 | H12: 1 | I12: 1 | J12: 1 | K12: 1 | L12: 1 | M12: 1
B13: Tipo de oportunidad | C13: 1 | D13: 1 | E13: 1 | F13: 1 | G13: 1 | H13: 1 | I13: 1 | J13: 1 | K13: 1 | L13: 1 | M13: 1
B14: Etapa actual | C14: 1 | D14: 1 | E14: 1 | F14: 1 | G14: 1 | H14: 1 | I14: 1 | J14: 1 | K14: 1 | L14: 1 | M14: 1
B15: Ganado | C15: 1 | D15: 1 | E15: 1 | F15: 1 | G15: 1 | H15: 1 | I15: 1 | J15: 1 | K15: 1 | L15: 1 | M15: 1
B16: Metas | C16: 1 | D16: 1 | E16: 1 | F16: 1 | G16: 1 | H16: 1 | I16: 1 | J16: 1 | K16: 1 | L16: 1 | M16: 1
B17: Metas de Comercial | C17: 1 | D17: 1 | E17: 1 | F17: 1 | G17: 1 | H17: 1 | I17: 1 | J17: 1 | K17: 1 | L17: 1 | M17: 1
B18: Área | C18: 1 | D18: 1 | E18: 1 | F18: 1 | G18: 1 | H18: 1 | I18: 1 | J18: 1 | K18: 1 | L18: 1 | M18: 1
... B214: Hallazgos | C214: 1 | D214: 1 | E214: 1 | F214: 1 | G214: 1 | H214: 1 | I214: 1 | J214: 1 | K214: 1 | L214: 1 | M214: 1
B215: Tipo de retiro | I215: 1 | J215: 1 | K215: 1 | L215: 1 | M215: 1
B216: Tipo de movimiento laboral | I216: 1 | J216: 1 | K216: 1 | L216: 1 | M216: 1
B217: Tipo de fuero | I217: 1 | J217: 1 | K217: 1 | L217: 1 | M217: 1
B218: Generación por año de nacimiento | I218: 1 | J218: 1 | K218: 1 | L218: 1 | M218: 1
B219: Identificación del proceso | K219: 1 | L219: 1 | M219: 1
B220: Modalidad de contratación | K220: 1 | L220: 1 | M220: 1
B221: Sector | K221: 1 | L221: 1 | M221: 1
B222: Subsector | K222: 1 | L222: 1 | M222: 1
B223: Orden de servicio | K223: 1 | L223: 1 | M223: 1
B224: Orden de trabajo | K224: 1 | L224: 1 | M224: 1
B225: Categoría servicios TI | L225: 1 | M225: 1
B226: Servicios TI | L226: 1 | M226: 1
B227: Control de acceso | L227: 1 | M227: 1
B228: Evento | L228: 1 | M228: 1
B229: Canales digitales | L229: 1 | M229: 1
B230: Medio de solicitud a doit | M230: 1
B231: Prioridad del Ticket | M231: 1
B232: Naturaleza del caso | M232: 1
B233: Estados de los tickets TI | M233: 1
B234: Estado orden de servicio | M234: 1
B235: Canal de recepción | M235: 1
...

Sheet Integracion-Flujo Datos
B1: Se realiza sobre las entidades identificadas en los procesos
C2: Integración | D2: Integración | E2: Integración | F2: Integración | G2: Integración | H2: Integración | I2: Integración | J2: Integración | K2: Integración | L2: Integración | M2: Integración
C3: 1 | D3: 2 | E3: 3 | F3: 4 | G3: 5 | H3: 6 | I3: 7 | J3: 8 | K3: 9 | L3: 10 | M3: 17
C4: =SUMIF(C7:C244,">0")/COUNTIF(C7:C244,">0") -> 0.98684211 | D4: =SUMIF(D7:D244,">0")/COUNTIF(D7:D244,">0") -> 0.96666667 | E4: =SUMIF(E7:E244,">0")/COUNTIF(E7:E244,">0") -> 0.79901961 | F4: =SUMIF(F7:F244,">0")/COUNTIF(F7:F244,">0") -> 0.86923077 | G4: =SUMIF(G7:G244,">0")/COUNTIF(G7:G244,">0") -> 0.98867925 | H4: =SUMIF(H7:H244,">0")/COUNTIF(H7:H244,">0") -> 0.98333333 | I4: =SUMIF(I7:I244,">0")/COUNTIF(I7:I244,">0") -> 0.94090909 | J4: =SUMIF(J7:J244,">0")/COUNTIF(J7:J244,">0") -> 0.94090909 | ... M4: =SUMIF(M7:M244,">0")/COUNTIF(M7:M244,">0") -> 0.80042017
C5: =AVERAGE(Tabla58[Integración Ago/2024]) -> 0.18028846 | D5: =AVERAGE(Tabla58[Integración Sep/2024]) -> 0.18125 | E5: =AVERAGE(Tabla58[Integración Oct/2024]) -> 0.19591346 | F5: =AVERAGE(Tabla58[Integración Nov/2024]) -> 0.21730769 | G5: =AVERAGE(Tabla58[Integración Dic/2024]) -> 0.25192308 | H5: =AVERAGE(Tabla58[Integración Ene/2025]) -> 0.25528846 | I5: =AVERAGE(Tabla58[Integración Feb/2025]) -> 0.29292453 | J5: =AVERAGE(Tabla58[Integración Mar/2025]) -> 0.29292453 | K5: =AVERAGE(Tabla58[Integración Abr/2025]) -> 0.32981651 | L5: =AVERAGE(Tabla58[Integración May/2025]) -> 0.34394619 | M5: =AVERAGE(Tabla58[Integración Dic/2025]) -> 0.80042017
B6: Entidades | C6: Integración Ago/2024 | D6: Integración Sep/2024 | E6: Integración Oct/2024 | F6: Integración Nov/2024 | G6: Integración Dic/2024 | H6: Integración Ene/2025 | I6: Integración Feb/2025 | J6: Integración Mar/2025 | K6: Integración Abr/2025 | L6: Integración May/2025 | M6: Integración Dic/2025
B7: Oportunidades | C7: 1 | D7: 1 | E7: 1 | F7: 1 | G7: 1 | H7: 1 | I7: 1 | J7: 1 | K7: 1 | L7: 1 | M7: 1
B8: Línea de negocios | C8: 1 | D8: 1 | E8: 1 | F8: 1 | G8: 1 | H8: 1 | I8: 1 | J8: 1 | K8: 1 | L8: 1 | M8: 1
B9: Equipo de ventas | C9: 1 | D9: 1 | E9: 1 | F9: 1 | G9: 1 | H9: 1 | I9: 1 | J9: 1 | K9: 1 | L9: 1 | M9: 1
B10: Tipo de cliente | C10: 1 | D10: 1 | E10: 1 | F10: 1 | G10: 1 | H10: 1 | I10: 1 | J10: 1 | K10: 1 | L10: 1 | M10: 1
B11: Cliente | C11: 1 | D11: 1 | E11: 1 | F11: 1 | G11: 1 | H11: 1 | I11: 1 | J11: 1 | K11: 1 | L11: 1 | M11: 1
B12: Tipo de venta | C12: 1 | D12: 1 | E12: 1 | F12: 1 | G12: 1 | H12: 1 | I12: 1 | J12: 1 | K12: 1 | L12: 1 | M12: 1
B13: Tipo de oportunidad | C13: 1 | D13: 1 | E13: 1 | F13: 1 | G13: 1 | H13: 1 | I13: 1 | J13: 1 | K13: 1 | L13: 1 | M13: 1
B14: Etapa actual | C14: 1 | D14: 1 | E14: 1 | F14: 1 | G14: 1 | H14: 1 | I14: 1 | J14: 1 | K14: 1 | L14: 1 | M14: 1
B15: Ganado | C15: 1 | D15: 1 | E15: 1 | F15: 1 | G15: 1 | H15: 1 | I15: 1 | J15: 1 | K15: 1 | L15: 1 | M15: 1
B16: Metas | C16: 1 | D16: 1 | E16: 1 | F16: 1 | G16: 1 | H16: 1 | I16: 1 | J16: 1 | K16: 1 | L16: 1 | M16: 1
B17: Metas de Comercial | C17: 1 | D17: 1 | E17: 1 | F17: 1 | G17: 1 | H17: 1 | I17: 1 | J17: 1 | K17: 1 | L17: 1 | M17: 1
B18: Área | C18: 1 | D18: 1 | E18: 1 | F18: 1 | G18: 1 | H18: 1 | I18: 1 | J18: 1 | K18: 1 | L18: 1 | M18: 1
... B214: Hallazgos | C214: 0 | D214: 0 | E214: 0 | F214: 0 | G214: 0 | H214: 0 | I214: 0 | J214: 0 | K214: 0 | L214: 0.3 | M214: 0.6
B215: Tipo de retiro | I215: 1 | J215: 1 | K215: 1 | L215: 1 | M215: 1
B216: Tipo de movimiento laboral | I216: 1 | J216: 1 | K216: 1 | L216: 1 | M216: 1
B217: Tipo de fuero | I217: 1 | J217: 1 | K217: 1 | L217: 1 | M217: 1
B218: Generación por año de nacimiento | I218: 1 | J218: 1 | K218: 1 | L218: 1 | M218: 1
B219: Identificación del proceso | K219: 1 | L219: 1 | M219: 1
B220: Modalidad de contratación | K220: 1 | L220: 1 | M220: 1
B221: Sector | K221: 1 | L221: 1 | M221: 1
B222: Subsector | K222: 1 | L222: 1 | M222: 1
B223: Orden de servicio | K223: 0.3 | L223: 0.3 | M223: 0.8
B224: Orden de trabajo | K224: 0.3 | L224: 0.3 | M224: 0.8
B225: Categoría servicios TI | L225: 0.3 | M225: 1
B226: Servicios TI | L226: 0.3 | M226: 1
B227: Control de acceso | L227: 0.3 | M227: 0.8
B228: Evento | L228: 0.3 | M228: 0.8
B229: Canales digitales | L229: 0.3 | M229: 1
B230: Medio de solicitud a doit | M230: 1
B231: Prioridad del Ticket | M231: 1
B232: Naturaleza del caso | M232: 1
B233: Estados de los tickets TI | M233: 1
B234: Estado orden de servicio | M234: 1
B235: Canal de recepción | M235: 1
...

Sheet Gestion Ciclo-Vida Datos
B1: Se realiza sobre las entidades identificadas en los procesos. Esta definido por los indicadores Calidad de datos, Uso-Acceso Datos, Integración-Flujo de datos; adicional a estos Creación y captura, Almacenamiento y registro
C2: Creación y Captura | D2: Almacenamiento y Registro | E2: Calidad de datos | F2: Uso y acceso | G2: Compartición e Interoperabilidad | H2: Gestión ciclo de Vida | I2: Creación y Captura | J2: Almacenamiento y Registro | K2: Calidad de datos | L2: Uso y acceso | M2: Compartición e Interoperabilidad | N2: Gestión ciclo de Vida | O2: Creación y Captura | P2: Almacenamiento y Registro | Q2: Calidad de datos | R2: Uso y acceso | S2: Compartición e Interoperabilidad | T2: Gestión ciclo de Vida | U2: Creación y Captura | V2: Almacenamiento y Registro | W2: Calidad de datos | X2: Uso y acceso | Y2: Compartición e Interoperabilidad | Z2: Gestión ciclo de Vida | AA2: Creación y Captura | AB2: Almacenamiento y Registro | AC2: Calidad de datos | AD2: Uso y acceso | AE2: Compartición e Interoperabilidad | AF2: Gestión ciclo de Vida | AG2: Creación y Captura | AH2: Almacenamiento y Registro | AI2: Calidad de datos | AJ2: Uso y acceso | AK2: Compartición e Interoperabilidad | AL2: Gestión ciclo de Vida | AM2: Creación y Captura | AN2: Almacenamiento y Registro | AO2: Calidad de datos | AP2: Uso y acceso | AQ2: Compartición e Interoperabilidad | AR2: Gestión ciclo de Vida | AS2: Creación y Captura | AT2: Almacenamiento y Registro | AU2: Calidad de datos | AV2: Uso y acceso | AW2: Compartición e Interoperabilidad | AX2: Gestión ciclo de Vida | AY2: Creación y Captura | AZ2: Almacenamiento y Registro | BA2: Calidad de datos | BB2: Uso y acceso | BC2: Compartición e Interoperabilidad | BD2: Gestión ciclo de Vida | BE2: Creación y Captura | BF2: Almacenamiento y Registro | BG2: Calidad de datos | BH2: Uso y acceso | BI2: Compartición e Interoperabilidad | BJ2: Gestión ciclo de Vida | BK2: Creación y Captura | BL2: Almacenamiento y Registro | BM2: Calidad de datos | BN2: Uso y acceso | BO2: Compartición e Interoperabilidad | BP2: Gestión ciclo de Vida
C3: 1 | D3: 1 | E3: 1 | F3: 1 | G3: 1 | H3: 1 | I3: 2 | J3: 2 | K3: 2 | L3: 2 | M3: 2 | N3: 2 | O3: 3 | P3: 3 | Q3: 3 | R3: 3 | S3: 3 | T3: 3 | U3: 4 | V3: 4 | W3: 4 | X3: 4 | Y3: 4 | Z3: 4 | AA3: 5 | AB3: 5 | AC3: 5 | AD3: 5 | AE3: 5 | AF3: 5 | AG3: 6 | AH3: 6 | AI3: 6 | AJ3: 6 | AK3: 6 | AL3: 6 | AM3: 7 | AN3: 7 | AO3: 7 | AP3: 7 | AQ3: 7 | AR3: 7 | AS3: 8 | AT3: 8 | AU3: 8 | AV3: 8 | AW3: 8 | AX3: 8 | AY3: 9 | AZ3: 9 | BA3: 9 | BB3: 9 | BC3: 9 | BD3: 9 | BE3: 10 | BF3: 10 | BG3: 10 | BH3: 10 | BI3: 10 | BJ3: 10 | BK3: 17 | BL3: 17 | BM3: 17 | BN3: 17 | BO3: 17 | BP3: 17
C4: =SUMIF(C7:C244,">0")/COUNTIF(C7:C244,">0") -> 0.99605263 | D4: =SUMIF(D7:D244,">0")/COUNTIF(D7:D244,">0") -> 0.98684211 | E4: =SUMIF(E7:E244,">0")/COUNTIF(E7:E244,">0") -> 0.93565789 | F4: =SUMIF(F7:F244,">0")/COUNTIF(F7:F244,">0") -> 0.88676471 | G4: =SUMIF(G7:G244,">0")/COUNTIF(G7:G244,">0") -> 0.98684211 | H4: =SUMIF(H7:H244,">0")/COUNTIF(H7:H244,">0") -> 0.52703105 | I4: =SUMIF(I7:I244,">0")/COUNTIF(I7:I244,">0") -> 0.97948718 | J4: =SUMIF(J7:J244,">0")/COUNTIF(J7:J244,">0") -> 0.96666667 | ... BP4: =SUMIF(BP7:BP244,">0")/COUNTIF(BP7:BP244,">0") -> 0.88886754
C5: =IFERROR(AVERAGEIF(Tabla4[Creación y captura Ago/2024],">0",Tabla4[Creación y captura Ago/2024]),0) -> 0.99605263 | D5: =IFERROR(AVERAGEIF(Tabla4[Almacenamiento y registro Ago/2024],">0",Tabla4[Almacenamiento y registro Ago/2024]),0) -> 0.98684211 | E5: =IFERROR(AVERAGEIF(Tabla4[Calidad de datos Ago/2024],">0",Tabla4[Calidad de datos Ago/2024]),0) -> 0.93565789 | F5: =AVERAGE(Tabla4[Uso y acceso Ago/2024]) -> 0.76008403 | G5: =AVERAGE(Tabla4[Compartición e Interoperabilidad Ago/2024]) -> 0.15756303 | H5: =AVERAGE(C5:G5) -> 0.76723994 | I5: =IFERROR(AVERAGEIF(Tabla4[Creación y captura Sep/2024],">0",Tabla4[Creación y captura Sep/2024]),0) -> 0.97948718 | J5: =IFERROR(AVERAGEIF(Tabla4[Almacenamiento y registro Sep/2024],">0",Tabla4[Almacenamiento y registro Sep/2024]),0) -> 0.96666667 | K5: =IFERROR(AVERAGEIF(Tabla4[Calidad de datos Sep/2024],">0",Tabla4[Calidad de datos Sep/2024]),0) -> 0.94888158 | L5: =AVERAGE(Tabla4[Uso y acceso Sep/2024]) -> 0.76176471 | M5: =AVERAGE(Tabla4[Compartición e Interoperabilidad Sep/2024]) -> 0.15840336 | N5: =AVERAGE(I5:M5) -> 0.7630407 | O5: =IFERROR(AVERAGEIF(Tabla4[Creación y captura Oct/2024],">0",Tabla4[Creación y captura Oct/2024]),0) -> 0.86666667 | P5: =IFERROR(AVERAGEIF(Tabla4[Almacenamiento y registro Oct/2024],">0",Tabla4[Almacenamiento y registro Oct/2024]),0) -> 0.79901961 | Q5: =IFERROR(AVERAGEIF(Tabla4[Calidad de datos Oct/2024],">0",Tabla4[Calidad de datos Oct/2024]),0) -> 0.94888158 | R5: =AVERAGE(Tabla4[Uso y acceso Oct/2024]) -> 0.82310924 | S5: =AVERAGE(Tabla4[Compartición e Interoperabilidad Oct/2024]) -> 0.17121849 | T5: =AVERAGE(O5:S5) -> 0.72177912 | U5: =IFERROR(AVERAGEIF(Tabla4[Creación y captura Nov/2024],">0",Tabla4[Creación y captura Nov/2024]),0) -> 0.96785714 | V5: =IFERROR(AVERAGEIF(Tabla4[Almacenamiento y registro Nov/2024],">0",Tabla4[Almacenamiento y registro Nov/2024]),0) -> 0.91730769 | W5: =IFERROR(AVERAGEIF(Tabla4[Calidad de datos Nov/2024],">0",Tabla4[Calidad de datos Nov/2024]),0) -> 0.94982143 | X5: =AVERAGE(Tabla4[Uso y acceso Nov/2024]) -> 0.82552521 | Y5: =AVERAGE(Tabla4[Compartición e Interoperabilidad Nov/2024]) -> 0.18991597 | Z5: =AVERAGE(U5:Y5) -> 0.77008549 | AA5: =IFERROR(AVERAGEIF(Tabla4[Creación y captura Dic/2024],">0",Tabla4[Creación y captura Dic/2024]),0) -> 0.97142857 | AB5: =IFERROR(AVERAGEIF(Tabla4[Almacenamiento y registro Dic/2024],">0",Tabla4[Almacenamiento y registro Dic/2024]),0) -> 0.98867925 | AC5: =IFERROR(AVERAGEIF(Tabla4[Calidad de datos Dic/2024],">0",Tabla4[Calidad de datos Dic/2024]),0) -> 0.96267857 | AD5: =AVERAGE(Tabla4[Uso y acceso Dic/2024]) -> 0.83695378 | AE5: =AVERAGE(Tabla4[Compartición e Interoperabilidad Dic/2024]) -> 0.22016807 | AF5: =AVERAGE(AA5:AE5) -> 0.79598165 | AG5: =IFERROR(AVERAGEIF(Tabla4[Creación y captura Ene/2025],">0",Tabla4[Creación y captura Ene/2025]),0) -> 0.98571429 | AH5: =IFERROR(AVERAGEIF(Tabla4[Almacenamiento y registro Ene/2025],">0",Tabla4[Almacenamiento y registro Ene/2025]),0) -> 0.98611111 | AI5: =IFERROR(AVERAGEIF(Tabla4[Calidad de datos Ene/2025],">0",Tabla4[Calidad de datos Ene/2025]),0) -> 0.97705357 | AJ5: =AVERAGE(Tabla4[Uso y acceso Ene/2025]) -> 0.83695378 | AK5: =AVERAGE(Tabla4[Compartición e Interoperabilidad Ene/2025]) -> 0.22310924 | AL5: =AVERAGE(AG5:AK5) -> 0.8017884 | AM5: =IFERROR(AVERAGEIF(Tabla4[Creación y captura Feb/2025],">0",Tabla4[Creación y captura Feb/2025]),0) -> 0.98934426 | AN5: =IFERROR(AVERAGEIF(Tabla4[Almacenamiento y registro Feb/2025],">0",Tabla4[Almacenamiento y registro Feb/2025]),0) -> 0.99344262 | AO5: =IFERROR(AVERAGEIF(Tabla4[Calidad de datos Feb/2025],">0",Tabla4[Calidad de datos Feb/2025]),0) -> 0.98616667 | AP5: =AVERAGE(Tabla4[Uso y acceso Feb/2025]) -> 0.85460084 | AQ5: =AVERAGE(Tabla4[Compartición e Interoperabilidad Feb/2025]) -> 0.26092437 | AR5: =AVERAGE(AM5:AQ5) -> 0.81689575 | AS5: =IFERROR(AVERAGEIF(Tabla4[Creación y captura Mar/2025],">0",Tabla4[Creación y captura Mar/2025]),0) -> 0.99166667 | AT5: =IFERROR(AVERAGEIF(Tabla4[Almacenamiento y registro Mar/2025],">0",Tabla4[Almacenamiento y registro Mar/2025]),0) -> 1 | AU5: =IFERROR(AVERAGEIF(Tabla4[Calidad de datos Mar/2025],">0",Tabla4[Calidad de datos Mar/2025]),0) -> 0.98679167 | AV5: =AVERAGE(Tabla4[Uso y acceso Mar/2025]) -> 0.85460084 | AW5: =AVERAGE(Tabla4[Compartición e Interoperabilidad Mar/2025]) -> 0.26092437 | AX5: =AVERAGE(AS5:AW5) -> 0.81879671 | AY5: =IFERROR(AVERAGEIF(Tabla4[Creación y captura Abr/2025],">0",Tabla4[Creación y captura Abr/2025]),0) -> 0.9575 | AZ5: =IFERROR(AVERAGEIF(Tabla4[Almacenamiento y registro Abr/2025],">0",Tabla4[Almacenamiento y registro Abr/2025]),0) -> 0.9025 | BA5: =IFERROR(AVERAGEIF(Tabla4[Calidad de datos Abr/2025],">0",Tabla4[Calidad de datos Abr/2025]),0) -> 0.93965625 | BB5: =AVERAGE(Tabla4[Uso y acceso Abr/2025]) -> 0.87981092 | BC5: =AVERAGE(Tabla4[Compartición e Interoperabilidad Abr/2025]) -> 0.30210084 | BD5: =AVERAGE(AY5:BC5) -> 0.7963136 | BE5: =IFERROR(AVERAGEIF(Tabla4[Creación y captura May/2025],">0",Tabla4[Creación y captura May/2025]),0) -> 0.927 | BF5: =IFERROR(AVERAGEIF(Tabla4[Almacenamiento y registro May/2025],">0",Tabla4[Almacenamiento y registro May/2025]),0) -> 0.837 | BG5: =IFERROR(AVERAGEIF(Tabla4[Calidad de datos May/2025],">0",Tabla4[Calidad de datos May/2025]),0) -> 0.996875 | BH5: =AVERAGE(Tabla4[Uso y acceso May/2025]) -> 0.91678571 | BI5: =AVERAGE(Tabla4[Compartición e Interoperabilidad May/2025]) -> 0.32226891 | BJ5: =AVERAGE(BE5:BI5) -> 0.79998592 | BK5: =IFERROR(AVERAGEIF(Tabla4[Creación y captura Dic/2025],">0",Tabla4[Creación y captura Dic/2025]),0) -> 0.95766423 | BL5: =IFERROR(AVERAGEIF(Tabla4[Almacenamiento y registro Dic/2025],">0",Tabla4[Almacenamiento y registro Dic/2025]),0) -> 0.90510949 | BM5: =IFERROR(AVERAGEIF(Tabla4[Calidad de datos Dic/2025],">0",Tabla4[Calidad de datos Dic/2025]),0) -> 0.91163813 | BN5: =AVERAGE(Tabla4[Uso y acceso Dic/2025]) -> 0.98779412 | BO5: =AVERAGE(Tabla4[Compartición e Interoperabilidad Dic/2025]) -> 0.80042017 | BP5: =AVERAGE(BK5:BO5) -> 0.91252523
B6: Entidades | C6: Creación y captura Ago/2024 | D6: Almacenamiento y registro Ago/2024 | E6: Calidad de datos Ago/2024 | F6: Uso y acceso Ago/2024 | G6: Compartición e Interoperabilidad Ago/2024 | H6: Gestión ciclo de Vida Ago/2024 | I6: Creación y captura Sep/2024 | J6: Almacenamiento y registro Sep/2024 | K6: Calidad de datos Sep/2024 | L6: Uso y acceso Sep/2024 | M6: Compartición e Interoperabilidad Sep/2024 | N6: Gestión ciclo de Vida Sep/2024 | O6: Creación y captura Oct/2024 | P6: Almacenamiento y registro Oct/2024 | Q6: Calidad de datos Oct/2024 | R6: Uso y acceso Oct/2024 | S6: Compartición e Interoperabilidad Oct/2024 | T6: Gestión ciclo de Vida Oct/2024 | U6: Creación y captura Nov/2024 | V6: Almacenamiento y registro Nov/2024 | W6: Calidad de datos Nov/2024 | X6: Uso y acceso Nov/2024 | Y6: Compartición e Interoperabilidad Nov/2024 | Z6: Gestión ciclo de Vida Nov/2024 | AA6: Creación y captura Dic/2024 | AB6: Almacenamiento y registro Dic/2024 | AC6: Calidad de datos Dic/2024 | AD6: Uso y acceso Dic/2024 | AE6: Compartición e Interoperabilidad Dic/2024 | AF6: Gestión ciclo de Vida Dic/2024 | AG6: Creación y captura Ene/2025 | AH6: Almacenamiento y registro Ene/2025 | AI6: Calidad de datos Ene/2025 | AJ6: Uso y acceso Ene/2025 | AK6: Compartición e Interoperabilidad Ene/2025 | AL6: Gestión ciclo de Vida Ene/2025 | AM6: Creación y captura Feb/2025 | AN6: Almacenamiento y registro Feb/2025 | AO6: Calidad de datos Feb/2025 | AP6: Uso y acceso Feb/2025 | AQ6: Compartición e Interoperabilidad Feb/2025 | AR6: Gestión ciclo de Vida Feb/2025 | AS6: Creación y captura Mar/2025 | AT6: Almacenamiento y registro Mar/2025 | AU6: Calidad de datos Mar/2025 | AV6: Uso y acceso Mar/2025 | AW6: Compartición e Interoperabilidad Mar/2025 | AX6: Gestión ciclo de Vida Mar/2025 | AY6: Creación y captura Abr/2025 | AZ6: Almacenamiento y registro Abr/2025 | BA6: Calidad de datos Abr/2025 | BB6: Uso y acceso Abr/2025 | BC6: Compartición e Interoperabilidad Abr/2025 | BD6: Gestión ciclo de Vida Abr/2025 | BE6: Creación y captura May/2025 | BF6: Almacenamiento y registro May/2025 | BG6: Calidad de datos May/2025 | BH6: Uso y acceso May/2025 | BI6: Compartición e Interoperabilidad May/2025 | BJ6: Gestión ciclo de Vida May/2025 | BK6: Creación y captura Dic/2025 | BL6: Almacenamiento y registro Dic/2025 | BM6: Calidad de datos Dic/2025 | BN6: Uso y acceso Dic/2025 | BO6: Compartición e Interoperabilidad Dic/2025 | BP6: Gestión ciclo de Vida Dic/2025
B7: Oportunidades | C7: 1 | D7: 1 | E7: =AVERAGE('Calidad de Datos'!C11:F11) -> 0.735 | F7: =Tabla13[[#This Row],[Uso y acceso Ago/2024]] -> 1 | G7: =Tabla58[[#This Row],[Integración Ago/2024]] -> 1 | H7: =AVERAGE(Tabla4[[#This Row],[Creación y captura Ago/2024]:[Compartición e Interoperabilidad Ago/2024]]) -> 0.947 | I7: 1 | J7: 1 | K7: =AVERAGE('Calidad de Datos'!G11:J11) -> 0.7875 | L7: =Tabla13[[#This Row],[Uso y acceso Sep/2024]] -> 1 | M7: =Tabla58[[#This Row],[Integración Sep/2024]] -> 1 | N7: =AVERAGE(Tabla4[[#This Row],[Creación y captura Sep/2024]:[Compartición e Interoperabilidad Sep/2024]]) -> 0.9575 | O7: 1 | P7: 1 | Q7: =AVERAGE('Calidad de Datos'!K11:N11) -> 0.7825 | R7: =Tabla13[[#This Row],[Uso y acceso Oct/2024]] -> 1 | S7: =Tabla58[[#This Row],[Integración Oct/2024]] -> 1 | T7: =AVERAGE(Tabla4[[#This Row],[Creación y captura Oct/2024]:[Compartición e Interoperabilidad Oct/2024]]) -> 0.9565 | U7: 1 | V7: 1 | W7: =AVERAGE('Calidad de Datos'!O11:R11) -> 0.875 | X7: =Tabla13[[#This Row],[Uso y acceso Nov/2024]] -> 1 | Y7: =Tabla58[[#This Row],[Integración Nov/2024]] -> 1 | Z7: =AVERAGE(Tabla4[[#This Row],[Creación y captura Nov/2024]:[Compartición e Interoperabilidad Nov/2024]]) -> 0.975 | AA7: 1 | AB7: 1 | AC7: =AVERAGE('Calidad de Datos'!S11:V11) -> 0.91125 | AD7: =Tabla13[[#This Row],[Uso y acceso Dic/2024]] -> 1 | AE7: =Tabla58[[#This Row],[Integración Dic/2024]] -> 1 | AF7: =AVERAGE(Tabla4[[#This Row],[Creación y captura Dic/2024]:[Compartición e Interoperabilidad Dic/2024]]) -> 0.98225 | AG7: 1 | AH7: 1 | AI7: =AVERAGE('Calidad de Datos'!W11:Z11) -> 0.925 | AJ7: =Tabla13[[#This Row],[Uso y acceso Ene/2025]] -> 1 | AK7: =Tabla58[[#This Row],[Integración Ene/2025]] -> 1 | AL7: =AVERAGE(Tabla4[[#This Row],[Creación y captura Ene/2025]:[Compartición e Interoperabilidad Ene/2025]]) -> 0.985 | AM7: 1 | AN7: 1 | AO7: =AVERAGE('Calidad de Datos'!AA11:AD11) -> 0.925 | AP7: =Tabla13[[#This Row],[Uso y acceso Feb/2025]] -> 1 | AQ7: =Tabla58[[#This Row],[Integración Feb/2025]] -> 1 | AR7: =AVERAGE(Tabla4[[#This Row],[Creación y captura Feb/2025]:[Compartición e Interoperabilidad Feb/2025]]) -> 0.985 | AS7: 1 | AT7: 1 | AU7: =AVERAGE('Calidad de Datos'!AE11:AH11) -> 0.925 | AV7: =Tabla13[[#This Row],[Uso y acceso Mar/2025]] -> 1 | AW7: =Tabla58[[#This Row],[Integración Mar/2025]] -> 1 | AX7: =AVERAGE(Tabla4[[#This Row],[Creación y captura Mar/2025]:[Compartición e Interoperabilidad Mar/2025]]) -> 0.985 | AY7: 1 | AZ7: 1 | BA7: =AVERAGE('Calidad de Datos'!AI11:AL11) -> 0.925 | BB7: =Tabla13[[#This Row],[Uso y acceso Abr/2025]] -> 1 | BC7: =Tabla58[[#This Row],[Integración Abr/2025]] -> 1 | BD7: =AVERAGE(Tabla4[[#This Row],[Creación y captura Abr/2025]:[Compartición e Interoperabilidad Abr/2025]]) -> 0.985 | BE7: 1 | BF7: 1 | BG7: =AVERAGE('Calidad de Datos'!AM11:AP11) -> 0.95 | BH7: =Tabla13[[#This Row],[Uso y acceso May/2025]] -> 1 | BI7: =Tabla58[[#This Row],[Integración May/2025]] -> 1 | BJ7: =AVERAGE(Tabla4[[#This Row],[Creación y captura May/2025]:[Compartición e Interoperabilidad May/2025]]) -> 0.99 | BK7: 1 | BL7: 1 | BM7: =AVERAGE('Calidad de Datos'!AQ11:AT11) -> 0.881375 | BN7: =Tabla13[[#This Row],[Uso y acceso Dic/2025]] -> 1 | BO7: =Tabla58[[#This Row],[Integración Dic/2025]] -> 1 | BP7: =AVERAGE(Tabla4[[#This Row],[Creación y captura Dic/2025]:[Compartición e Interoperabilidad Dic/2025]]) -> 0.976275
B8: Línea de negocios | C8: 1 | D8: 1 | E8: =AVERAGE('Calidad de Datos'!C12:F12) -> 1 | F8: =Tabla13[[#This Row],[Uso y acceso Ago/2024]] -> 1 | G8: =Tabla58[[#This Row],[Integración Ago/2024]] -> 1 | H8: =AVERAGE(Tabla4[[#This Row],[Creación y captura Ago/2024]:[Compartición e Interoperabilidad Ago/2024]]) -> 1 | I8: 1 | J8: 1 | K8: =AVERAGE('Calidad de Datos'!G12:J12) -> 1 | L8: =Tabla13[[#This Row],[Uso y acceso Sep/2024]] -> 1 | M8: =Tabla58[[#This Row],[Integración Sep/2024]] -> 1 | N8: =AVERAGE(Tabla4[[#This Row],[Creación y captura Sep/2024]:[Compartición e Interoperabilidad Sep/2024]]) -> 1 | O8: 1 | P8: 1 | Q8: =AVERAGE('Calidad de Datos'!K12:N12) -> 1 | R8: =Tabla13[[#This Row],[Uso y acceso Oct/2024]] -> 1 | S8: =Tabla58[[#This Row],[Integración Oct/2024]] -> 1 | T8: =AVERAGE(Tabla4[[#This Row],[Creación y captura Oct/2024]:[Compartición e Interoperabilidad Oct/2024]]) -> 1 | U8: 1 | V8: 1 | W8: =AVERAGE('Calidad de Datos'!O12:R12) -> 1 | X8: =Tabla13[[#This Row],[Uso y acceso Nov/2024]] -> 1 | Y8: =Tabla58[[#This Row],[Integración Nov/2024]] -> 1 | Z8: =AVERAGE(Tabla4[[#This Row],[Creación y captura Nov/2024]:[Compartición e Interoperabilidad Nov/2024]]) -> 1 | AA8: 1 | AB8: 1 | AC8: =AVERAGE('Calidad de Datos'!S12:V12) -> 1 | AD8: =Tabla13[[#This Row],[Uso y acceso Dic/2024]] -> 1 | AE8: =Tabla58[[#This Row],[Integración Dic/2024]] -> 1 | AF8: =AVERAGE(Tabla4[[#This Row],[Creación y captura Dic/2024]:[Compartición e Interoperabilidad Dic/2024]]) -> 1 | AG8: 1 | AH8: 1 | AI8: =AVERAGE('Calidad de Datos'!W12:Z12) -> 1 | AJ8: =Tabla13[[#This Row],[Uso y acceso Ene/2025]] -> 1 | AK8: =Tabla58[[#This Row],[Integración Ene/2025]] -> 1 | AL8: =AVERAGE(Tabla4[[#This Row],[Creación y captura Ene/2025]:[Compartición e Interoperabilidad Ene/2025]]) -> 1 | AM8: 1 | AN8: 1 | AO8: =AVERAGE('Calidad de Datos'!AA12:AD12) -> 1 | AP8: =Tabla13[[#This Row],[Uso y acceso Feb/2025]] -> 1 | AQ8: =Tabla58[[#This Row],[Integración Feb/2025]] -> 1 | AR8: =AVERAGE(Tabla4[[#This Row],[Creación y captura Feb/2025]:[Compartición e Interoperabilidad Feb/2025]]) -> 1 | AS8: 1 | AT8: 1 | AU8: =AVERAGE('Calidad de Datos'!AE12:AH12) -> 1 | AV8: =Tabla13[[#This Row],[Uso y acceso Mar/2025]] -> 1 | AW8: =Tabla58[[#This Row],[Integración Mar/2025]] -> 1 | AX8: =AVERAGE(Tabla4[[#This Row],[Creación y captura Mar/2025]:[Compartición e Interoperabilidad Mar/2025]]) -> 1 | AY8: 1 | AZ8: 1 | BA8: =AVERAGE('Calidad de Datos'!AI12:AL12) -> 1 | BB8: =Tabla13[[#This Row],[Uso y acceso Abr/2025]] -> 1 | BC8: =Tabla58[[#This Row],[Integración Abr/2025]] -> 1 | BD8: =AVERAGE(Tabla4[[#This Row],[Creación y captura Abr/2025]:[Compartición e Interoperabilidad Abr/2025]]) -> 1 | BE8: 1 | BF8: 1 | BG8: =AVERAGE('Calidad de Datos'!AM12:AP12) -> 1 | BH8: =Tabla13[[#This Row],[Uso y acceso May/2025]] -> 1 | BI8: =Tabla58[[#This Row],[Integración May/2025]] -> 1 | BJ8: =AVERAGE(Tabla4[[#This Row],[Creación y captura May/2025]:[Compartición e Interoperabilidad May/2025]]) -> 1 | BK8: 1 | BL8: 1 | BM8: =AVERAGE('Calidad de Datos'!AQ12:AT12) -> 1 | BN8: =Tabla13[[#This Row],[Uso y acceso Dic/2025]] -> 1 | BO8: =Tabla58[[#This Row],[Integración Dic/2025]] -> 1 | BP8: =AVERAGE(Tabla4[[#This Row],[Creación y captura Dic/2025]:[Compartición e Interoperabilidad Dic/2025]]) -> 1
B9: Equipo de ventas | C9: 1 | D9: 1 | E9: =AVERAGE('Calidad de Datos'!C13:F13) -> 1 | F9: =Tabla13[[#This Row],[Uso y acceso Ago/2024]] -> 1 | G9: =Tabla58[[#This Row],[Integración Ago/2024]] -> 1 | H9: =AVERAGE(Tabla4[[#This Row],[Creación y captura Ago/2024]:[Compartición e Interoperabilidad Ago/2024]]) -> 1 | I9: 1 | J9: 1 | K9: =AVERAGE('Calidad de Datos'!G13:J13) -> 1 | L9: =Tabla13[[#This Row],[Uso y acceso Sep/2024]] -> 1 | M9: =Tabla58[[#This Row],[Integración Sep/2024]] -> 1 | N9: =AVERAGE(Tabla4[[#This Row],[Creación y captura Sep/2024]:[Compartición e Interoperabilidad Sep/2024]]) -> 1 | O9: 1 | P9: 1 | Q9: =AVERAGE('Calidad de Datos'!K13:N13) -> 1 | R9: =Tabla13[[#This Row],[Uso y acceso Oct/2024]] -> 1 | S9: =Tabla58[[#This Row],[Integración Oct/2024]] -> 1 | T9: =AVERAGE(Tabla4[[#This Row],[Creación y captura Oct/2024]:[Compartición e Interoperabilidad Oct/2024]]) -> 1 | U9: 1 | V9: 1 | W9: =AVERAGE('Calidad de Datos'!O13:R13) -> 1 | X9: =Tabla13[[#This Row],[Uso y acceso Nov/2024]] -> 1 | Y9: =Tabla58[[#This Row],[Integración Nov/2024]] -> 1 | Z9: =AVERAGE(Tabla4[[#This Row],[Creación y captura Nov/2024]:[Compartición e Interoperabilidad Nov/2024]]) -> 1 | AA9: 1 | AB9: 1 | AC9: =AVERAGE('Calidad de Datos'!S13:V13) -> 1 | AD9: =Tabla13[[#This Row],[Uso y acceso Dic/2024]] -> 1 | AE9: =Tabla58[[#This Row],[Integración Dic/2024]] -> 1 | AF9: =AVERAGE(Tabla4[[#This Row],[Creación y captura Dic/2024]:[Compartición e Interoperabilidad Dic/2024]]) -> 1 | AG9: 1 | AH9: 1 | AI9: =AVERAGE('Calidad de Datos'!W13:Z13) -> 1 | AJ9: =Tabla13[[#This Row],[Uso y acceso Ene/2025]] -> 1 | AK9: =Tabla58[[#This Row],[Integración Ene/2025]] -> 1 | AL9: =AVERAGE(Tabla4[[#This Row],[Creación y captura Ene/2025]:[Compartición e Interoperabilidad Ene/2025]]) -> 1 | AM9: 1 | AN9: 1 | AO9: =AVERAGE('Calidad de Datos'!AA13:AD13) -> 1 | AP9: =Tabla13[[#This Row],[Uso y acceso Feb/2025]] -> 1 | AQ9: =Tabla58[[#This Row],[Integración Feb/2025]] -> 1 | AR9: =AVERAGE(Tabla4[[#This Row],[Creación y captura Feb/2025]:[Compartición e Interoperabilidad Feb/2025]]) -> 1 | AS9: 1 | AT9: 1 | AU9: =AVERAGE('Calidad de Datos'!AE13:AH13) -> 1 | AV9: =Tabla13[[#This Row],[Uso y acceso Mar/2025]] -> 1 | AW9: =Tabla58[[#This Row],[Integración Mar/2025]] -> 1 | AX9: =AVERAGE(Tabla4[[#This Row],[Creación y captura Mar/2025]:[Compartición e Interoperabilidad Mar/2025]]) -> 1 | AY9: 1 | AZ9: 1 | BA9: =AVERAGE('Calidad de Datos'!AI13:AL13) -> 1 | BB9: =Tabla13[[#This Row],[Uso y acceso Abr/2025]] -> 1 | BC9: =Tabla58[[#This Row],[Integración Abr/2025]] -> 1 | BD9: =AVERAGE(Tabla4[[#This Row],[Creación y captura Abr/2025]:[Compartición e Interoperabilidad Abr/2025]]) -> 1 | BE9: 1 | BF9: 1 | BG9: =AVERAGE('Calidad de Datos'!AM13:AP13) -> 1 | BH9: =Tabla13[[#This Row],[Uso y acceso May/2025]] -> 1 | BI9: =Tabla58[[#This Row],[Integración May/2025]] -> 1 | BJ9: =AVERAGE(Tabla4[[#This Row],[Creación y captura May/2025]:[Compartición e Interoperabilidad May/2025]]) -> 1 | BK9: 1 | BL9: 1 | BM9: =AVERAGE('Calidad de Datos'!AQ13:AT13) -> 1 | BN9: =Tabla13[[#This Row],[Uso y acceso Dic/2025]] -> 1 | BO9: =Tabla58[[#This Row],[Integración Dic/2025]] -> 1 | BP9: =AVERAGE(Tabla4[[#This Row],[Creación y captura Dic/2025]:[Compartición e Interoperabilidad Dic/2025]]) -> 1
B10: Tipo de cliente | C10: 1 | D10: 1 | E10: =AVERAGE('Calidad de Datos'!C14:F14) -> 1 | F10: =Tabla13[[#This Row],[Uso y acceso Ago/2024]] -> 1 | G10: =Tabla58[[#This Row],[Integración Ago/2024]] -> 1 | H10: =AVERAGE(Tabla4[[#This Row],[Creación y captura Ago/2024]:[Compartición e Interoperabilidad Ago/2024]]) -> 1 | I10: 1 | J10: 1 | K10: =AVERAGE('Calidad de Datos'!G14:J14) -> 1 | L10: =Tabla13[[#This Row],[Uso y acceso Sep/2024]] -> 1 | M10: =Tabla58[[#This Row],[Integración Sep/2024]] -> 1 | N10: =AVERAGE(Tabla4[[#This Row],[Creación y captura Sep/2024]:[Compartición e Interoperabilidad Sep/2024]]) -> 1 | O10: 1 | P10: 1 | Q10: =AVERAGE('Calidad de Datos'!K14:N14) -> 1 | R10: =Tabla13[[#This Row],[Uso y acceso Oct/2024]] -> 1 | S10: =Tabla58[[#This Row],[Integración Oct/2024]] -> 1 | T10: =AVERAGE(Tabla4[[#This Row],[Creación y captura Oct/2024]:[Compartición e Interoperabilidad Oct/2024]]) -> 1 | U10: 1 | V10: 1 | W10: =AVERAGE('Calidad de Datos'!O14:R14) -> 1 | X10: =Tabla13[[#This Row],[Uso y acceso Nov/2024]] -> 1 | Y10: =Tabla58[[#This Row],[Integración Nov/2024]] -> 1 | Z10: =AVERAGE(Tabla4[[#This Row],[Creación y captura Nov/2024]:[Compartición e Interoperabilidad Nov/2024]]) -> 1 | AA10: 1 | AB10: 1 | AC10: =AVERAGE('Calidad de Datos'!S14:V14) -> 1 | AD10: =Tabla13[[#This Row],[Uso y acceso Dic/2024]] -> 1 | AE10: =Tabla58[[#This Row],[Integración Dic/2024]] -> 1 | AF10: =AVERAGE(Tabla4[[#This Row],[Creación y captura Dic/2024]:[Compartición e Interoperabilidad Dic/2024]]) -> 1 | AG10: 1 | AH10: 1 | AI10: =AVERAGE('Calidad de Datos'!W14:Z14) -> 1 | AJ10: =Tabla13[[#This Row],[Uso y acceso Ene/2025]] -> 1 | AK10: =Tabla58[[#This Row],[Integración Ene/2025]] -> 1 | AL10: =AVERAGE(Tabla4[[#This Row],[Creación y captura Ene/2025]:[Compartición e Interoperabilidad Ene/2025]]) -> 1 | AM10: 1 | AN10: 1 | AO10: =AVERAGE('Calidad de Datos'!AA14:AD14) -> 1 | AP10: =Tabla13[[#This Row],[Uso y acceso Feb/2025]] -> 1 | AQ10: =Tabla58[[#This Row],[Integración Feb/2025]] -> 1 | AR10: =AVERAGE(Tabla4[[#This Row],[Creación y captura Feb/2025]:[Compartición e Interoperabilidad Feb/2025]]) -> 1 | AS10: 1 | AT10: 1 | AU10: =AVERAGE('Calidad de Datos'!AE14:AH14) -> 1 | AV10: =Tabla13[[#This Row],[Uso y acceso Mar/2025]] -> 1 | AW10: =Tabla58[[#This Row],[Integración Mar/2025]] -> 1 | AX10: =AVERAGE(Tabla4[[#This Row],[Creación y captura Mar/2025]:[Compartición e Interoperabilidad Mar/2025]]) -> 1 | AY10: 1 | AZ10: 1 | BA10: =AVERAGE('Calidad de Datos'!AI14:AL14) -> 1 | BB10: =Tabla13[[#This Row],[Uso y acceso Abr/2025]] -> 1 | BC10: =Tabla58[[#This Row],[Integración Abr/2025]] -> 1 | BD10: =AVERAGE(Tabla4[[#This Row],[Creación y captura Abr/2025]:[Compartición e Interoperabilidad Abr/2025]]) -> 1 | BE10: 1 | BF10: 1 | BG10: =AVERAGE('Calidad de Datos'!AM14:AP14) -> 1 | BH10: =Tabla13[[#This Row],[Uso y acceso May/2025]] -> 1 | BI10: =Tabla58[[#This Row],[Integración May/2025]] -> 1 | BJ10: =AVERAGE(Tabla4[[#This Row],[Creación y captura May/2025]:[Compartición e Interoperabilidad May/2025]]) -> 1 | BK10: 1 | BL10: 1 | BM10: =AVERAGE('Calidad de Datos'!AQ14:AT14) -> 1 | BN10: =Tabla13[[#This Row],[Uso y acceso Dic/2025]] -> 1 | BO10: =Tabla58[[#This Row],[Integración Dic/2025]] -> 1 | BP10: =AVERAGE(Tabla4[[#This Row],[Creación y captura Dic/2025]:[Compartición e Interoperabilidad Dic/2025]]) -> 1
B11: Cliente | C11: 1 | D11: 1 | E11: =AVERAGE('Calidad de Datos'!C15:F15) -> 0.625 | F11: =Tabla13[[#This Row],[Uso y acceso Ago/2024]] -> 1 | G11: =Tabla58[[#This Row],[Integración Ago/2024]] -> 1 | H11: =AVERAGE(Tabla4[[#This Row],[Creación y captura Ago/2024]:[Compartición e Interoperabilidad Ago/2024]]) -> 0.925 | I11: 1 | J11: 1 | K11: =AVERAGE('Calidad de Datos'!G15:J15) -> 0.625 | L11: =Tabla13[[#This Row],[Uso y acceso Sep/2024]] -> 1 | M11: =Tabla58[[#This Row],[Integración Sep/2024]] -> 1 | N11: =AVERAGE(Tabla4[[#This Row],[Creación y captura Sep/2024]:[Compartición e Interoperabilidad Sep/2024]]) -> 0.925 | O11: 1 | P11: 1 | Q11: =AVERAGE('Calidad de Datos'!K15:N15) -> 0.6325 | R11: =Tabla13[[#This Row],[Uso y acceso Oct/2024]] -> 1 | S11: =Tabla58[[#This Row],[Integración Oct/2024]] -> 1 | T11: =AVERAGE(Tabla4[[#This Row],[Creación y captura Oct/2024]:[Compartición e Interoperabilidad Oct/2024]]) -> 0.9265 | U11: 1 | V11: 1 | W11: =AVERAGE('Calidad de Datos'!O15:R15) -> 0.7625 | X11: =Tabla13[[#This Row],[Uso y acceso Nov/2024]] -> 1 | Y11: =Tabla58[[#This Row],[Integración Nov/2024]] -> 1 | Z11: =AVERAGE(Tabla4[[#This Row],[Creación y captura Nov/2024]:[Compartición e Interoperabilidad Nov/2024]]) -> 0.9525 | AA11: 1 | AB11: 1 | AC11: =AVERAGE('Calidad de Datos'!S15:V15) -> 0.82375 | AD11: =Tabla13[[#This Row],[Uso y acceso Dic/2024]] -> 1 | AE11: =Tabla58[[#This Row],[Integración Dic/2024]] -> 1 | AF11: =AVERAGE(Tabla4[[#This Row],[Creación y captura Dic/2024]:[Compartición e Interoperabilidad Dic/2024]]) -> 0.96475 | AG11: 1 | AH11: 1 | AI11: =AVERAGE('Calidad de Datos'!W15:Z15) -> 0.825 | AJ11: =Tabla13[[#This Row],[Uso y acceso Ene/2025]] -> 1 | AK11: =Tabla58[[#This Row],[Integración Ene/2025]] -> 1 | AL11: =AVERAGE(Tabla4[[#This Row],[Creación y captura Ene/2025]:[Compartición e Interoperabilidad Ene/2025]]) -> 0.965 | AM11: 1 | AN11: 1 | AO11: =AVERAGE('Calidad de Datos'!AA15:AD15) -> 0.825 | AP11: =Tabla13[[#This Row],[Uso y acceso Feb/2025]] -> 1 | AQ11: =Tabla58[[#This Row],[Integración Feb/2025]] -> 1 | AR11: =AVERAGE(Tabla4[[#This Row],[Creación y captura Feb/2025]:[Compartición e Interoperabilidad Feb/2025]]) -> 0.965 | AS11: 1 | AT11: 1 | AU11: =AVERAGE('Calidad de Datos'!AE15:AH15) -> 0.825 | AV11: =Tabla13[[#This Row],[Uso y acceso Mar/2025]] -> 1 | AW11: =Tabla58[[#This Row],[Integración Mar/2025]] -> 1 | AX11: =AVERAGE(Tabla4[[#This Row],[Creación y captura Mar/2025]:[Compartición e Interoperabilidad Mar/2025]]) -> 0.965 | AY11: 1 | AZ11: 1 | BA11: =AVERAGE('Calidad de Datos'!AI15:AL15) -> 0.825 | BB11: =Tabla13[[#This Row],[Uso y acceso Abr/2025]] -> 1 | BC11: =Tabla58[[#This Row],[Integración Abr/2025]] -> 1 | BD11: =AVERAGE(Tabla4[[#This Row],[Creación y captura Abr/2025]:[Compartición e Interoperabilidad Abr/2025]]) -> 0.965 | BE11: 1 | BF11: 1 | BG11: =AVERAGE('Calidad de Datos'!AM15:AP15) -> 0.825 | BH11: =Tabla13[[#This Row],[Uso y acceso May/2025]] -> 1 | BI11: =Tabla58[[#This Row],[Integración May/2025]] -> 1 | BJ11: =AVERAGE(Tabla4[[#This Row],[Creación y captura May/2025]:[Compartición e Interoperabilidad May/2025]]) -> 0.965 | BK11: 1 | BL11: 1 | BM11: =AVERAGE('Calidad de Datos'!AQ15:AT15) -> 0.8385 | BN11: =Tabla13[[#This Row],[Uso y acceso Dic/2025]] -> 1 | BO11: =Tabla58[[#This Row],[Integración Dic/2025]] -> 1 | BP11: =AVERAGE(Tabla4[[#This Row],[Creación y captura Dic/2025]:[Compartición e Interoperabilidad Dic/2025]]) -> 0.9677
B12: Tipo de venta | C12: 1 | D12: 1 | E12: =AVERAGE('Calidad de Datos'!C16:F16) -> 1 | F12: =Tabla13[[#This Row],[Uso y acceso Ago/2024]] -> 1 | G12: =Tabla58[[#This Row],[Integración Ago/2024]] -> 1 | H12: =AVERAGE(Tabla4[[#This Row],[Creación y captura Ago/2024]:[Compartición e Interoperabilidad Ago/2024]]) -> 1 | I12: 1 | J12: 1 | K12: =AVERAGE('Calidad de Datos'!G16:J16) -> 1 | L12: =Tabla13[[#This Row],[Uso y acceso Sep/2024]] -> 1 | M12: =Tabla58[[#This Row],[Integración Sep/2024]] -> 1 | N12: =AVERAGE(Tabla4[[#This Row],[Creación y captura Sep/2024]:[Compartición e Interoperabilidad Sep/2024]]) -> 1 | O12: 1 | P12: 1 | Q12: =AVERAGE('Calidad de Datos'!K16:N16) -> 1 | R12: =Tabla13[[#This Row],[Uso y acceso Oct/2024]] -> 1 | S12: =Tabla58[[#This Row],[Integración Oct/2024]] -> 1 | T12: =AVERAGE(Tabla4[[#This Row],[Creación y captura Oct/2024]:[Compartición e Interoperabilidad Oct/2024]]) -> 1 | U12: 1 | V12: 1 | W12: =AVERAGE('Calidad de Datos'!O16:R16) -> 1 | X12: =Tabla13[[#This Row],[Uso y acceso Nov/2024]] -> 1 | Y12: =Tabla58[[#This Row],[Integración Nov/2024]] -> 1 | Z12: =AVERAGE(Tabla4[[#This Row],[Creación y captura Nov/2024]:[Compartición e Interoperabilidad Nov/2024]]) -> 1 | AA12: 1 | AB12: 1 | AC12: =AVERAGE('Calidad de Datos'!S16:V16) -> 1 | AD12: =Tabla13[[#This Row],[Uso y acceso Dic/2024]] -> 1 | AE12: =Tabla58[[#This Row],[Integración Dic/2024]] -> 1 | AF12: =AVERAGE(Tabla4[[#This Row],[Creación y captura Dic/2024]:[Compartición e Interoperabilidad Dic/2024]]) -> 1 | AG12: 1 | AH12: 1 | AI12: =AVERAGE('Calidad de Datos'!W16:Z16) -> 1 | AJ12: =Tabla13[[#This Row],[Uso y acceso Ene/2025]] -> 1 | AK12: =Tabla58[[#This Row],[Integración Ene/2025]] -> 1 | AL12: =AVERAGE(Tabla4[[#This Row],[Creación y captura Ene/2025]:[Compartición e Interoperabilidad Ene/2025]]) -> 1 | AM12: 1 | AN12: 1 | AO12: =AVERAGE('Calidad de Datos'!AA16:AD16) -> 1 | AP12: =Tabla13[[#This Row],[Uso y acceso Feb/2025]] -> 1 | AQ12: =Tabla58[[#This Row],[Integración Feb/2025]] -> 1 | AR12: =AVERAGE(Tabla4[[#This Row],[Creación y captura Feb/2025]:[Compartición e Interoperabilidad Feb/2025]]) -> 1 | AS12: 1 | AT12: 1 | AU12: =AVERAGE('Calidad de Datos'!AE16:AH16) -> 1 | AV12: =Tabla13[[#This Row],[Uso y acceso Mar/2025]] -> 1 | AW12: =Tabla58[[#This Row],[Integración Mar/2025]] -> 1 | AX12: =AVERAGE(Tabla4[[#This Row],[Creación y captura Mar/2025]:[Compartición e Interoperabilidad Mar/2025]]) -> 1 | AY12: 1 | AZ12: 1 | BA12: =AVERAGE('Calidad de Datos'!AI16:AL16) -> 1 | BB12: =Tabla13[[#This Row],[Uso y acceso Abr/2025]] -> 1 | BC12: =Tabla58[[#This Row],[Integración Abr/2025]] -> 1 | BD12: =AVERAGE(Tabla4[[#This Row],[Creación y captura Abr/2025]:[Compartición e Interoperabilidad Abr/2025]]) -> 1 | BE12: 1 | BF12: 1 | BG12: =AVERAGE('Calidad de Datos'!AM16:AP16) -> 1 | BH12: =Tabla13[[#This Row],[Uso y acceso May/2025]] -> 1 | BI12: =Tabla58[[#This Row],[Integración May/2025]] -> 1 | BJ12: =AVERAGE(Tabla4[[#This Row],[Creación y captura May/2025]:[Compartición e Interoperabilidad May/2025]]) -> 1 | BK12: 1 | BL12: 1 | BM12: =AVERAGE('Calidad de Datos'!AQ16:AT16) -> 1 | BN12: =Tabla13[[#This Row],[Uso y acceso Dic/2025]] -> 1 | BO12: =Tabla58[[#This Row],[Integración Dic/2025]] -> 1 | BP12: =AVERAGE(Tabla4[[#This Row],[Creación y captura Dic/2025]:[Compartición e Interoperabilidad Dic/2025]]) -> 1
